Workbook

Sheet INSPECTED FACILITIES 2025
A1: GDP INSPECTION CLASSIFICATION DATA BASE AS AT 2025
A2: S/N | B2: NAME OF MANUFACTURER | C2: LOCATION ADDRESS | D2: CONTACT | E2: TYPE OF LAST INSPECTION | F2: DATE OF LAST INSPECTION | G2: FINDINGS | H2: DATE CAPA ISSUED | I2: CAPA SUBMITTED | J2: CONCLUSION | K2: REMARKS | L2: EXPECTED DATE OF INSPECTION | M2: CC | N2: COMPANY FILE
A3: 1 | B3: SANTECARE LIMITED | C3: 55, COKER ROAD, ILUPEJU | D3: 8127926887 | E3: GDP | F3: 45678 | G3: Medium-Risk (B) | H3: 26th january 2025 | I3: NO | J3: CAPA TO BE SUBMITTED | K3: =IF(I3="YES","CAPA VERIFICATION SHOULD BE SCHEDULED",IF(I3="NO","REMINDER LETTER SHOULD BE SENT","")) -> REMINDER LETTER SHOULD BE SENT | L3: 46023 | M3: https://nafdacng.sharepoint.com/sites/PMSLAGOS/Shared Documents/GSDP (GOOD STORAGE AND DISTRIBUTION PRACTICE)/GSDP COMPANY FILES\Santa Care LTD | N3: SANTA CARE
A4: 2 | B4: JANE-MADOK PHARMACY & WELLNESS CENTER | C4: 3, ISHERI OSUN RD., JAKANDE GATE, ISOLO | D4: 9035803090 | E4: GDP | F4: 45680 | G4: Medium-Risk (B) | H4: 25th january 2025 | I4: NO | J4: CAPA TO BE SUBMITTED | K4: =IF(I4="YES","CAPA VERIFICATION SHOULD BE SCHEDULED",IF(I4="NO","REMINDER LETTER SHOULD BE SENT","")) -> REMINDER LETTER SHOULD BE SENT | L4: 46023 | M4: https://nafdacng.sharepoint.com/sites/PMSLAGOS/Shared Documents/GSDP (GOOD STORAGE AND DISTRIBUTION PRACTICE)/GSDP COMPANY FILES\Jane-Madok | N4: =IF(M4="","",HYPERLINK(M4,B4)) -> JANE-MADOK PHARMACY & WELLNESS CENTER
A5: 3 | B5: ROCHE PRODUCTS LIMITED (MEDICAL DEVICES) | C5: AGL WAREHOUSE, KILOMETER11, OPPOSITE TOP MOUNTAIN UNIVERSITY, ALONG LAGOS IBADAN EXPRESSWAY, IBAFO | D5: 7033089165 | E5: GDP | F5: 45680 | G5: Medium-Risk (B) | H5: 11th February 2025 | I5: NO | J5: CAPA TO BE SUBMITTED | K5: =IF(I5="YES","CAPA VERIFICATION SHOULD BE SCHEDULED",IF(I5="NO","REMINDER LETTER SHOULD BE SENT","")) -> REMINDER LETTER SHOULD BE SENT | L5: 46054 | M5: https://nafdacng.sharepoint.com/sites/PMSLAGOS/Shared Documents/GSDP (GOOD STORAGE AND DISTRIBUTION PRACTICE)/GSDP COMPANY FILES\Roche Products ltd | N5: =IF(M5="","",HYPERLINK(M5,B5)) -> ROCHE PRODUCTS LIMITED (MEDICAL DEVICES)
A6: 4 | B6: KCH CONSUMER HEALTHCARE LTD. (CAPA) | C6: 2B KWAME NKRUMAH LANE, CROWN ESTATE, LEKKI-EPE EXPRESSWAY, AJAH | D6: 8022317625 | E6: CAPA | F6: 45685 | G6: Medium-Risk (B) | H6: 28th january 2025 | I6: YES | J6: CAPA SUBMITTED | K6: =IF(I6="YES","CAPA VERIFICATION SHOULD BE SCHEDULED",IF(I6="NO","REMINDER LETTER SHOULD BE SENT","")) -> CAPA VERIFICATION SHOULD BE SCHEDULED | L6: 46023 | M6: https://nafdacng.sharepoint.com/sites/PMSLAGOS/Shared Documents/GSDP (GOOD STORAGE AND DISTRIBUTION PRACTICE)/GSDP COMPANY FILES\KCH CONSUMER | N6: =IF(M6="","",HYPERLINK(M6,B6)) -> KCH CONSUMER HEALTHCARE LTD. (CAPA)
A7: 5 | B7: MUJID HEALTHCARE LTD | C7: PLOT B, GREENLAND ESTATE, AJAH | D7: 8033268130 | E7: GDP | F7: 45685 | G7: Medium-Risk (B) | H7: 45685 | I7: NO | J7: CAPA TO BE SUBMITTED | K7: =IF(I7="YES","CAPA VERIFICATION SHOULD BE SCHEDULED",IF(I7="NO","REMINDER LETTER SHOULD BE SENT","")) -> REMINDER LETTER SHOULD BE SENT | L7: 46023 | M7: https://nafdacng.sharepoint.com/sites/PMSLAGOS/Shared Documents/GSDP (GOOD STORAGE AND DISTRIBUTION PRACTICE)/GSDP COMPANY FILES\MULTIBASE | N7: =IF(M7="","",HYPERLINK(M7,B7)) -> MUJID HEALTHCARE LTD
A8: 6 | B8: ROCHE PRODUCTS LIMITED (MEDICAL DEVICES) | C8: ISN MEDICAL 40-42 ASSOCIATION AVENUE, ILUPEJU | D8: 7044644915 | E8: GDP | F8: 45693 | G8: Medium-Risk (B) | H8: 45685 | I8: NO | J8: CAPA TO BE SUBMITTED | K8: =IF(I8="YES","CAPA VERIFICATION SHOULD BE SCHEDULED",IF(I8="NO","REMINDER LETTER SHOULD BE SENT","")) -> REMINDER LETTER SHOULD BE SENT | L8: 45683 | N8: =IF(M8="","",HYPERLINK(M8,B8))
A9: 7 | B9: EUROMED LTD | E9: GDP | F9: 45734 | G9: Medium-Risk (B) | H9: 25TH MARCH 2025 | I9: YES | J9: CAPA SUBMITTED | K9: =IF(I9="YES","CAPA VERIFICATION SHOULD BE SCHEDULED",IF(I9="NO","REMINDER LETTER SHOULD BE SENT","")) -> CAPA VERIFICATION SHOULD BE SCHEDULED | L9: 45870 | M9: https://nafdacng.sharepoint.com/sites/PMSLAGOS/Shared Documents/GSDP (GOOD STORAGE AND DISTRIBUTION PRACTICE)/GSDP COMPANY FILES\EUROMED | N9: =IF(M9="","",HYPERLINK(M9,B9)) -> EUROMED LTD
A10: 8 | B10: GREENLIFE PHARMA CEUTICALS LTD. (CAPA) | C10: 35A, ASSOCIATION AVENUE, OFF OBANIKORO BUS STOP, ILUPEJU | D10: 8132993626 | E10: CAPA | F10: 45734 | G10: Low-Risk (A) | H10: N/A | I10: YES | J10: CLOSED | K10: CLOSED | L10: 46447 | M10: https://nafdacng.sharepoint.com/sites/PMSLAGOS/Shared Documents/GSDP (GOOD STORAGE AND DISTRIBUTION PRACTICE)/GSDP COMPANY FILES\GREENLIFE PHARM. LTD | N10: =IF(M10="","",HYPERLINK(M10,B10)) -> GREENLIFE PHARMA CEUTICALS LTD. (CAPA)
A11: 9 | B11: DORTEMAG PHARM. & STORES | C11: 381G, TITILAYO ADEDOYIN STR., OMOLE EST. PHASE 1, OGBA-IKEJA | D11: PHARM. SEYE AGBOOLA 0803315214 | E11: GDP | F11: 45734 | G11: Medium-Risk (B) | H11: 18TH MARCH 2025 | I11: NO | J11: CAPA TO BE SUBMITTED | K11: =IF(I11="YES","CAPA VERIFICATION SHOULD BE SCHEDULED",IF(I11="NO","REMINDER LETTER SHOULD BE SENT","")) -> REMINDER LETTER SHOULD BE SENT | L11: 46082 | M11: https://nafdacng.sharepoint.com/sites/PMSLAGOS/Shared Documents/GSDP (GOOD STORAGE AND DISTRIBUTION PRACTICE)/GSDP COMPANY FILES\DORTEMAG | N11: =IF(M11="","",HYPERLINK(M11,B11)) -> DORTEMAG PHARM. & STORES
A12: 10 | B12: HEALTHLINE NIG. LTD | C12: 29, ADENIYI JONES AVENUE, IKEJA | D12: MRS. ITUNU AJAYI 08030678801 | E12: GDP | F12: 45734 | G12: Medium-Risk (B) | H12: 18TH MRCH 2025 | I12: NO | J12: CAPA TO BE SUBMITTED | K12: =IF(I12="YES","CAPA VERIFICATION SHOULD BE SCHEDULED",IF(I12="NO","REMINDER LETTER SHOULD BE SENT","")) -> REMINDER LETTER SHOULD BE SENT | L12: 45717 | M12: https://nafdacng.sharepoint.com/sites/PMSLAGOS/Shared Documents/GSDP (GOOD STORAGE AND DISTRIBUTION PRACTICE)/GSDP COMPANY FILES\HEALTHLINE NIG. LTD | N12: =IF(M12="","",HYPERLINK(M12,B12)) -> HEALTHLINE NIG. LTD
A13: 11 | B13: GETZPHARMA NIG. LTD | C13: PLOT 2, IJA ODOLA CLOSE IKEJA GRA | D13: OBEGOLU NNEKA 08165370750 | E13: GDP | F13: 45734 | G13: Medium-Risk (B) | H13: 18TH MARCH 2025 | I13: NO | J13: CAPA TO BE SUBMITTED | K13: =IF(I13="YES","CAPA VERIFICATION SHOULD BE SCHEDULED",IF(I13="NO","REMINDER LETTER SHOULD BE SENT","")) -> REMINDER LETTER SHOULD BE SENT | L13: 45717 | M13: https://nafdacng.sharepoint.com/sites/PMSLAGOS/Shared Documents/GSDP (GOOD STORAGE AND DISTRIBUTION PRACTICE)/GSDP COMPANY FILES\GETZ PHARM NIG. LTD | N13: =IF(M13="","",HYPERLINK(M13,B13)) -> GETZPHARMA NIG. LTD
A14: 12 | B14: SHEPHERD HEALTH & VETERINARY LTD. | C14: 24, MONTGOMERY RD., YABA | D14: JOSEPH ADETUNJI 08037184254 | E14: GDP | F14: 45735 | G14: Medium-Risk (B) | H14: 19TH MARCH 2025 | I14: YES | J14: CAPA TO BE SUBMITTED | K14: =IF(I14="YES","CAPA VERIFICATION SHOULD BE SCHEDULED",IF(I14="NO","REMINDER LETTER SHOULD BE SENT","")) -> CAPA VERIFICATION SHOULD BE SCHEDULED | L14: 45717 | M14: https://nafdacng.sharepoint.com/sites/PMSLAGOS/Shared Documents/GSDP (GOOD STORAGE AND DISTRIBUTION PRACTICE)/GSDP COMPANY FILES\SHEPHERD HEALTH | N14: =IF(M14="","",HYPERLINK(M14,B14)) -> SHEPHERD HEALTH & VETERINARY LTD.
A15: 13 | B15: ADCEM PHARMACEUTICALS LTD | C15: 2, NIWILI CLOSE, IKEJA | D15: OKEKE ONYEKACHI 08123915479 | E15: GDP | F15: 45735 | G15: Medium-Risk (B) | I15: N/A | J15: CAPA TO BE SUBMITTED | K15: =IF(I15="YES","CAPA VERIFICATION SHOULD BE SCHEDULED",IF(I15="NO","REMINDER LETTER SHOULD BE SENT","")) | L15: 45717 | M15: https://nafdacng.sharepoint.com/sites/PMSLAGOS/Shared Documents/GSDP (GOOD STORAGE AND DISTRIBUTION PRACTICE)/GSDP COMPANY FILES\Adcem | N15: =IF(M15="","",HYPERLINK(M15,B15)) -> ADCEM PHARMACEUTICALS LTD
A16: 14 | B16: ADDMORE PHARMACY | C16: 251, AGEGE-MOTOR ROAD, MUSHIN | D16: BENSON NDULUE 08023019928 | E16: GDP | F16: 45735 | G16: Medium-Risk (B) | H16: 19TH MARCH 2025 | I16: NO | J16: CAPA TO BE SUBMITTED | K16: =IF(I16="YES","CAPA VERIFICATION SHOULD BE SCHEDULED",IF(I16="NO","REMINDER LETTER SHOULD BE SENT","")) -> REMINDER LETTER SHOULD BE SENT | L16: 45717 | M16: https://nafdacng.sharepoint.com/sites/PMSLAGOS/Shared Documents/GSDP (GOOD STORAGE AND DISTRIBUTION PRACTICE)/GSDP COMPANY FILES\Addmore | N16: =IF(M16="","",HYPERLINK(M16,B16)) -> ADDMORE PHARMACY
A17: 15 | B17: AXION PHARMACEUTICALS LTD | C17: 13, MODUPE STREET, SOMOLU, LAGOS. | D17: PHARM. ONYINYE 07061902283 | E17: GDP | F17: 45736 | G17: High-Risk (C) | H17: N/A | I17: NO | J17: CAPA TO BE SUBMITTED | K17: =IF(I17="YES","CAPA VERIFICATION SHOULD BE SCHEDULED",IF(I17="NO","REMINDER LETTER SHOULD BE SENT","")) -> REMINDER LETTER SHOULD BE SENT | L17: 45901 | M17: https://nafdacng.sharepoint.com/sites/PMSLAGOS/Shared Documents/GSDP (GOOD STORAGE AND DISTRIBUTION PRACTICE)/GSDP COMPANY FILES\Axion | N17: =IF(M17="","",HYPERLINK(M17,B17)) -> AXION PHARMACEUTICALS LTD
A18: 16 | B18: MED EXPRESS | C18: 7A, ADEWALE KOLAWOLE CRESCENT, OFF KUBOYE STR., MARUWA, LEKKI | D18: RUEMU OKUNDIA 08033001059 | E18: GDP | F18: 45736 | G18: Low-Risk (A) | H18: 19TH MARCH 2025 | I18: YES | J18: CAPA SUBMITTED | K18: DONE | L18: SATISFACTORY | M18: https://nafdacng.sharepoint.com/sites/PMSLAGOS/Shared Documents/GSDP (GOOD STORAGE AND DISTRIBUTION PRACTICE)/GSDP COMPANY FILES\MEDEXPRESS | N18: =IF(M18="","",HYPERLINK(M18,B18)) -> MED EXPRESS
A19: 20 | B19: SOLID ACCORD LTD | C19: 85B, FEMI KILLA RD., OFF AGO PALACE WAY, OKOTA | D19: MR FRANCIS OHALE 08033738531 | E19: GDP | F19: 45736 | G19: High-Risk (C) | H19: 21ST MARCH 2025 | I19: YES | J19: CAPA SUBMITTED | K19: =IF(I19="YES","CAPA VERIFICATION SHOULD BE SCHEDULED",IF(I19="NO","REMINDER LETTER SHOULD BE SENT","")) -> CAPA VERIFICATION SHOULD BE SCHEDULED | L19: 45742 | M19: https://nafdacng.sharepoint.com/sites/PMSLAGOS/Shared Documents/GSDP (GOOD STORAGE AND DISTRIBUTION PRACTICE)/GSDP COMPANY FILES\Solid Accord | N19: =IF(M19="","",HYPERLINK(M19,B19)) -> SOLID ACCORD LTD
A20: 21 | B20: AQUATIX PHARM. LTD | C20: 9, DAVE ANAZODO STREET, NEAR CHIVITA COMPANY, AJAO ESTATE | D20: MR. PRADEEP CHAUDHARY 08025555568 | E20: GDP | F20: 45736 | G20: Low-Risk (A) | H20: 21ST MARCH 2025 | I20: NO | J20: CAPA TO BE SUBMITTED | K20: =IF(I20="YES","CAPA VERIFICATION SHOULD BE SCHEDULED",IF(I20="NO","REMINDER LETTER SHOULD BE SENT","")) -> REMINDER LETTER SHOULD BE SENT | L20: 45925 | M20: https://nafdacng.sharepoint.com/sites/PMSLAGOS/Shared Documents/GSDP (GOOD STORAGE AND DISTRIBUTION PRACTICE)/GSDP COMPANY FILES\AQUATIX | N20: =IF(M20="","",HYPERLINK(M20,B20)) -> AQUATIX PHARM. LTD
A21: 22 | B21: SAI SAGAR | C21: 2, KAARA STREET.,OFF OSOLO WAY,AJAO ESTATE,LAGOS | D21: PHARM. OKEKE UCHE 07055244581 | E21: GDP | F21: 45736 | G21: High-Risk (C) | H21: 21ST MARCH 2025 | I21: NO | J21: CAPA TO BE SUBMITTED | K21: =IF(I21="YES","CAPA VERIFICATION SHOULD BE SCHEDULED",IF(I21="NO","REMINDER LETTER SHOULD BE SENT","")) -> REMINDER LETTER SHOULD BE SENT | L21: 45901 | M21: https://nafdacng.sharepoint.com/sites/PMSLAGOS/Shared%20Documents/GDP%20(GOOD%20DISTRIBUTION%20PRATICE)/GSDP%20COMPANY%20FILES/ICE%20REMEDIES | N21: =IF(M21="","",HYPERLINK(M21,B21)) -> SAI SAGAR
A22: 23 | B22: MAYDON PHARM. & CHEM. CO. LTD. | C22: 15, WILMER STREET, OFF TOWN PLANNING WAY, ILUPEJU | D22: Pharm. PE Orazukile 08034304758 | E22: GDP | F22: 45762 | G22: Medium-Risk (B) | H22: 5TH MAY 2025 | I22: YES | J22: CAPA SUBMITTED | K22: =IF(I22="YES","CAPA VERIFICATION SHOULD BE SCHEDULED",IF(I22="NO","REMINDER LETTER SHOULD BE SENT","")) -> CAPA VERIFICATION SHOULD BE SCHEDULED | L22: 45748 | M22: https://nafdacng.sharepoint.com/sites/PMSLAGOS/Shared Documents/GSDP (GOOD STORAGE AND DISTRIBUTION PRACTICE)/GSDP COMPANY FILES\MAYDON | N22: =IF(M22="","",HYPERLINK(M22,B22)) -> MAYDON PHARM. & CHEM. CO. LTD.
A23: 24 | B23: ALMOND ETHICALS LTD | C23: 2B, MOJOLA STREET, AJAO ESTATE, ANTHONY VILLAGE LAGOS | D23: THEODORE R. OKAFOR 08033324448 | E23: GDP | F23: 45762 | G23: Medium-Risk (B) | H23: 5TH MAY 2025 | I23: NO | J23: CAPA TO BE SUBMITTED | K23: =IF(I23="YES","CAPA VERIFICATION SHOULD BE SCHEDULED",IF(I23="NO","REMINDER LETTER SHOULD BE SENT","")) -> REMINDER LETTER SHOULD BE SENT | L23: 45748 | M23: https://nafdacng.sharepoint.com/sites/PMSLAGOS/Shared%20Documents/GDP%20(GOOD%20DISTRIBUTION%20PRATICE)/GSDP%20COMPANY%20FILES\ALMOND%20ETHICALS | N23: =IF(M23="","",HYPERLINK(M23,B23)) -> ALMOND ETHICALS LTD
A24: 25 | B24: EJIMATH PHARMACY LTD. | C24: 10, ABEOKUTA STREET, OFF ABEOKUTA EXPRESS ROAD, PLEASURE, ALIMOSHO, LAGOS | D24: Pharm. (Dr.) Agu Nnamdulu | E24: GDP | F24: 45762 | G24: Medium-Risk (B) | H24: 23RD APRIL 2025 | I24: NO | J24: CAPA TO BE SUBMITTED | K24: =IF(I24="YES","CAPA VERIFICATION SHOULD BE SCHEDULED",IF(I24="NO","REMINDER LETTER SHOULD BE SENT","")) -> REMINDER LETTER SHOULD BE SENT | L24: 45773 | M24: https://nafdacng.sharepoint.com/sites/PMSLAGOS/Shared Documents/GSDP (GOOD STORAGE AND DISTRIBUTION PRACTICE)/GSDP COMPANY FILES\EJIMATH | N24: =IF(M24="","",HYPERLINK(M24,B24)) -> EJIMATH PHARMACY LTD.
A25: 26 | B25: NAFRO PHARMA NIG. LTD. | C25: SUITE B16, AMORI SHOPPING PLAZA, EGBEDA. | D25: Abasilim 08033262248 | E25: GDP | F25: 45762 | G25: Medium-Risk (B) | H25: 23RD APRIL 2025 | I25: NO | J25: CAPA TO BE SUBMITTED | K25: =IF(I25="YES","CAPA VERIFICATION SHOULD BE SCHEDULED",IF(I25="NO","REMINDER LETTER SHOULD BE SENT","")) -> REMINDER LETTER SHOULD BE SENT | L25: 45748 | M25: https://nafdacng.sharepoint.com/sites/PMSLAGOS/Shared Documents/GSDP (GOOD STORAGE AND DISTRIBUTION PRACTICE)/GSDP COMPANY FILES\NANCIL1 | N25: =IF(M25="","",HYPERLINK(M25,B25)) -> NAFRO PHARMA NIG. LTD.
A26: 27 | B26: THOMPSON & GRACE PHARM. LTD. | C26: 7, MORONU MADUAGWU STR., OFF MASHA, SURULERE | D26: Pharm. Anthony Otaigbe 07060954163 | E26: GDP | F26: 45763 | G26: Medium-Risk (B) | J26: CAPA TO BE SUBMITTED | K26: =IF(I26="YES","CAPA VERIFICATION SHOULD BE SCHEDULED",IF(I26="NO","REMINDER LETTER SHOULD BE SENT","")) | L26: 45748 | M26: https://nafdacng.sharepoint.com/sites/PMSLAGOS/Shared Documents/GSDP (GOOD STORAGE AND DISTRIBUTION PRACTICE)/GSDP COMPANY FILES\Thompson & Grace Pharm | N26: =IF(M26="","",HYPERLINK(M26,B26)) -> THOMPSON & GRACE PHARM. LTD.
A27: 28 | B27: GLOBAL ONE WORD HEALTHCARE | C27: 30B TOWOLAWI, COKER VILLAGE, ORILE IGANMU, SURULERE | D27: PHARM. IFE ADETIFA 07033775248 | E27: GDP | F27: 45763 | G27: Medium-Risk (B) | H27: 24TH APRIL 2025 | I27: YES | J27: CAPA SUBMITTED | K27: =IF(I27="YES","CAPA VERIFICATION SHOULD BE SCHEDULED",IF(I27="NO","REMINDER LETTER SHOULD BE SENT","")) -> CAPA VERIFICATION SHOULD BE SCHEDULED | L27: 45748 | M27: https://nafdacng.sharepoint.com/sites/PMSLAGOS/Shared Documents/GSDP (GOOD STORAGE AND DISTRIBUTION PRACTICE)/GSDP COMPANY FILES\Global One healthcare | N27: =IF(M27="","",HYPERLINK(M27,B27)) -> GLOBAL ONE WORD HEALTHCARE
A28: 29 | B28: LABETA DRUGS LTD. | C28: 16, BADARU STREET, BY MASHA BUSSTOP, SURULERE | D28: Elizabeth Amomo 08023263729 | E28: GDP | F28: 45763 | G28: Medium-Risk (B) | H28: 24TH APRIL 2025 | I28: YES | J28: CAPA SUBMITTED | K28: =IF(I28="YES","CAPA VERIFICATION SHOULD BE SCHEDULED",IF(I28="NO","REMINDER LETTER SHOULD BE SENT","")) -> CAPA VERIFICATION SHOULD BE SCHEDULED | L28: 45748 | M28: https://nafdacng.sharepoint.com/sites/PMSLAGOS/Shared Documents/GSDP (GOOD STORAGE AND DISTRIBUTION PRACTICE)/GSDP COMPANY FILES\LABETA | N28: =IF(M28="","",HYPERLINK(M28,B28)) -> LABETA DRUGS LTD.
A29: 30 | B29: MULTIBASE PHARMA IND. NIG. LTD | C29: 7A, AJIBADE OKE STR., AJAO ESTATE | D29: 8033183813 | E29: GDP | F29: 45764 | G29: Low-Risk (A) | I29: YES | J29: NO CAPA UNTIL IMPORTATION BEGINS | K29: =IF(I29="YES","CAPA VERIFICATION SHOULD BE SCHEDULED",IF(I29="NO","REMINDER LETTER SHOULD BE SENT","")) -> CAPA VERIFICATION SHOULD BE SCHEDULED | L29: 46113 | M29: https://nafdacng.sharepoint.com/sites/PMSLAGOS/Shared Documents/GSDP (GOOD STORAGE AND DISTRIBUTION PRACTICE)/GSDP COMPANY FILES\MULTICHARIS PHARMACY & CHEM | N29: =IF(M29="","",HYPERLINK(M29,B29)) -> MULTIBASE PHARMA IND. NIG. LTD
A30: 31 | B30: GENERICS & SPECIALITIES LTD (CAPA) | C30: 9, DAVE ANAZODO STREET, NEAR CHIVITA COMPANY, AJAO ESTATE | D30: Pharm. Cyril Odidika | E30: CAPA | F30: 45764 | G30: Low-Risk (A) | J30: CLOSED | K30: CONTINOUS MONITORING TO ENSURE COMPLAINCE | L30: SATISFACTORY | M30: https://nafdacng.sharepoint.com/sites/PMSLAGOS/Shared Documents/GSDP (GOOD STORAGE AND DISTRIBUTION PRACTICE)/GSDP COMPANY FILES\GENERICS & SPECIALITIES | N30: =IF(M30="","",HYPERLINK(M30,B30)) -> GENERICS & SPECIALITIES LTD (CAPA)
A31: 32 | B31: NANCIL NIG. LTD. | C31: 1, CEDAR ROAD, OFF OJODU ABIODUN ROAD, OJODU BERGER | D31: Pharm. Chizoba Akubue | E31: GDP | F31: 45764 | G31: Medium-Risk (B) | H31: 22ND APRIL 2025 | I31: YES | J31: CAPA SUBMITTED | K31: DONE | L31: SATISFACTORY | M31: https://nafdacng.sharepoint.com/sites/PMSLAGOS/Shared Documents/GSDP (GOOD STORAGE AND DISTRIBUTION PRACTICE)/GSDP COMPANY FILES\NEAT LINE PHARM LTD | N31: =IF(M31="","",HYPERLINK(M31,B31)) -> NANCIL NIG. LTD.
A32: 33 | B32: TETA PHARM. LTD.(CAPA) | C32: 4, OKEHO STREET, IREAKARI ESTATE, ISOLO | D32: Pharm. George Akinsuli | E32: CAPA | F32: 45764 | G32: Medium-Risk (B) | H32: 24TH APRIL 2025 | I32: YES | J32: CAPA SUBMITTED | K32: =IF(I32="YES","CAPA VERIFICATION SHOULD BE SCHEDULED",IF(I32="NO","REMINDER LETTER SHOULD BE SENT","")) -> CAPA VERIFICATION SHOULD BE SCHEDULED | L32: 45748 | M32: https://nafdacng.sharepoint.com/sites/PMSLAGOS/Shared Documents/GSDP (GOOD STORAGE AND DISTRIBUTION PRACTICE)/GSDP COMPANY FILES\TEKA PHARM | N32: =IF(M32="","",HYPERLINK(M32,B32)) -> TETA PHARM. LTD.(CAPA)
A33: 34 | B33: VITANE PHARM. NIG. LTD. | D33: M.ALATEEKS | E33: GDP | F33: 45762 | G33: Low-Risk (A) | J33: CAPA TO BE SUBMITTED | K33: =IF(I33="YES","CAPA VERIFICATION SHOULD BE SCHEDULED",IF(I33="NO","REMINDER LETTER SHOULD BE SENT","")) | L33: 46113 | N33: =IF(M33="","",HYPERLINK(M33,B33))
A34: 35 | B34: ORANGE DRUGS LTD. | C34: 66/68, TOWN PLANNING WAY, ILUPEJU | D34: 8036005454 | E34: GDP | F34: 45797 | G34: Medium-Risk (B) | H34: 21ST MAY 2025 | I34: NO | J34: CAPA TO BE SUBMITTED | K34: =IF(I34="YES","CAPA VERIFICATION SHOULD BE SCHEDULED",IF(I34="NO","REMINDER LETTER SHOULD BE SENT","")) -> REMINDER LETTER SHOULD BE SENT | L34: 45778 | M34: https://nafdacng.sharepoint.com/sites/PMSLAGOS/Shared Documents/GSDP (GOOD STORAGE AND DISTRIBUTION PRACTICE)/GSDP COMPANY FILES\Orange drugs ltd | N34: =IF(M34="","",HYPERLINK(M34,B34)) -> ORANGE DRUGS LTD.
A35: 36 | B35: GLOBAL HEALTHCARE LTD | C35: 12, OLUSOJI IDOWU STREET, OFF ADEKUNLE ODUNLAMI CRESCERNT, ILUPEJU | D35: OLADIMEJI GBOTOSO 08033371573 | E35: GDP | F35: 45797 | G35: Medium-Risk (B) | H35: 21ST MAY 2025 | I35: NO | J35: CAPA TO BE SUBMITTED | K35: =IF(I35="YES","CAPA VERIFICATION SHOULD BE SCHEDULED",IF(I35="NO","REMINDER LETTER SHOULD BE SENT","")) -> REMINDER LETTER SHOULD BE SENT | L35: 45778 | M35: https://nafdacng.sharepoint.com/sites/PMSLAGOS/Shared Documents/GSDP (GOOD STORAGE AND DISTRIBUTION PRACTICE)/GSDP COMPANY FILES\Global Healthcare Ltd | N35: =IF(M35="","",HYPERLINK(M35,B35)) -> GLOBAL HEALTHCARE LTD
A36: 37 | B36: OXUS PHARMA LTD. | C36: 20, OGUNAIKE STREET, OFF SHIPEOLU STREET, PALMGROOVE | D36: PHARM. EGBUNIKE 08065139357 | E36: GDP | F36: 45797 | G36: Medium-Risk (B) | H36: 21ST MAY 2025 | I36: NO | J36: CAPA TO BE SUBMITTED | K36: =IF(I36="YES","CAPA VERIFICATION SHOULD BE SCHEDULED",IF(I36="NO","REMINDER LETTER SHOULD BE SENT","")) -> REMINDER LETTER SHOULD BE SENT | L36: 45778 | M36: https://nafdacng.sharepoint.com/sites/PMSLAGOS/Shared Documents/GSDP (GOOD STORAGE AND DISTRIBUTION PRACTICE)/GSDP COMPANY FILES\Oxus pharma | N36: =IF(M36="","",HYPERLINK(M36,B36)) -> OXUS PHARMA LTD.
A37: 38 | B37: MICRONOVA PHARM. INDT. LTD | C37: PLOT 3, BILLINGS WAY, OREGUN IND ESTATE, IKEJA | D37: OGUEF SOLOMON 08033555665 | E37: GDP | F37: 45797 | G37: Medium-Risk (B) | H37: 26TH MAY 2025 | I37: NO | J37: CAPA TO BE SUBMITTED | K37: =IF(I37="YES","CAPA VERIFICATION SHOULD BE SCHEDULED",IF(I37="NO","REMINDER LETTER SHOULD BE SENT","")) -> REMINDER LETTER SHOULD BE SENT | L37: 45778 | M37: https://nafdacng.sharepoint.com/sites/PMSLAGOS/Shared Documents/GSDP (GOOD STORAGE AND DISTRIBUTION PRACTICE)/GSDP COMPANY FILES\Mid century Agro Allied Ventures | N37: =IF(M37="","",HYPERLINK(M37,B37)) -> MICRONOVA PHARM. INDT. LTD
A38: 39 | B38: TURNER WRIGHT LTD. | C38: 15, ADENEKAN SALAKO STR., OGBA, IKEJA | D38: PHARM. F. AKINDELE 08033068480 | E38: GDP | F38: 45797 | G38: Medium-Risk (B) | H38: 25TH MAY 2025 | I38: NO | J38: CAPA TO BE SUBMITTED | K38: =IF(I38="YES","CAPA VERIFICATION SHOULD BE SCHEDULED",IF(I38="NO","REMINDER LETTER SHOULD BE SENT","")) -> REMINDER LETTER SHOULD BE SENT | L38: 45778 | M38: https://nafdacng.sharepoint.com/sites/PMSLAGOS/Shared%20Documents/GDP%20(GOOD%20DISTRIBUTION%20PRATICE)/GSDP%20COMPANY%20FILES/TURNER%20WRIGHT%20LTD | N38: =IF(M38="","",HYPERLINK(M38,B38)) -> TURNER WRIGHT LTD.
A39: 40 | B39: BRIAN MUNRO LTD | C39: 25, IZE IYAMU STR., OFF BILLINGSWAY, OREGUN | D39: PHARM. OLORUNSOLA BOLUWATIFE 08060378307 | E39: GDP | F39: 45799 | G39: Medium-Risk (B) | H39: 23RD MAY 2025 | I39: NO | J39: CAPA TO BE SUBMITTED | K39: =IF(I39="YES","CAPA VERIFICATION SHOULD BE SCHEDULED",IF(I39="NO","REMINDER LETTER SHOULD BE SENT","")) -> REMINDER LETTER SHOULD BE SENT | L39: 45778 | M39: https://nafdacng.sharepoint.com/sites/PMSLAGOS/Shared Documents/GSDP (GOOD STORAGE AND DISTRIBUTION PRACTICE)/GSDP COMPANY FILES\Brian Munroe | N39: =IF(M39="","",HYPERLINK(M39,B39)) -> BRIAN MUNRO LTD
A40: 41 | B40: SAGAR VITACEUTICALS (CAPA) | C40: PLOT 2, LADIPO OLUWOLE STR., OFF AKRAN AVENUE, IKEJA | D40: PHARM. AJENIFUJA 08023692457 | E40: CAPA | F40: 45799 | G40: Low-Risk (A) | H40: 23RD MAY 2025 | I40: YES | J40: CAPA SUBMITTED | K40: CLOSED | L40: 45778 | M40: https://nafdacng.sharepoint.com/sites/PMSLAGOS/Shared Documents/GSDP (GOOD STORAGE AND DISTRIBUTION PRACTICE)/GSDP COMPANY FILES\SAGAR VITACEAUTICALS NIG LTD | N40: =IF(M40="","",HYPERLINK(M40,B40)) -> SAGAR VITACEUTICALS (CAPA)
...

Sheet January
A1: GDP INSPECTION CLASSIFICATION DATA BASE AS AT 2025
A2: S/N | B2: NAME OF MANUFACTURER | C2: LOCATION ADDRESS | D2: CONTACT | E2: TYPE OF LAST INSPECTION | F2: DATE OF LAST INSPECTION | G2: FINDINGS | H2: DATE CAPA ISSUED | I2: CAPA SUBMITTED | J2: CONCLUSION | K2: REMARKS | L2: EXPECTED DATE OF INSPECTION | M2: CC | N2: COMPANY FILE | O2: Column1
A3: 1 | B3: SANTECARE LIMITED | C3: 55, COKER ROAD, ILUPEJU | D3: 8127926887 | E3: GDP | F3: 45678 | G3: Medium-Risk (B) | H3: 26th january 2025 | I3: NO | J3: CAPA TO BE SUBMITTED | K3: =IF(I3="YES","CAPA VERIFICATION SHOULD BE SCHEDULED",IF(I3="NO","REMINDER LETTER SHOULD BE SENT","")) -> REMINDER LETTER SHOULD BE SENT | L3: 46023 | M3: https://nafdacng.sharepoint.com/sites/PMSLAGOS/Shared Documents/GSDP (GOOD STORAGE AND DISTRIBUTION PRACTICE)/GSDP COMPANY FILES\Santa Care LTD | N3: SANTA CARE | O3: https://nafdacng.sharepoint.com/sites/PMSLAGOS/Shared%20Documents/GSDP%20(GOOD%20STORAGE%20AND%20DISTRIBUTION%20PRACTICE)/GSDP%20COMPANY%20FILES/A.N%20CHIDOZIE%20PHARMACEUTICAL%20LTD
A4: 2 | B4: JANE-MADOK PHARMACY & WELLNESS CENTER | C4: 3, ISHERI OSUN RD., JAKANDE GATE, ISOLO | D4: 9035803090 | E4: GDP | F4: 45680 | G4: Medium-Risk (B) | H4: 25th january 2025 | I4: NO | J4: CAPA TO BE SUBMITTED | K4: =IF(I4="YES","CAPA VERIFICATION SHOULD BE SCHEDULED",IF(I4="NO","REMINDER LETTER SHOULD BE SENT","")) -> REMINDER LETTER SHOULD BE SENT | L4: 46023 | M4: https://nafdacng.sharepoint.com/sites/PMSLAGOS/Shared Documents/GSDP (GOOD STORAGE AND DISTRIBUTION PRACTICE)/GSDP COMPANY FILES\Jane-Madok | N4: =IF(M4="","",HYPERLINK(M4,B4)) -> JANE-MADOK PHARMACY & WELLNESS CENTER | O4: https://nafdacng.sharepoint.com/sites/PMSLAGOS/Shared Documents/GSDP (GOOD STORAGE AND DISTRIBUTION PRACTICE)/GSDP COMPANY FILES/A.N CHIDOZIE PHARMACEUTICAL LTD
A5: 3 | B5: ROCHE PRODUCTS LIMITED (MEDICAL DEVICES) | C5: AGL WAREHOUSE, KILOMETER11, OPPOSITE TOP MOUNTAIN UNIVERSITY, ALONG LAGOS IBADAN EXPRESSWAY, IBAFO | D5: 7033089165 | E5: GDP | F5: 45680 | G5: Medium-Risk (B) | H5: 11th February 2025 | I5: NO | J5: CAPA TO BE SUBMITTED | K5: =IF(I5="YES","CAPA VERIFICATION SHOULD BE SCHEDULED",IF(I5="NO","REMINDER LETTER SHOULD BE SENT","")) -> REMINDER LETTER SHOULD BE SENT | L5: 46054 | M5: https://nafdacng.sharepoint.com/sites/PMSLAGOS/Shared Documents/GSDP (GOOD STORAGE AND DISTRIBUTION PRACTICE)/GSDP COMPANY FILES\Roche Products ltd | N5: =IF(M5="","",HYPERLINK(M5,B5)) -> ROCHE PRODUCTS LIMITED (MEDICAL DEVICES)
A6: 4 | B6: KCH CONSUMER HEALTHCARE LTD. (CAPA) | C6: 2B KWAME NKRUMAH LANE, CROWN ESTATE, LEKKI-EPE EXPRESSWAY, AJAH | D6: 8022317625 | E6: CAPA | F6: 45685 | G6: Medium-Risk (B) | H6: 28th january 2025 | I6: YES | J6: CAPA SUBMITTED | K6: =IF(I6="YES","CAPA VERIFICATION SHOULD BE SCHEDULED",IF(I6="NO","REMINDER LETTER SHOULD BE SENT","")) -> CAPA VERIFICATION SHOULD BE SCHEDULED | L6: 46023 | M6: https://nafdacng.sharepoint.com/sites/PMSLAGOS/Shared Documents/GSDP (GOOD STORAGE AND DISTRIBUTION PRACTICE)/GSDP COMPANY FILES\KCH CONSUMER | N6: =IF(M6="","",HYPERLINK(M6,B6)) -> KCH CONSUMER HEALTHCARE LTD. (CAPA)
A7: 5 | B7: MUJID HEALTHCARE LTD | C7: PLOT B, GREENLAND ESTATE, AJAH | D7: 8033268130 | E7: GDP | F7: 45685 | G7: Medium-Risk (B) | H7: 45685 | I7: NO | J7: CAPA TO BE SUBMITTED | K7: =IF(I7="YES","CAPA VERIFICATION SHOULD BE SCHEDULED",IF(I7="NO","REMINDER LETTER SHOULD BE SENT","")) -> REMINDER LETTER SHOULD BE SENT | L7: 46023 | M7: https://nafdacng.sharepoint.com/sites/PMSLAGOS/Shared Documents/GSDP (GOOD STORAGE AND DISTRIBUTION PRACTICE)/GSDP COMPANY FILES\MULTIBASE | N7: =IF(M7="","",HYPERLINK(M7,B7)) -> MUJID HEALTHCARE LTD

Sheet February
A1: GDP INSPECTION CLASSIFICATION DATA BASE AS AT 2025
A2: S/N | B2: NAME OF MANUFACTURER | C2: LOCATION ADDRESS | D2: CONTACT | E2: TYPE OF LAST INSPECTION | F2: DATE OF LAST INSPECTION | G2: FINDINGS | H2: DATE CAPA ISSUED | I2: CAPA SUBMITTED | J2: CONCLUSION | K2: REMARKS | L2: EXPECTED DATE OF INSPECTION | M2: CC | N2: COMPANY FILE
A3: 6 | B3: ROCHE PRODUCTS LIMITED (MEDICAL DEVICES) | C3: ISN MEDICAL 40-42 ASSOCIATION AVENUE, ILUPEJU | D3: 7044644915 | E3: GDP | F3: 45693 | G3: Medium-Risk (B) | H3: 45685 | I3: NO | J3: CAPA TO BE SUBMITTED | K3: =IF(I3="YES","CAPA VERIFICATION SHOULD BE SCHEDULED",IF(I3="NO","REMINDER LETTER SHOULD BE SENT","")) -> REMINDER LETTER SHOULD BE SENT | L3: 45683 | N3: =IF(M3="","",HYPERLINK(M3,B3))

Sheet March
A1: GDP INSPECTION CLASSIFICATION DATA BASE AS AT 2025
A2: S/N | B2: NAME OF MANUFACTURER | C2: LOCATION ADDRESS | D2: CONTACT | E2: TYPE OF LAST INSPECTION | F2: DATE OF LAST INSPECTION | G2: FINDINGS | H2: DATE CAPA ISSUED | I2: CAPA SUBMITTED | J2: CONCLUSION | K2: REMARKS | L2: EXPECTED DATE OF INSPECTION | M2: CC | N2: COMPANY FILE
A3: 7 | B3: EUROMED LTD | E3: GDP | F3: 45734 | G3: Medium-Risk (B) | H3: 25TH MARCH 2025 | I3: YES | J3: CAPA SUBMITTED | K3: =IF(I3="YES","CAPA VERIFICATION SHOULD BE SCHEDULED",IF(I3="NO","REMINDER LETTER SHOULD BE SENT","")) -> CAPA VERIFICATION SHOULD BE SCHEDULED | L3: 45870 | M3: https://nafdacng.sharepoint.com/sites/PMSLAGOS/Shared Documents/GSDP (GOOD STORAGE AND DISTRIBUTION PRACTICE)/GSDP COMPANY FILES\EUROMED | N3: =IF(M3="","",HYPERLINK(M3,B3)) -> EUROMED LTD
A4: 8 | B4: GREENLIFE PHARMA CEUTICALS LTD. (CAPA) | C4: 35A, ASSOCIATION AVENUE, OFF OBANIKORO BUS STOP, ILUPEJU | D4: 8132993626 | E4: CAPA | F4: 45734 | G4: Low-Risk (A) | H4: N/A | I4: YES | J4: CLOSED | K4: CLOSED | L4: 46447 | M4: https://nafdacng.sharepoint.com/sites/PMSLAGOS/Shared Documents/GSDP (GOOD STORAGE AND DISTRIBUTION PRACTICE)/GSDP COMPANY FILES\GREENLIFE PHARM. LTD | N4: =IF(M4="","",HYPERLINK(M4,B4)) -> GREENLIFE PHARMA CEUTICALS LTD. (CAPA)
A5: 9 | B5: DORTEMAG PHARM. & STORES | C5: 381G, TITILAYO ADEDOYIN STR., OMOLE EST. PHASE 1, OGBA-IKEJA | D5: PHARM. SEYE AGBOOLA 0803315214 | E5: GDP | F5: 45734 | G5: Medium-Risk (B) | H5: 18TH MARCH 2025 | I5: NO | J5: CAPA TO BE SUBMITTED | K5: =IF(I5="YES","CAPA VERIFICATION SHOULD BE SCHEDULED",IF(I5="NO","REMINDER LETTER SHOULD BE SENT","")) -> REMINDER LETTER SHOULD BE SENT | L5: 46082 | M5: https://nafdacng.sharepoint.com/sites/PMSLAGOS/Shared Documents/GSDP (GOOD STORAGE AND DISTRIBUTION PRACTICE)/GSDP COMPANY FILES\DORTEMAG | N5: =IF(M5="","",HYPERLINK(M5,B5)) -> DORTEMAG PHARM. & STORES
A6: 10 | B6: HEALTHLINE NIG. LTD | C6: 29, ADENIYI JONES AVENUE, IKEJA | D6: MRS. ITUNU AJAYI 08030678801 | E6: GDP | F6: 45734 | G6: Medium-Risk (B) | H6: 18TH MRCH 2025 | I6: NO | J6: CAPA TO BE SUBMITTED | K6: =IF(I6="YES","CAPA VERIFICATION SHOULD BE SCHEDULED",IF(I6="NO","REMINDER LETTER SHOULD BE SENT","")) -> REMINDER LETTER SHOULD BE SENT | L6: 45717 | M6: https://nafdacng.sharepoint.com/sites/PMSLAGOS/Shared Documents/GSDP (GOOD STORAGE AND DISTRIBUTION PRACTICE)/GSDP COMPANY FILES\HEALTHLINE NIG. LTD | N6: =IF(M6="","",HYPERLINK(M6,B6)) -> HEALTHLINE NIG. LTD
A7: 11 | B7: GETZPHARMA NIG. LTD | C7: PLOT 2, IJA ODOLA CLOSE IKEJA GRA | D7: OBEGOLU NNEKA 08165370750 | E7: GDP | F7: 45734 | G7: Medium-Risk (B) | H7: 18TH MARCH 2025 | I7: NO | J7: CAPA TO BE SUBMITTED | K7: =IF(I7="YES","CAPA VERIFICATION SHOULD BE SCHEDULED",IF(I7="NO","REMINDER LETTER SHOULD BE SENT","")) -> REMINDER LETTER SHOULD BE SENT | L7: 45717 | M7: https://nafdacng.sharepoint.com/sites/PMSLAGOS/Shared Documents/GSDP (GOOD STORAGE AND DISTRIBUTION PRACTICE)/GSDP COMPANY FILES\GETZ PHARM NIG. LTD | N7: =IF(M7="","",HYPERLINK(M7,B7)) -> GETZPHARMA NIG. LTD
A8: 12 | B8: SHEPHERD HEALTH & VETERINARY LTD. | C8: 24, MONTGOMERY RD., YABA | D8: JOSEPH ADETUNJI 08037184254 | E8: GDP | F8: 45735 | G8: Medium-Risk (B) | H8: 19TH MARCH 2025 | I8: YES | J8: CAPA TO BE SUBMITTED | K8: =IF(I8="YES","CAPA VERIFICATION SHOULD BE SCHEDULED",IF(I8="NO","REMINDER LETTER SHOULD BE SENT","")) -> CAPA VERIFICATION SHOULD BE SCHEDULED | L8: 45717 | M8: https://nafdacng.sharepoint.com/sites/PMSLAGOS/Shared Documents/GSDP (GOOD STORAGE AND DISTRIBUTION PRACTICE)/GSDP COMPANY FILES\SHEPHERD HEALTH | N8: =IF(M8="","",HYPERLINK(M8,B8)) -> SHEPHERD HEALTH & VETERINARY LTD.
A9: 13 | B9: ADCEM PHARMACEUTICALS LTD | C9: 2, NIWILI CLOSE, IKEJA | D9: OKEKE ONYEKACHI 08123915479 | E9: GDP | F9: 45735 | G9: Medium-Risk (B) | I9: N/A | J9: CAPA TO BE SUBMITTED | K9: =IF(I9="YES","CAPA VERIFICATION SHOULD BE SCHEDULED",IF(I9="NO","REMINDER LETTER SHOULD BE SENT","")) | L9: 45717 | M9: https://nafdacng.sharepoint.com/sites/PMSLAGOS/Shared Documents/GSDP (GOOD STORAGE AND DISTRIBUTION PRACTICE)/GSDP COMPANY FILES\Adcem | N9: =IF(M9="","",HYPERLINK(M9,B9)) -> ADCEM PHARMACEUTICALS LTD
A10: 14 | B10: ADDMORE PHARMACY | C10: 251, AGEGE-MOTOR ROAD, MUSHIN | D10: BENSON NDULUE 08023019928 | E10: GDP | F10: 45735 | G10: Medium-Risk (B) | H10: 19TH MARCH 2025 | I10: NO | J10: CAPA TO BE SUBMITTED | K10: =IF(I10="YES","CAPA VERIFICATION SHOULD BE SCHEDULED",IF(I10="NO","REMINDER LETTER SHOULD BE SENT","")) -> REMINDER LETTER SHOULD BE SENT | L10: 45717 | M10: https://nafdacng.sharepoint.com/sites/PMSLAGOS/Shared Documents/GSDP (GOOD STORAGE AND DISTRIBUTION PRACTICE)/GSDP COMPANY FILES\Addmore | N10: =IF(M10="","",HYPERLINK(M10,B10)) -> ADDMORE PHARMACY
A11: 15 | B11: AXION PHARMACEUTICALS LTD | C11: 13, MODUPE STREET, SOMOLU, LAGOS. | D11: PHARM. ONYINYE 07061902283 | E11: GDP | F11: 45736 | G11: High-Risk (C) | H11: N/A | I11: NO | J11: CAPA TO BE SUBMITTED | K11: =IF(I11="YES","CAPA VERIFICATION SHOULD BE SCHEDULED",IF(I11="NO","REMINDER LETTER SHOULD BE SENT","")) -> REMINDER LETTER SHOULD BE SENT | L11: 45901 | M11: https://nafdacng.sharepoint.com/sites/PMSLAGOS/Shared Documents/GSDP (GOOD STORAGE AND DISTRIBUTION PRACTICE)/GSDP COMPANY FILES\Axion | N11: =IF(M11="","",HYPERLINK(M11,B11)) -> AXION PHARMACEUTICALS LTD
A12: 16 | B12: MED EXPRESS | C12: 7A, ADEWALE KOLAWOLE CRESCENT, OFF KUBOYE STR., MARUWA, LEKKI | D12: RUEMU OKUNDIA 08033001059 | E12: GDP | F12: 45736 | G12: Low-Risk (A) | H12: 19TH MARCH 2025 | I12: YES | J12: CAPA SUBMITTED | K12: DONE | L12: SATISFACTORY | M12: https://nafdacng.sharepoint.com/sites/PMSLAGOS/Shared Documents/GSDP (GOOD STORAGE AND DISTRIBUTION PRACTICE)/GSDP COMPANY FILES\MEDEXPRESS | N12: =IF(M12="","",HYPERLINK(M12,B12)) -> MED EXPRESS
A13: 20 | B13: SOLID ACCORD LTD | C13: 85B, FEMI KILLA RD., OFF AGO PALACE WAY, OKOTA | D13: MR FRANCIS OHALE 08033738531 | E13: GDP | F13: 45736 | G13: High-Risk (C) | H13: 21ST MARCH 2025 | I13: YES | J13: CAPA SUBMITTED | K13: =IF(I13="YES","CAPA VERIFICATION SHOULD BE SCHEDULED",IF(I13="NO","REMINDER LETTER SHOULD BE SENT","")) -> CAPA VERIFICATION SHOULD BE SCHEDULED | L13: 45742 | M13: https://nafdacng.sharepoint.com/sites/PMSLAGOS/Shared Documents/GSDP (GOOD STORAGE AND DISTRIBUTION PRACTICE)/GSDP COMPANY FILES\Solid Accord | N13: =IF(M13="","",HYPERLINK(M13,B13)) -> SOLID ACCORD LTD
A14: 21 | B14: AQUATIX PHARM. LTD | C14: 9, DAVE ANAZODO STREET, NEAR CHIVITA COMPANY, AJAO ESTATE | D14: MR. PRADEEP CHAUDHARY 08025555568 | E14: GDP | F14: 45736 | G14: Low-Risk (A) | H14: 21ST MARCH 2025 | I14: NO | J14: CAPA TO BE SUBMITTED | K14: =IF(I14="YES","CAPA VERIFICATION SHOULD BE SCHEDULED",IF(I14="NO","REMINDER LETTER SHOULD BE SENT","")) -> REMINDER LETTER SHOULD BE SENT | L14: 45925 | M14: https://nafdacng.sharepoint.com/sites/PMSLAGOS/Shared Documents/GSDP (GOOD STORAGE AND DISTRIBUTION PRACTICE)/GSDP COMPANY FILES\AQUATIX | N14: =IF(M14="","",HYPERLINK(M14,B14)) -> AQUATIX PHARM. LTD
A15: 22 | B15: SAI SAGAR | C15: 2, KAARA STREET.,OFF OSOLO WAY,AJAO ESTATE,LAGOS | D15: PHARM. OKEKE UCHE 07055244581 | E15: GDP | F15: 45736 | G15: High-Risk (C) | H15: 21ST MARCH 2025 | I15: NO | J15: CAPA TO BE SUBMITTED | K15: =IF(I15="YES","CAPA VERIFICATION SHOULD BE SCHEDULED",IF(I15="NO","REMINDER LETTER SHOULD BE SENT","")) -> REMINDER LETTER SHOULD BE SENT | L15: 45901 | M15: https://nafdacng.sharepoint.com/sites/PMSLAGOS/Shared%20Documents/GDP%20(GOOD%20DISTRIBUTION%20PRATICE)/GSDP%20COMPANY%20FILES/ICE%20REMEDIES | N15: =IF(M15="","",HYPERLINK(M15,B15)) -> SAI SAGAR

Sheet April
A1: GDP INSPECTION CLASSIFICATION DATA BASE AS AT 2025
A2: S/N | B2: NAME OF MANUFACTURER | C2: LOCATION ADDRESS | D2: CONTACT | E2: TYPE OF LAST INSPECTION | F2: DATE OF LAST INSPECTION | G2: FINDINGS | H2: DATE CAPA ISSUED | I2: CAPA SUBMITTED | J2: CONCLUSION | K2: REMARKS | L2: EXPECTED DATE OF INSPECTION | M2: CC | N2: COMPANY FILE
A3: 23 | B3: MAYDON PHARM. & CHEM. CO. LTD. | C3: 15, WILMER STREET, OFF TOWN PLANNING WAY, ILUPEJU | D3: Pharm. PE Orazukile 08034304758 | E3: GDP | F3: 45762 | G3: Medium-Risk (B) | H3: 5TH MAY 2025 | I3: YES | J3: CAPA SUBMITTED | K3: =IF(I3="YES","CAPA VERIFICATION SHOULD BE SCHEDULED",IF(I3="NO","REMINDER LETTER SHOULD BE SENT","")) -> CAPA VERIFICATION SHOULD BE SCHEDULED | L3: 45748 | M3: https://nafdacng.sharepoint.com/sites/PMSLAGOS/Shared Documents/GSDP (GOOD STORAGE AND DISTRIBUTION PRACTICE)/GSDP COMPANY FILES\MAYDON | N3: =IF(M3="","",HYPERLINK(M3,B3)) -> MAYDON PHARM. & CHEM. CO. LTD.
A4: 24 | B4: ALMOND ETHICALS LTD | C4: 2B, MOJOLA STREET, AJAO ESTATE, ANTHONY VILLAGE LAGOS | D4: THEODORE R. OKAFOR 08033324448 | E4: GDP | F4: 45762 | G4: Medium-Risk (B) | H4: 5TH MAY 2025 | I4: NO | J4: CAPA TO BE SUBMITTED | K4: =IF(I4="YES","CAPA VERIFICATION SHOULD BE SCHEDULED",IF(I4="NO","REMINDER LETTER SHOULD BE SENT","")) -> REMINDER LETTER SHOULD BE SENT | L4: 45748 | M4: https://nafdacng.sharepoint.com/sites/PMSLAGOS/Shared%20Documents/GDP%20(GOOD%20DISTRIBUTION%20PRATICE)/GSDP%20COMPANY%20FILES\ALMOND%20ETHICALS | N4: =IF(M4="","",HYPERLINK(M4,B4)) -> ALMOND ETHICALS LTD
A5: 25 | B5: EJIMATH PHARMACY LTD. | C5: 10, ABEOKUTA STREET, OFF ABEOKUTA EXPRESS ROAD, PLEASURE, ALIMOSHO, LAGOS | D5: Pharm. (Dr.) Agu Nnamdulu | E5: GDP | F5: 45762 | G5: Medium-Risk (B) | H5: 23RD APRIL 2025 | I5: NO | J5: CAPA TO BE SUBMITTED | K5: =IF(I5="YES","CAPA VERIFICATION SHOULD BE SCHEDULED",IF(I5="NO","REMINDER LETTER SHOULD BE SENT","")) -> REMINDER LETTER SHOULD BE SENT | L5: 45773 | M5: https://nafdacng.sharepoint.com/sites/PMSLAGOS/Shared Documents/GSDP (GOOD STORAGE AND DISTRIBUTION PRACTICE)/GSDP COMPANY FILES\EJIMATH | N5: =IF(M5="","",HYPERLINK(M5,B5)) -> EJIMATH PHARMACY LTD.
A6: 26 | B6: NAFRO PHARMA NIG. LTD. | C6: SUITE B16, AMORI SHOPPING PLAZA, EGBEDA. | D6: Abasilim 08033262248 | E6: GDP | F6: 45762 | G6: Medium-Risk (B) | H6: 23RD APRIL 2025 | I6: NO | J6: CAPA TO BE SUBMITTED | K6: =IF(I6="YES","CAPA VERIFICATION SHOULD BE SCHEDULED",IF(I6="NO","REMINDER LETTER SHOULD BE SENT","")) -> REMINDER LETTER SHOULD BE SENT | L6: 45748 | M6: https://nafdacng.sharepoint.com/sites/PMSLAGOS/Shared Documents/GSDP (GOOD STORAGE AND DISTRIBUTION PRACTICE)/GSDP COMPANY FILES\NANCIL1 | N6: =IF(M6="","",HYPERLINK(M6,B6)) -> NAFRO PHARMA NIG. LTD.
A7: 27 | B7: THOMPSON & GRACE PHARM. LTD. | C7: 7, MORONU MADUAGWU STR., OFF MASHA, SURULERE | D7: Pharm. Anthony Otaigbe 07060954163 | E7: GDP | F7: 45763 | G7: Medium-Risk (B) | J7: CAPA TO BE SUBMITTED | K7: =IF(I7="YES","CAPA VERIFICATION SHOULD BE SCHEDULED",IF(I7="NO","REMINDER LETTER SHOULD BE SENT","")) | L7: 45748 | M7: https://nafdacng.sharepoint.com/sites/PMSLAGOS/Shared Documents/GSDP (GOOD STORAGE AND DISTRIBUTION PRACTICE)/GSDP COMPANY FILES\Thompson & Grace Pharm | N7: =IF(M7="","",HYPERLINK(M7,B7)) -> THOMPSON & GRACE PHARM. LTD.
A8: 28 | B8: GLOBAL ONE WORD HEALTHCARE | C8: 30B TOWOLAWI, COKER VILLAGE, ORILE IGANMU, SURULERE | D8: PHARM. IFE ADETIFA 07033775248 | E8: GDP | F8: 45763 | G8: Medium-Risk (B) | H8: 24TH APRIL 2025 | I8: YES | J8: CAPA SUBMITTED | K8: =IF(I8="YES","CAPA VERIFICATION SHOULD BE SCHEDULED",IF(I8="NO","REMINDER LETTER SHOULD BE SENT","")) -> CAPA VERIFICATION SHOULD BE SCHEDULED | L8: 45748 | M8: https://nafdacng.sharepoint.com/sites/PMSLAGOS/Shared Documents/GSDP (GOOD STORAGE AND DISTRIBUTION PRACTICE)/GSDP COMPANY FILES\Global One healthcare | N8: =IF(M8="","",HYPERLINK(M8,B8)) -> GLOBAL ONE WORD HEALTHCARE
A9: 29 | B9: LABETA DRUGS LTD. | C9: 16, BADARU STREET, BY MASHA BUSSTOP, SURULERE | D9: Elizabeth Amomo 08023263729 | E9: GDP | F9: 45763 | G9: Medium-Risk (B) | H9: 24TH APRIL 2025 | I9: YES | J9: CAPA SUBMITTED | K9: =IF(I9="YES","CAPA VERIFICATION SHOULD BE SCHEDULED",IF(I9="NO","REMINDER LETTER SHOULD BE SENT","")) -> CAPA VERIFICATION SHOULD BE SCHEDULED | L9: 45748 | M9: https://nafdacng.sharepoint.com/sites/PMSLAGOS/Shared Documents/GSDP (GOOD STORAGE AND DISTRIBUTION PRACTICE)/GSDP COMPANY FILES\LABETA | N9: =IF(M9="","",HYPERLINK(M9,B9)) -> LABETA DRUGS LTD.
A10: 30 | B10: MULTIBASE PHARMA IND. NIG. LTD | C10: 7A, AJIBADE OKE STR., AJAO ESTATE | D10: 8033183813 | E10: GDP | F10: 45764 | G10: Low-Risk (A) | I10: YES | J10: NO CAPA UNTIL IMPORTATION BEGINS | K10: =IF(I10="YES","CAPA VERIFICATION SHOULD BE SCHEDULED",IF(I10="NO","REMINDER LETTER SHOULD BE SENT","")) -> CAPA VERIFICATION SHOULD BE SCHEDULED | L10: 46113 | M10: https://nafdacng.sharepoint.com/sites/PMSLAGOS/Shared Documents/GSDP (GOOD STORAGE AND DISTRIBUTION PRACTICE)/GSDP COMPANY FILES\MULTICHARIS PHARMACY & CHEM | N10: =IF(M10="","",HYPERLINK(M10,B10)) -> MULTIBASE PHARMA IND. NIG. LTD
A11: 31 | B11: GENERICS & SPECIALITIES LTD (CAPA) | C11: 9, DAVE ANAZODO STREET, NEAR CHIVITA COMPANY, AJAO ESTATE | D11: Pharm. Cyril Odidika | E11: CAPA | F11: 45764 | G11: Low-Risk (A) | J11: CLOSED | K11: CONTINOUS MONITORING TO ENSURE COMPLAINCE | L11: SATISFACTORY | M11: https://nafdacng.sharepoint.com/sites/PMSLAGOS/Shared Documents/GSDP (GOOD STORAGE AND DISTRIBUTION PRACTICE)/GSDP COMPANY FILES\GENERICS & SPECIALITIES | N11: =IF(M11="","",HYPERLINK(M11,B11)) -> GENERICS & SPECIALITIES LTD (CAPA)
A12: 32 | B12: NANCIL NIG. LTD. | C12: 1, CEDAR ROAD, OFF OJODU ABIODUN ROAD, OJODU BERGER | D12: Pharm. Chizoba Akubue | E12: GDP | F12: 45764 | G12: Medium-Risk (B) | H12: 22ND APRIL 2025 | I12: YES | J12: CAPA SUBMITTED | K12: DONE | L12: SATISFACTORY | M12: https://nafdacng.sharepoint.com/sites/PMSLAGOS/Shared Documents/GSDP (GOOD STORAGE AND DISTRIBUTION PRACTICE)/GSDP COMPANY FILES\NEAT LINE PHARM LTD | N12: =IF(M12="","",HYPERLINK(M12,B12)) -> NANCIL NIG. LTD.
A13: 33 | B13: TETA PHARM. LTD.(CAPA) | C13: 4, OKEHO STREET, IREAKARI ESTATE, ISOLO | D13: Pharm. George Akinsuli | E13: CAPA | F13: 45764 | G13: Medium-Risk (B) | H13: 24TH APRIL 2025 | I13: YES | J13: CAPA SUBMITTED | K13: =IF(I13="YES","CAPA VERIFICATION SHOULD BE SCHEDULED",IF(I13="NO","REMINDER LETTER SHOULD BE SENT","")) -> CAPA VERIFICATION SHOULD BE SCHEDULED | L13: 45748 | M13: https://nafdacng.sharepoint.com/sites/PMSLAGOS/Shared Documents/GSDP (GOOD STORAGE AND DISTRIBUTION PRACTICE)/GSDP COMPANY FILES\TEKA PHARM | N13: =IF(M13="","",HYPERLINK(M13,B13)) -> TETA PHARM. LTD.(CAPA)
A14: 34 | B14: VITANE PHARM. NIG. LTD. | D14: M.ALATEEKS | E14: GDP | F14: 45762 | G14: Low-Risk (A) | J14: CAPA TO BE SUBMITTED | K14: =IF(I14="YES","CAPA VERIFICATION SHOULD BE SCHEDULED",IF(I14="NO","REMINDER LETTER SHOULD BE SENT","")) | L14: 46113 | N14: =IF(M14="","",HYPERLINK(M14,B14))

Sheet May
A1: GDP INSPECTION CLASSIFICATION DATA BASE AS AT 2025
A2: S/N | B2: NAME OF MANUFACTURER | C2: LOCATION ADDRESS | D2: CONTACT | E2: TYPE OF LAST INSPECTION | F2: DATE OF LAST INSPECTION | G2: FINDINGS | H2: DATE CAPA ISSUED | I2: CAPA SUBMITTED | J2: CONCLUSION | K2: REMARKS | L2: EXPECTED DATE OF INSPECTION | M2: CC | N2: COMPANY FILE
A3: 35 | B3: ORANGE DRUGS LTD. | C3: 66/68, TOWN PLANNING WAY, ILUPEJU | D3: 8036005454 | E3: GDP | F3: 45797 | G3: Medium-Risk (B) | H3: 21ST MAY 2025 | I3: NO | J3: CAPA TO BE SUBMITTED | K3: =IF(I3="YES","CAPA VERIFICATION SHOULD BE SCHEDULED",IF(I3="NO","REMINDER LETTER SHOULD BE SENT","")) -> REMINDER LETTER SHOULD BE SENT | L3: 45778 | M3: https://nafdacng.sharepoint.com/sites/PMSLAGOS/Shared Documents/GSDP (GOOD STORAGE AND DISTRIBUTION PRACTICE)/GSDP COMPANY FILES\Orange drugs ltd | N3: =IF(M3="","",HYPERLINK(M3,B3)) -> ORANGE DRUGS LTD.
A4: 36 | B4: GLOBAL HEALTHCARE LTD | C4: 12, OLUSOJI IDOWU STREET, OFF ADEKUNLE ODUNLAMI CRESCERNT, ILUPEJU | D4: OLADIMEJI GBOTOSO 08033371573 | E4: GDP | F4: 45797 | G4: Medium-Risk (B) | H4: 21ST MAY 2025 | I4: NO | J4: CAPA TO BE SUBMITTED | K4: =IF(I4="YES","CAPA VERIFICATION SHOULD BE SCHEDULED",IF(I4="NO","REMINDER LETTER SHOULD BE SENT","")) -> REMINDER LETTER SHOULD BE SENT | L4: 45778 | M4: https://nafdacng.sharepoint.com/sites/PMSLAGOS/Shared Documents/GSDP (GOOD STORAGE AND DISTRIBUTION PRACTICE)/GSDP COMPANY FILES\Global Healthcare Ltd | N4: =IF(M4="","",HYPERLINK(M4,B4)) -> GLOBAL HEALTHCARE LTD
A5: 37 | B5: OXUS PHARMA LTD. | C5: 20, OGUNAIKE STREET, OFF SHIPEOLU STREET, PALMGROOVE | D5: PHARM. EGBUNIKE 08065139357 | E5: GDP | F5: 45797 | G5: Medium-Risk (B) | H5: 21ST MAY 2025 | I5: NO | J5: CAPA TO BE SUBMITTED | K5: =IF(I5="YES","CAPA VERIFICATION SHOULD BE SCHEDULED",IF(I5="NO","REMINDER LETTER SHOULD BE SENT","")) -> REMINDER LETTER SHOULD BE SENT | L5: 45778 | M5: https://nafdacng.sharepoint.com/sites/PMSLAGOS/Shared Documents/GSDP (GOOD STORAGE AND DISTRIBUTION PRACTICE)/GSDP COMPANY FILES\Oxus pharma | N5: =IF(M5="","",HYPERLINK(M5,B5)) -> OXUS PHARMA LTD.
A6: 38 | B6: MICRONOVA PHARM. INDT. LTD | C6: PLOT 3, BILLINGS WAY, OREGUN IND ESTATE, IKEJA | D6: OGUEF SOLOMON 08033555665 | E6: GDP | F6: 45797 | G6: Medium-Risk (B) | H6: 26TH MAY 2025 | I6: NO | J6: CAPA TO BE SUBMITTED | K6: =IF(I6="YES","CAPA VERIFICATION SHOULD BE SCHEDULED",IF(I6="NO","REMINDER LETTER SHOULD BE SENT","")) -> REMINDER LETTER SHOULD BE SENT | L6: 45778 | M6: https://nafdacng.sharepoint.com/sites/PMSLAGOS/Shared Documents/GSDP (GOOD STORAGE AND DISTRIBUTION PRACTICE)/GSDP COMPANY FILES\Mid century Agro Allied Ventures | N6: =IF(M6="","",HYPERLINK(M6,B6)) -> MICRONOVA PHARM. INDT. LTD
A7: 39 | B7: TURNER WRIGHT LTD. | C7: 15, ADENEKAN SALAKO STR., OGBA, IKEJA | D7: PHARM. F. AKINDELE 08033068480 | E7: GDP | F7: 45797 | G7: Medium-Risk (B) | H7: 25TH MAY 2025 | I7: NO | J7: CAPA TO BE SUBMITTED | K7: =IF(I7="YES","CAPA VERIFICATION SHOULD BE SCHEDULED",IF(I7="NO","REMINDER LETTER SHOULD BE SENT","")) -> REMINDER LETTER SHOULD BE SENT | L7: 45778 | M7: https://nafdacng.sharepoint.com/sites/PMSLAGOS/Shared%20Documents/GDP%20(GOOD%20DISTRIBUTION%20PRATICE)/GSDP%20COMPANY%20FILES/TURNER%20WRIGHT%20LTD | N7: =IF(M7="","",HYPERLINK(M7,B7)) -> TURNER WRIGHT LTD.
A8: 40 | B8: BRIAN MUNRO LTD | C8: 25, IZE IYAMU STR., OFF BILLINGSWAY, OREGUN | D8: PHARM. OLORUNSOLA BOLUWATIFE 08060378307 | E8: GDP | F8: 45799 | G8: Medium-Risk (B) | H8: 23RD MAY 2025 | I8: NO | J8: CAPA TO BE SUBMITTED | K8: =IF(I8="YES","CAPA VERIFICATION SHOULD BE SCHEDULED",IF(I8="NO","REMINDER LETTER SHOULD BE SENT","")) -> REMINDER LETTER SHOULD BE SENT | L8: 45778 | M8: https://nafdacng.sharepoint.com/sites/PMSLAGOS/Shared Documents/GSDP (GOOD STORAGE AND DISTRIBUTION PRACTICE)/GSDP COMPANY FILES\Brian Munroe | N8: =IF(M8="","",HYPERLINK(M8,B8)) -> BRIAN MUNRO LTD
A9: 41 | B9: SAGAR VITACEUTICALS (CAPA) | C9: PLOT 2, LADIPO OLUWOLE STR., OFF AKRAN AVENUE, IKEJA | D9: PHARM. AJENIFUJA 08023692457 | E9: CAPA | F9: 45799 | G9: Low-Risk (A) | H9: 23RD MAY 2025 | I9: YES | J9: CAPA SUBMITTED | K9: CLOSED | L9: 45778 | M9: https://nafdacng.sharepoint.com/sites/PMSLAGOS/Shared Documents/GSDP (GOOD STORAGE AND DISTRIBUTION PRACTICE)/GSDP COMPANY FILES\SAGAR VITACEAUTICALS NIG LTD | N9: =IF(M9="","",HYPERLINK(M9,B9)) -> SAGAR VITACEUTICALS (CAPA)
A10: 42 | B10: NEIMETH INTERNATIONAL PHARMACEUTICALS PLC | C10: PLOT 16, AKANNI DOHERTY LAYOUT, BILLINGS WAY OREGUN INDUSTRIAL ROAD | D10: PHARM. ONWUBUYA PHILIP 08085246483 | E10: GDP | F10: 45799 | G10: Medium-Risk (B) | H10: 23RD MAY 2025 | I10: YES | J10: CAPA SUBMITTED | K10: =IF(I10="YES","CAPA VERIFICATION SHOULD BE SCHEDULED",IF(I10="NO","REMINDER LETTER SHOULD BE SENT","")) -> CAPA VERIFICATION SHOULD BE SCHEDULED | L10: 46143 | M10: https://nafdacng.sharepoint.com/sites/PMSLAGOS/Shared Documents/GSDP (GOOD STORAGE AND DISTRIBUTION PRACTICE)/GSDP COMPANY FILES\NEMITT PHARMACEUTICALS LTD | N10: =IF(M10="","",HYPERLINK(M10,B10)) -> NEIMETH INTERNATIONAL PHARMACEUTICALS PLC
A11: 43 | B11: EVERSHINE PHARMACEUTICAL NIG. LTD. (CAPA) | C11: 41, AMOKE ALASALA STREET, IYANA IPAJA, LAGOS. | D11: PHARM. CLETHS S.N. 08062744196 | E11: CAPA | F11: 45799 | G11: Medium-Risk (B) | H11: 23RD MAY 2025 | I11: NO | J11: CAPA TO BE SUBMITTED | K11: =IF(I11="YES","CAPA VERIFICATION SHOULD BE SCHEDULED",IF(I11="NO","REMINDER LETTER SHOULD BE SENT","")) -> REMINDER LETTER SHOULD BE SENT | L11: 45778 | M11: https://nafdacng.sharepoint.com/sites/PMSLAGOS/Shared Documents/GSDP (GOOD STORAGE AND DISTRIBUTION PRACTICE)/GSDP COMPANY FILES\EVERSHINE PHARMA NIG LTD | N11: =IF(M11="","",HYPERLINK(M11,B11)) -> EVERSHINE PHARMACEUTICAL NIG. LTD. (CAPA)
A12: 44 | B12: ASSENE-LABOREX LTD | C12: PLT. 2 & 4, BLK. D, IND. SCHEME, APAPA-OSHODI E-WAY | D12: PHARM. TIMI ESO 08184544791 | E12: GDP | F12: 45799 | G12: Low-Risk (A) | H12: N/A | I12: NO | J12: CLOSED | K12: CLOSED | L12: SATISFACTORY | M12: https://nafdacng.sharepoint.com/sites/PMSLAGOS/Shared Documents/GSDP (GOOD STORAGE AND DISTRIBUTION PRACTICE)/GSDP COMPANY FILES\Assene-LABOREX | N12: =IF(M12="","",HYPERLINK(M12,B12)) -> ASSENE-LABOREX LTD
A13: 45 | B13: PEMASON PHARMACY LTD | C13: NO. 15, REGINAL PETER CHIDIEBERE STREET, HOPE ESTATE, ISOLO | D13: PHARM. OGBANUSI 08034000540 | E13: GDP | F13: 45799 | G13: Medium-Risk (B) | H13: N/A | I13: NO | J13: CAPA TO BE SUBMITTED | K13: =IF(I13="YES","CAPA VERIFICATION SHOULD BE SCHEDULED",IF(I13="NO","REMINDER LETTER SHOULD BE SENT","")) -> REMINDER LETTER SHOULD BE SENT | L13: 45778 | M13: https://nafdacng.sharepoint.com/sites/PMSLAGOS/Shared Documents/GSDP (GOOD STORAGE AND DISTRIBUTION PRACTICE)/GSDP COMPANY FILES\PEMASON | N13: =IF(M13="","",HYPERLINK(M13,B13)) -> PEMASON PHARMACY LTD
A14: 46 | B14: NKOYO CHEMIST | C14: 23, AGBONYIN STREET, AGUDA, SURULERE | D14: PHARM. CHISOM 08035747466 | E14: GDP | F14: 45799 | G14: Medium-Risk (B) | H14: N/A | I14: NO | J14: CAPA TO BE SUBMITTED | K14: =IF(I14="YES","CAPA VERIFICATION SHOULD BE SCHEDULED",IF(I14="NO","REMINDER LETTER SHOULD BE SENT","")) -> REMINDER LETTER SHOULD BE SENT | L14: 45778 | M14: https://nafdacng.sharepoint.com/sites/PMSLAGOS/Shared Documents/GSDP (GOOD STORAGE AND DISTRIBUTION PRACTICE)/GSDP COMPANY FILES/EUROMED | N14: =IF(M14="","",HYPERLINK(M14,B14)) -> NKOYO CHEMIST

Sheet June
A1: GDP INSPECTION CLASSIFICATION DATA BASE AS AT 2025
A2: S/N | B2: NAME OF MANUFACTURER | C2: LOCATION ADDRESS | D2: CONTACT | E2: TYPE OF LAST INSPECTION | F2: DATE OF LAST INSPECTION | G2: FINDINGS | H2: DATE CAPA ISSUED | I2: CAPA SUBMITTED | J2: CONCLUSION | K2: REMARKS | L2: EXPECTED DATE OF INSPECTION | M2: CC | N2: COMPANY FILE
A3: 47 | B3: EVANS THERAPEUTICS | C3: 24,ABIMBOLA WAY,ISOLO LAGOS | D3: PHARM. ADEMOLA ADEKUNLE | E3: GDP | F3: 45827 | G3: Low-Risk (A) | H3: 24th june 2025 | I3: NO | J3: CAPA TO BE SUBMITTED | K3: =IF(I3="YES","CAPA VERIFICATION SHOULD BE SCHEDULED",IF(I3="NO","REMINDER LETTER SHOULD BE SENT","")) -> REMINDER LETTER SHOULD BE SENT | L3: 46174 | M3: https://nafdacng.sharepoint.com/sites/PMSLAGOS/Shared Documents/GSDP (GOOD STORAGE AND DISTRIBUTION PRACTICE)/GSDP COMPANY FILES\EVANS THERAPEUTICS | N3: =IF(M3="","",HYPERLINK(M3,B3)) -> EVANS THERAPEUTICS
A4: 48 | B4: STRIDES LIFESCIENCES LTD | C4: CHEMLINE HOUSE 7,OBASA STREET,OFF OBA AKRAN AVENUE,IKEJA | D4: PHARM. KELECHI EKE | E4: GDP | F4: 45827 | G4: Medium-Risk (B) | H4: 24th june 2025 | I4: NO | J4: CAPA TO BE SUBMITTED | K4: =IF(I4="YES","CAPA VERIFICATION SHOULD BE SCHEDULED",IF(I4="NO","REMINDER LETTER SHOULD BE SENT","")) -> REMINDER LETTER SHOULD BE SENT | L4: 45809 | M4: https://nafdacng.sharepoint.com/sites/PMSLAGOS/Shared Documents/GSDP (GOOD STORAGE AND DISTRIBUTION PRACTICE)/GSDP COMPANY FILES\STRIDELIFESCIENCES | N4: =IF(M4="","",HYPERLINK(M4,B4)) -> STRIDES LIFESCIENCES LTD
A5: 49 | B5: KUNIMED PHARMACHEM LTD | C5: 18/20 MORTUNE AVENUE,VALLEY ESTATE,IKEJA | D5: PHARM. EZEAMA EMMANUEL | E5: GDP | F5: 45827 | G5: Medium-Risk (B) | H5: 24th june 2025 | I5: NO | J5: CAPA TO BE SUBMITTED | K5: =IF(I5="YES","CAPA VERIFICATION SHOULD BE SCHEDULED",IF(I5="NO","REMINDER LETTER SHOULD BE SENT","")) -> REMINDER LETTER SHOULD BE SENT | L5: 45809 | M5: https://nafdacng.sharepoint.com/sites/PMSLAGOS/Shared Documents/GSDP (GOOD STORAGE AND DISTRIBUTION PRACTICE)/GSDP COMPANY FILES\KUNIMED1 | N5: =IF(M5="","",HYPERLINK(M5,B5)) -> KUNIMED PHARMACHEM LTD
A6: 50 | B6: PACMAI INTL LTD | C6: 4, SHOWEMIMO STREET,BEHIND ION FILLING STATION AFTER ABULE,BEFORE OJO BARRACKS | D6: PHARM. GBENGA AJERO | E6: GDP | F6: 45828 | G6: High-Risk (C) | H6: 30th june 2025 | I6: NO | J6: CAPA TO BE SUBMITTED | K6: =IF(I6="YES","CAPA VERIFICATION SHOULD BE SCHEDULED",IF(I6="NO","REMINDER LETTER SHOULD BE SENT","")) -> REMINDER LETTER SHOULD BE SENT | L6: 46174 | M6: https://nafdacng.sharepoint.com/sites/PMSLAGOS/Shared Documents/GSDP (GOOD STORAGE AND DISTRIBUTION PRACTICE)/GSDP COMPANY FILES\Pacmal intl ltd | N6: =IF(M6="","",HYPERLINK(M6,B6)) -> PACMAI INTL LTD
A7: 51 | B7: SKIN PHARM LTD | C7: 230, IDEWU STREET,OLODI APAPA | D7: OPARAOCHA MARYEY | E7: GDP | F7: 45828 | G7: Medium-Risk (B) | H7: 30th june 2025 | I7: NO | J7: CAPA TO BE SUBMITTED | K7: =IF(I7="YES","CAPA VERIFICATION SHOULD BE SCHEDULED",IF(I7="NO","REMINDER LETTER SHOULD BE SENT","")) -> REMINDER LETTER SHOULD BE SENT | L7: 45809 | M7: https://nafdacng.sharepoint.com/sites/PMSLAGOS/Shared Documents/GSDP (GOOD STORAGE AND DISTRIBUTION PRACTICE)/GSDP COMPANY FILES\SKINPHARM | N7: =IF(M7="","",HYPERLINK(M7,B7)) -> SKIN PHARM LTD
A8: 52 | B8: AMAKIN PHARMACEUTICALS LTD | C8: 25, OTUNBA GBADAMOSI/ASADO STREET,OLODI APAPA | D8: PHARM MACDONALD A. | E8: GDP | F8: 45828 | G8: Medium-Risk (B) | H8: 30th june 2025 | I8: YES | J8: CAPA SUBMITTED | K8: =IF(I8="YES","CAPA VERIFICATION SHOULD BE SCHEDULED",IF(I8="NO","REMINDER LETTER SHOULD BE SENT","")) -> CAPA VERIFICATION SHOULD BE SCHEDULED | L8: 45809 | M8: https://nafdacng.sharepoint.com/sites/PMSLAGOS/Shared Documents/GSDP (GOOD STORAGE AND DISTRIBUTION PRACTICE)/GSDP COMPANY FILES\AMAKIN PHARM | N8: =IF(M8="","",HYPERLINK(M8,B8)) -> AMAKIN PHARMACEUTICALS LTD
A9: 53 | B9: MC FORIS PHARM LTD | C9: 7,APOSTOLIC CHURCH STREET,AJAO ESTATE | D9: PHARM ASHIMOLE PRECIOUS | E9: GDP | F9: 45828 | G9: Medium-Risk (B) | H9: 25th june 2025 | I9: NO | J9: CAPA TO BE SUBMITTED | K9: =IF(I9="YES","CAPA VERIFICATION SHOULD BE SCHEDULED",IF(I9="NO","REMINDER LETTER SHOULD BE SENT","")) -> REMINDER LETTER SHOULD BE SENT | L9: 45809 | M9: https://nafdacng.sharepoint.com/sites/PMSLAGOS/Shared Documents/GSDP (GOOD STORAGE AND DISTRIBUTION PRACTICE)/GSDP COMPANY FILES\MCFORIS Pharm ltd | N9: =IF(M9="","",HYPERLINK(M9,B9)) -> MC FORIS PHARM LTD
A10: 54 | B10: BERLIN PHARM & HEALTHCARE | C10: 42, COMFORT EBOH,KIRIKIRI INDUSTRIAL AREA,APAPA | D10: FELIX ANIKPEA 08060817888 | E10: GDP | F10: 45831 | G10: High-Risk (C) | H10: 24th june 2025 | I10: NO | J10: CAPA TO BE SUBMITTED | K10: =IF(I10="YES","CAPA VERIFICATION SHOULD BE SCHEDULED",IF(I10="NO","REMINDER LETTER SHOULD BE SENT","")) -> REMINDER LETTER SHOULD BE SENT | L10: 45992 | M10: https://nafdacng.sharepoint.com/sites/PMSLAGOS/Shared Documents/GSDP (GOOD STORAGE AND DISTRIBUTION PRACTICE)/GSDP COMPANY FILES\BERLIN PHARM | N10: =IF(M10="","",HYPERLINK(M10,B10)) -> BERLIN PHARM & HEALTHCARE
A11: 55 | B11: SUITE LIFE PHARMACEUTICALS | C11: SUITE LIFE CLOSE,HOPE ESTATE,AGO PALACE,OKOTA | D11: MRS JULIUS-IFEANYI UCHE | E11: GDP | F11: 45831 | G11: High-Risk (C) | H11: 24th june 2025 | I11: NO | J11: CAPA TO BE SUBMITTED | K11: =IF(I11="YES","CAPA VERIFICATION SHOULD BE SCHEDULED",IF(I11="NO","REMINDER LETTER SHOULD BE SENT","")) -> REMINDER LETTER SHOULD BE SENT | L11: 45992 | M11: https://nafdacng.sharepoint.com/sites/PMSLAGOS/Shared Documents/GSDP (GOOD STORAGE AND DISTRIBUTION PRACTICE)/GSDP COMPANY FILES\SUITELIFE | N11: =IF(M11="","",HYPERLINK(M11,B11)) -> SUITE LIFE PHARMACEUTICALS
A12: 56 | B12: GLOBAL ONE WORD HEALTHCARE | C12: 30B TOLAWI COKER VILLAGE ORILE IGANMU SURULERE | D12: PHARM. IFE ADETIFA | E12: CAPA | F12: 45831 | G12: Low-Risk (A) | H12: CLOSED | I12: YES | J12: CLOSED | K12: SATISFACTORY | L12: 46174 | M12: https://nafdacng.sharepoint.com/sites/PMSLAGOS/Shared Documents/GSDP (GOOD STORAGE AND DISTRIBUTION PRACTICE)/GSDP COMPANY FILES\Global One healthcare | N12: =IF(M12="","",HYPERLINK(M12,B12)) -> GLOBAL ONE WORD HEALTHCARE
A13: 57 | B13: FRESHBORN INDUSTRIES LTD | C13: PLOT 3164, BLOCK 68, MARIAN ROAD,AMUWO ODOFIN | D13: PHARM. EBURUO BONIFACE | E13: GDP | F13: 45831 | G13: Medium-Risk (B) | H13: 30th june 2025 | I13: NO | J13: CAPA TO BE SUBMITTED | K13: =IF(I13="YES","CAPA VERIFICATION SHOULD BE SCHEDULED",IF(I13="NO","REMINDER LETTER SHOULD BE SENT","")) -> REMINDER LETTER SHOULD BE SENT | L13: 45809 | M13: https://nafdacng.sharepoint.com/sites/PMSLAGOS/Shared Documents/GSDP (GOOD STORAGE AND DISTRIBUTION PRACTICE)/GSDP COMPANY FILES\FRESHBORN | N13: =IF(M13="","",HYPERLINK(M13,B13)) -> FRESHBORN INDUSTRIES LTD
A14: 58 | B14: EMINENT DRUGS LIMITED | C14: 6B OMONUBI ,OFF OMOLANI STREET,IJESHATEDO-SU | D14: PHARM. AKALUGO JUDE | E14: GDP | F14: 45831 | G14: High-Risk (C) | H14: 30th june 2025 | I14: NO | J14: CAPA TO BE SUBMITTED | K14: =IF(I14="YES","CAPA VERIFICATION SHOULD BE SCHEDULED",IF(I14="NO","REMINDER LETTER SHOULD BE SENT","")) -> REMINDER LETTER SHOULD BE SENT | L14: 45809 | M14: https://nafdacng.sharepoint.com/sites/PMSLAGOS/Shared Documents/GSDP (GOOD STORAGE AND DISTRIBUTION PRACTICE)/GSDP COMPANY FILES\EMINENT DRUGS | N14: =IF(M14="","",HYPERLINK(M14,B14)) -> EMINENT DRUGS LIMITED

Sheet July
A1: GDP INSPECTION CLASSIFICATION DATA BASE AS AT 2025
A2: S/N | B2: NAME OF MANUFACTURER | C2: LOCATION ADDRESS | D2: CONTACT | E2: TYPE OF LAST INSPECTION | F2: DATE OF LAST INSPECTION | G2: FINDINGS | H2: DATE CAPA ISSUED | I2: CAPA SUBMITTED | J2: CONCLUSION | K2: REMARKS | L2: EXPECTED DATE OF INSPECTION | M2: CC | N2: COMPANY FILE
A3: 59 | B3: MALVIN MEDICS | C3: 6, WILMERS STREET,ILUPEJU LAGOS | D3: PHARM. PETER OGINI | E3: GDP | F3: 45855 | G3: Medium-Risk (B) | H3: N/A | I3: NO | J3: CAPA TO BE SUBMITTED | K3: =IF(I3="YES","CAPA VERIFICATION SHOULD BE SCHEDULED",IF(I3="NO","REMINDER LETTER SHOULD BE SENT","")) -> REMINDER LETTER SHOULD BE SENT | L3: 45839 | M3: https://nafdacng.sharepoint.com/sites/PMSLAGOS/Shared Documents/GSDP (GOOD STORAGE AND DISTRIBUTION PRACTICE)/GSDP COMPANY FILES\MALVEN MEDICS LTD | N3: =IF(M3="","",HYPERLINK(M3,B3)) -> MALVIN MEDICS
A4: 60 | B4: PANGENE BIOTECH | C4: 64,BAYO OYEWALE STREET,AGO PALACE,OKOTA,LAGOS | D4: PHARM. NKESE UYOATA | E4: GDP | F4: 45855 | G4: High-Risk (C) | H4: 24TH JULY 2025 | I4: YES | J4: CAPA SUBMITTED | K4: =IF(I4="YES","CAPA VERIFICATION SHOULD BE SCHEDULED",IF(I4="NO","REMINDER LETTER SHOULD BE SENT","")) -> CAPA VERIFICATION SHOULD BE SCHEDULED | L4: 45962 | M4: https://nafdacng.sharepoint.com/sites/PMSLAGOS/Shared Documents/GSDP (GOOD STORAGE AND DISTRIBUTION PRACTICE)/GSDP COMPANY FILES\PANGENE BIOTECH | N4: =IF(M4="","",HYPERLINK(M4,B4)) -> PANGENE BIOTECH
A5: 61 | B5: CEEMIKE PHARMA LTD | C5: 41,SHEU HUSSEIN ARIKEKEWUYO ROAD,I/VIEW ESTATE PH2,AMUWO ODOFIN,LAGOS | D5: PHARM.EBINUM SUNDAY | E5: GDP | F5: 45854 | G5: High-Risk (C) | H5: 23RD JULY 2025 | I5: YES | J5: CAPA SUBMITTED | K5: =IF(I5="YES","CAPA VERIFICATION SHOULD BE SCHEDULED",IF(I5="NO","REMINDER LETTER SHOULD BE SENT","")) -> CAPA VERIFICATION SHOULD BE SCHEDULED | L5: 46023 | M5: https://nafdacng.sharepoint.com/sites/PMSLAGOS/Shared Documents/GSDP (GOOD STORAGE AND DISTRIBUTION PRACTICE)/GSDP COMPANY FILES\CEEMIKE | N5: =IF(M5="","",HYPERLINK(M5,B5)) -> CEEMIKE PHARMA LTD
A6: 62 | B6: TOC PHARMACEUTICALS | C6: 88,ILAMOYE STREET,IJESHATEDO,LAGOS | D6: PHARM. FASASI | E6: GDP | F6: 45855 | G6: High-Risk (C) | H6: 24TH JULY 2025 | I6: NO | J6: CAPA TO BE SUBMITTED | K6: =IF(I6="YES","CAPA VERIFICATION SHOULD BE SCHEDULED",IF(I6="NO","REMINDER LETTER SHOULD BE SENT","")) -> REMINDER LETTER SHOULD BE SENT | L6: 46023 | M6: https://nafdacng.sharepoint.com/sites/PMSLAGOS/Shared Documents/GSDP (GOOD STORAGE AND DISTRIBUTION PRACTICE)/GSDP COMPANY FILES\TOC PHARMACEUTICALS | N6: =IF(M6="","",HYPERLINK(M6,B6)) -> TOC PHARMACEUTICALS
A7: 63 | B7: GOLDEN GAZELLE | C7: 387,AGEGE MOTOR ROAD,MUSHIN, LAGOS | D7: PHARM. OKWUAKU MARTINS | E7: GDP | F7: 45856 | G7: Medium-Risk (B) | H7: 24TH JULY 2025 | I7: NO | J7: CAPA TO BE SUBMITTED | K7: =IF(I7="YES","CAPA VERIFICATION SHOULD BE SCHEDULED",IF(I7="NO","REMINDER LETTER SHOULD BE SENT","")) -> REMINDER LETTER SHOULD BE SENT | L7: 45839 | M7: https://nafdacng.sharepoint.com/sites/PMSLAGOS/Shared Documents/GSDP (GOOD STORAGE AND DISTRIBUTION PRACTICE)/GSDP COMPANY FILES/GOLDEN GAZELLE | N7: =IF(M7="","",HYPERLINK(M7,B7)) -> GOLDEN GAZELLE

Sheet August
A1: GDP INSPECTION CLASSIFICATION DATA BASE AS AT 2025
A2: S/N | B2: NAME OF MANUFACTURER | C2: LOCATION ADDRESS | D2: CONTACT | E2: TYPE OF LAST INSPECTION | F2: DATE OF LAST INSPECTION | G2: FINDINGS | H2: DATE CAPA ISSUED | I2: CAPA SUBMITTED | J2: CONCLUSION | K2: REMARKS | L2: EXPECTED DATE OF INSPECTION | M2: CC | N2: COMPANY FILE
A3: 64 | B3: SHEPHERD HEALTH & VETERINARY LTD. | C3: 24,MONTGOMERY ROAD,YABA,LAGOS | D3: PHARM ADETUNJI JOSEPH | E3: CAPA | F3: 45894 | G3: Low-Risk (A) | H3: 30TH AUGUST 2025 | I3: NO | J3: CAPA TO BE SUBMITTED | K3: =IF(I3="YES","CAPA VERIFICATION SHOULD BE SCHEDULED",IF(I3="NO","REMINDER LETTER SHOULD BE SENT","")) -> REMINDER LETTER SHOULD BE SENT | L3: 46600 | M3: https://nafdacng.sharepoint.com/sites/PMSLAGOS/Shared Documents/GSDP (GOOD STORAGE AND DISTRIBUTION PRACTICE)/GSDP COMPANY FILES/SHEPHERD HEALTH | N3: =IF(M3="","",HYPERLINK(M3,B3)) -> SHEPHERD HEALTH & VETERINARY LTD.
