Workbook

Sheet INSPECTED FACILITIES 2023
A1: GDP INSPECTION CLASSIFICATION DATA BASE AS AT 2023
A2: S/N | B2: NAME OF MANUFACTURER | C2: LOCATION ADDRESS | D2: CONTACT | E2: TYPE OF LAST INSPECTION | G2: FINDINGS | H2: CAPA ISSUED DATE | I2: CAPA SUBMITTED | J2: CONCLUSION | K2: REMARKS | L2: EXPECTED DATE OF INSPECTION | M2: OMPANY FILE | N2: Column1 | O2: COMPANY FILE
A3: 1 | B3: MECURE INDUSTRIES LTD | C3: Plot 6, Block H, Apapa Oshodi Expressway, Oshodi, Lagos | D3: 0700632873 | E3: GDP | F3: 44970 | G3: Low-Risk (A) | H3: 31st march 2023 | I3: YES | J3: CAPA Submited | K3: CAPA VERIFICATION SHOULD BE SCHEDULED | L3: 45689 | M3: https://nafdacng.sharepoint.com/sites/PMSLAGOS/Shared Documents/GDP (GOOD DISTRIBUTION PRATICE)/GSDP COMPANY FILES\MECURE IND. LTD | N3: https://nafdacng.sharepoint.com/sites/PMSLAGOS/Shared Documents/GSDP (GOOD STORAGE AND DISTRIBUTION PRACTICE)/GSDP COMPANY FILES\MECURE IND. LTD | O3: MECURE INDUSTRIES LTD
A4: 2 | B4: GENEITH PHARMACEUTICALS | C4: 12, Adewale Crescent, Oshodi, Lagos | D4: 08122912281 | E4: GDP | F4: 44970 | G4: Low-Risk (A) | H4: 31st march 2023 | I4: YES | J4: CAPA Submited | K4: =IF(I4="YES","CAPA VERIFICATION SHOULD BE SCHEDULED",IF(I4="NO","REMINDER LETTER SHOULD BE SENT","")) -> CAPA VERIFICATION SHOULD BE SCHEDULED | L4: 45689 | M4: https://nafdacng.sharepoint.com/sites/PMSLAGOS/Shared Documents/GDP (GOOD DISTRIBUTION PRATICE)/GSDP COMPANY FILES\GENEITH PHARM. LTD | N4: https://nafdacng.sharepoint.com/sites/PMSLAGOS/Shared Documents/GSDP (GOOD STORAGE AND DISTRIBUTION PRACTICE)/GSDP COMPANY FILES\GENEITH PHARM. LTD | O4: =IF(M4="","",HYPERLINK(M4,B4)) -> GENEITH PHARMACEUTICALS
A5: 3 | B5: ONWUADI & SONS LTD | C5: 11, Achakpo Street, Ajegunle, Lagos | D5: 08028642459 | E5: GDP | F5: 44970 | G5: Medium-Risk (B) | H5: 4th April 2023 | I5: YES | J5: CAPA Submited | K5: =IF(I5="YES","CAPA VERIFICATION SHOULD BE SCHEDULED",IF(I5="NO","REMINDER LETTER SHOULD BE SENT","")) -> CAPA VERIFICATION SHOULD BE SCHEDULED | L5: 45323 | M5: https://nafdacng.sharepoint.com/sites/PMSLAGOS/Shared Documents/GDP (GOOD DISTRIBUTION PRATICE)/GSDP COMPANY FILES\ONWUADI AND SONS LTD | N5: https://nafdacng.sharepoint.com/sites/PMSLAGOS/Shared Documents/GSDP (GOOD STORAGE AND DISTRIBUTION PRACTICE)/GSDP COMPANY FILES\ONWUADI AND SONS LTD | O5: =IF(M5="","",HYPERLINK(M5,B5)) -> ONWUADI & SONS LTD
A6: 4 | B6: MODDY DRUG CO. LTD | C6: 93, Baale Street, Ajegunle, Lagos | D6: 0802306320 | E6: GDP | F6: 44970 | G6: Medium-Risk (B) | H6: 4th April 2023 | I6: NO | J6: CAPA to be Submited | K6: =IF(I6="YES","CAPA VERIFICATION SHOULD BE SCHEDULED",IF(I6="NO","REMINDER LETTER SHOULD BE SENT","")) -> REMINDER LETTER SHOULD BE SENT | L6: 45323 | M6: https://nafdacng.sharepoint.com/sites/PMSLAGOS/Shared Documents/GDP (GOOD DISTRIBUTION PRATICE)/GSDP COMPANY FILES\MOODY DRUGS CO. LTD | N6: https://nafdacng.sharepoint.com/sites/PMSLAGOS/Shared Documents/GSDP (GOOD STORAGE AND DISTRIBUTION PRACTICE)/GSDP COMPANY FILES\MOODY DRUGS CO. LTD | O6: =IF(M6="","",HYPERLINK(M6,B6)) -> MODDY DRUG CO. LTD
A7: 5 | B7: JUMENCO PHARMACEUTICAL | C7: 52, Ladega Street, Ikorodu,Lagos | D7: 08065232177 | E7: GDP | F7: 14/02/2023 | G7: Medium-Risk (B) | H7: 31st march 2023 | I7: NO | J7: CAPA to be Submited | K7: =IF(I7="YES","CAPA VERIFICATION SHOULD BE SCHEDULED",IF(I7="NO","REMINDER LETTER SHOULD BE SENT","")) -> REMINDER LETTER SHOULD BE SENT | L7: 45323 | M7: https://nafdacng.sharepoint.com/sites/PMSLAGOS/Shared Documents/GDP (GOOD DISTRIBUTION PRATICE)/GSDP COMPANY FILES\JUMENCO PHARMACEUTICALS LTD | N7: https://nafdacng.sharepoint.com/sites/PMSLAGOS/Shared Documents/GSDP (GOOD STORAGE AND DISTRIBUTION PRACTICE)/GSDP COMPANY FILES\JUMENCO PHARMACEUTICALS LTD | O7: =IF(M7="","",HYPERLINK(M7,B7)) -> JUMENCO PHARMACEUTICAL
A8: 6 | B8: ANOKEM PHARMACEUTICALS | C8: 58,Eluku Street,Ikorodu, Lagos | D8: 07017691325 | E8: GDP | F8: 14/02/2023 | G8: Medium-Risk (B) | H8: 4th April 2023 | I8: NO | J8: CAPA to be Submited | K8: =IF(I8="YES","CAPA VERIFICATION SHOULD BE SCHEDULED",IF(I8="NO","REMINDER LETTER SHOULD BE SENT","")) -> REMINDER LETTER SHOULD BE SENT | L8: 45323 | M8: https://nafdacng.sharepoint.com/sites/PMSLAGOS/Shared Documents/GDP (GOOD DISTRIBUTION PRATICE)/GSDP COMPANY FILES\ANOKEM PHARM. LTD | N8: https://nafdacng.sharepoint.com/sites/PMSLAGOS/Shared Documents/GSDP (GOOD STORAGE AND DISTRIBUTION PRACTICE)/GSDP COMPANY FILES\ANOKEM PHARM. LTD | O8: =IF(M8="","",HYPERLINK(M8,B8)) -> ANOKEM PHARMACEUTICALS
A9: 7 | B9: RALPHONES PHARMACEUTICAL | C9: 1 Ralphone Lane,Irawo ajegunle,ikorodu,Lagos | D9: 08037588238 | E9: GDP | F9: 14/02/2023 | G9: Low-Risk (A) | H9: 31st march 2023 | I9: YES | J9: CAPA Submited | K9: =IF(I9="YES","CAPA VERIFICATION SHOULD BE SCHEDULED",IF(I9="NO","REMINDER LETTER SHOULD BE SENT","")) -> CAPA VERIFICATION SHOULD BE SCHEDULED | L9: 45689 | M9: https://nafdacng.sharepoint.com/sites/PMSLAGOS/Shared Documents/GDP (GOOD DISTRIBUTION PRATICE)/GSDP COMPANY FILES\RALPHONES PHARMACEUTICAL LTD | N9: https://nafdacng.sharepoint.com/sites/PMSLAGOS/Shared Documents/GSDP (GOOD STORAGE AND DISTRIBUTION PRACTICE)/GSDP COMPANY FILES\RALPHONES PHARMACEUTICAL LTD | O9: =IF(M9="","",HYPERLINK(M9,B9)) -> RALPHONES PHARMACEUTICAL
A10: 8 | B10: LUGZ PHARMACEUTICAL | C10: 58,Lagos Rd,Opp UBA,Ikorodu, Lagos | D10: 08093955361 08148337773 | E10: GDP | F10: 14/02/2023 | G10: Medium-Risk (B) | H10: 4th April 2023 | I10: NO | J10: CAPA to be Submited | K10: =IF(I10="YES","CAPA VERIFICATION SHOULD BE SCHEDULED",IF(I10="NO","REMINDER LETTER SHOULD BE SENT","")) -> REMINDER LETTER SHOULD BE SENT | L10: 45323 | M10: https://nafdacng.sharepoint.com/sites/PMSLAGOS/Shared Documents/GDP (GOOD DISTRIBUTION PRATICE)/GSDP COMPANY FILES\LUGZ PHARMACY | N10: https://nafdacng.sharepoint.com/sites/PMSLAGOS/Shared Documents/GSDP (GOOD STORAGE AND DISTRIBUTION PRACTICE)/GSDP COMPANY FILES\LUGZ PHARMACY | O10: =IF(M10="","",HYPERLINK(M10,B10)) -> LUGZ PHARMACEUTICAL
A11: 9 | B11: LADAMOS PHARMACY | C11: 2, Adenaike Alagbe Street , Ikorodu, Lagos | D11: 08033885195 | E11: GDP | F11: 14/02/2023 | G11: High-Risk (C) | H11: They were not issued cd | I11: N/A | J11: CAPA to be Submited | K11: =IF(I11="YES","CAPA VERIFICATION SHOULD BE SCHEDULED",IF(I11="NO","REMINDER LETTER SHOULD BE SENT","")) | L11: 44774 | O11: =IF(M11="","",HYPERLINK(M11,B11))
A12: 10 | B12: GOODCARE PHARMACEUTICAL | C12: 11, sawo Road,Agric,Ikorodu,Lagos | D12: 08064266572 | E12: GDP | F12: 15/02/2023 | G12: Medium-Risk (B) | H12: 4th April 2023 | I12: YES | J12: CAPA Submited | K12: =IF(I12="YES","CAPA VERIFICATION SHOULD BE SCHEDULED",IF(I12="NO","REMINDER LETTER SHOULD BE SENT","")) -> CAPA VERIFICATION SHOULD BE SCHEDULED | L12: 45323 | M12: https://nafdacng.sharepoint.com/sites/PMSLAGOS/Shared Documents/GDP (GOOD DISTRIBUTION PRATICE)/GSDP COMPANY FILES\GOODCARE | N12: https://nafdacng.sharepoint.com/sites/PMSLAGOS/Shared Documents/GSDP (GOOD STORAGE AND DISTRIBUTION PRACTICE)/GSDP COMPANY FILES\GOODCARE | O12: =IF(M12="","",HYPERLINK(M12,B12)) -> GOODCARE PHARMACEUTICAL
A13: 11 | B13: PATVICS PHARMACEUTICAL | C13: 603, Ikorodu Road, Mile 12, Lagos | D13: 08033927269 | E13: GDP | F13: 15/02/2023 | G13: High-Risk (C) | H13: 4th April 2023 | I13: NO | J13: CAPA to be Submited | K13: =IF(I13="YES","CAPA VERIFICATION SHOULD BE SCHEDULED",IF(I13="NO","REMINDER LETTER SHOULD BE SENT","")) -> REMINDER LETTER SHOULD BE SENT | L13: 44774 | M13: https://nafdacng.sharepoint.com/sites/PMSLAGOS/Shared Documents/GDP (GOOD DISTRIBUTION PRATICE)/GSDP COMPANY FILES\PATVICS LTD | N13: https://nafdacng.sharepoint.com/sites/PMSLAGOS/Shared Documents/GSDP (GOOD STORAGE AND DISTRIBUTION PRACTICE)/GSDP COMPANY FILES\PATVICS LTD | O13: =IF(M13="","",HYPERLINK(M13,B13)) -> PATVICS PHARMACEUTICAL
A14: 12 | B14: KOJOS PHARMACY | C14: 5, Oju Emuren Street, Odogunyan, Ikorodu | D14: 08073823496 | E14: GDP | F14: 15/02/2023 | G14: Low-Risk (A) | H14: 31st march 2023 | I14: NO | J14: CAPA to be Submited | K14: =IF(I14="YES","CAPA VERIFICATION SHOULD BE SCHEDULED",IF(I14="NO","REMINDER LETTER SHOULD BE SENT","")) -> REMINDER LETTER SHOULD BE SENT | L14: 45689 | M14: https://nafdacng.sharepoint.com/sites/PMSLAGOS/Shared Documents/GDP (GOOD DISTRIBUTION PRATICE)/GSDP COMPANY FILES\KOJOS PHARMACY LTD | N14: https://nafdacng.sharepoint.com/sites/PMSLAGOS/Shared Documents/GSDP (GOOD STORAGE AND DISTRIBUTION PRACTICE)/GSDP COMPANY FILES\KOJOS PHARMACY LTD | O14: =IF(M14="","",HYPERLINK(M14,B14)) -> KOJOS PHARMACY
A15: 13 | B15: VIXA PHARMACEUTICALS | C15: 13B, Sunday Jigida street, off celestical way,ogudu, lagos | D15: 07082004139 | E15: GDP | F15: 15/02/2023 | G15: Medium-Risk (B) | H15: 4th April 2023 | I15: YES | J15: CAPA Submited | K15: =IF(I15="YES","CAPA VERIFICATION SHOULD BE SCHEDULED",IF(I15="NO","REMINDER LETTER SHOULD BE SENT","")) -> CAPA VERIFICATION SHOULD BE SCHEDULED | L15: 45323 | O15: =IF(M15="","",HYPERLINK(M15,B15))
A16: 14 | B16: SWIPHA NIGERIA | C16: 5, Dopemu road, depemu Lagos | D16: 08146679976 | E16: GDP | F16: 16/02/2023 | G16: Low-Risk (A) | H16: 4th April 2023 | I16: YES | J16: CAPA Submited | K16: =IF(I16="YES","CAPA VERIFICATION SHOULD BE SCHEDULED",IF(I16="NO","REMINDER LETTER SHOULD BE SENT","")) -> CAPA VERIFICATION SHOULD BE SCHEDULED | L16: 45689 | M16: https://nafdacng.sharepoint.com/sites/PMSLAGOS/Shared Documents/GDP (GOOD DISTRIBUTION PRATICE)/GSDP COMPANY FILES\SWIPHA NIG. LTD | N16: https://nafdacng.sharepoint.com/sites/PMSLAGOS/Shared Documents/GSDP (GOOD STORAGE AND DISTRIBUTION PRACTICE)/GSDP COMPANY FILES\SWIPHA NIG. LTD | O16: =IF(M16="","",HYPERLINK(M16,B16)) -> SWIPHA NIGERIA
A17: 15 | B17: BJ CHOICE PHARM | C17: 1, Okenube Last Bus Stop, Ikotun Lagos | D17: 08033204754 | E17: GDP | F17: 16/02/2023 | G17: Medium-Risk (B) | H17: 45631 | I17: NO | J17: CAPA to be Submited | K17: =IF(I17="YES","CAPA VERIFICATION SHOULD BE SCHEDULED",IF(I17="NO","REMINDER LETTER SHOULD BE SENT","")) -> REMINDER LETTER SHOULD BE SENT | L17: 45323 | M17: https://nafdacng.sharepoint.com/sites/PMSLAGOS/Shared Documents/GDP (GOOD DISTRIBUTION PRATICE)/GSDP COMPANY FILES\BJ CHOICE PHARM. LTD | N17: https://nafdacng.sharepoint.com/sites/PMSLAGOS/Shared Documents/GSDP (GOOD STORAGE AND DISTRIBUTION PRACTICE)/GSDP COMPANY FILES\BJ CHOICE PHARM. LTD | O17: =IF(M17="","",HYPERLINK(M17,B17)) -> BJ CHOICE PHARM
A18: 16 | B18: PAKEN VENTURES | C18: 294, Idimu Road, Ikotun-Egbeda | D18: 08103961314 | E18: GDP | F18: 16/02/2023 | G18: High-Risk (C) | H18: 4th April 2023 | I18: NO | J18: CAPA to be Submited | K18: =IF(I18="YES","CAPA VERIFICATION SHOULD BE SCHEDULED",IF(I18="NO","REMINDER LETTER SHOULD BE SENT","")) -> REMINDER LETTER SHOULD BE SENT | L18: 44774 | M18: https://nafdacng.sharepoint.com/sites/PMSLAGOS/Shared Documents/GDP (GOOD DISTRIBUTION PRATICE)/GSDP COMPANY FILES\PAKEN VENTURES LTD | N18: https://nafdacng.sharepoint.com/sites/PMSLAGOS/Shared Documents/GSDP (GOOD STORAGE AND DISTRIBUTION PRACTICE)/GSDP COMPANY FILES\PAKEN VENTURES LTD | O18: =IF(M18="","",HYPERLINK(M18,B18)) -> PAKEN VENTURES
A19: 17 | B19: HENBOSCO PHARMACY | C19: 195, Abeokuta Exp. Way, Iyana Ipaja | D19: 08099916512 | E19: GDP | F19: 17/02/2023 | G19: High-Risk (C) | H19: They were not issued cd | I19: NO | J19: CAPA to be Submited | K19: =IF(I19="YES","CAPA VERIFICATION SHOULD BE SCHEDULED",IF(I19="NO","REMINDER LETTER SHOULD BE SENT","")) -> REMINDER LETTER SHOULD BE SENT | L19: 44774 | M19: https://nafdacng.sharepoint.com/sites/PMSLAGOS/Shared Documents/GDP (GOOD DISTRIBUTION PRATICE)/GSDP COMPANY FILES\HENBOSCO PHARMACY LTD | N19: https://nafdacng.sharepoint.com/sites/PMSLAGOS/Shared Documents/GSDP (GOOD STORAGE AND DISTRIBUTION PRACTICE)/GSDP COMPANY FILES\HENBOSCO PHARMACY LTD | O19: =IF(M19="","",HYPERLINK(M19,B19)) -> HENBOSCO PHARMACY
A20: 18 | B20: LYNDUS PHARMACY LTD | C20: 9 Akesan Rd, Egan, by Nepa, Igando, Alimosho, Lagos | D20: 08137719998 08037138148 | E20: GDP | F20: 21/02/2023 | G20: High-Risk (C) | H20: 4th April 2023 | I20: NO | J20: CAPA to be Submited | K20: =IF(I20="YES","CAPA VERIFICATION SHOULD BE SCHEDULED",IF(I20="NO","REMINDER LETTER SHOULD BE SENT","")) -> REMINDER LETTER SHOULD BE SENT | L20: 44774 | M20: https://nafdacng.sharepoint.com/sites/PMSLAGOS/Shared Documents/GDP (GOOD DISTRIBUTION PRATICE)/GSDP COMPANY FILES\LYNDUS PHARMACY LTD | N20: https://nafdacng.sharepoint.com/sites/PMSLAGOS/Shared Documents/GSDP (GOOD STORAGE AND DISTRIBUTION PRACTICE)/GSDP COMPANY FILES\LYNDUS PHARMACY LTD | O20: =IF(M20="","",HYPERLINK(M20,B20)) -> LYNDUS PHARMACY LTD
A21: 19 | B21: ROM CHIDECK PHARM. LTD | C21: 4, Disusts, Isheri, Oshun, Alem, Lagos . | D21: 07018687107 | E21: GDP | F21: 21/02/2023 | G21: High-Risk (C) | H21: 4th April 2023 | I21: NO | J21: CAPA to be Submited | K21: =IF(I21="YES","CAPA VERIFICATION SHOULD BE SCHEDULED",IF(I21="NO","REMINDER LETTER SHOULD BE SENT","")) -> REMINDER LETTER SHOULD BE SENT | L21: 44774 | M21: https://nafdacng.sharepoint.com/sites/PMSLAGOS/Shared%20Documents/GDP%20(GOOD%20DISTRIBUTION%20PRATICE)/GSDP%20COMPANY%20FILES\ROM-CHIDEK | N21: https://nafdacng.sharepoint.com/sites/PMSLAGOS/Shared%20Documents/GDP%20(GOOD%20DISTRIBUTION%20PRATICE)/GSDP%20COMPANY%20FILES\ROM-CHIDEK | O21: =IF(M21="","",HYPERLINK(M21,B21)) -> ROM CHIDECK PHARM. LTD
A22: 20 | B22: JUVYWAY PHARMCY CO.LTD | C22: 57,Alimosho Road,Iyana- Ipaja, Lagos | D22: 08133295836 | E22: GDP | F22: 22/02/2023 | G22: High-Risk (C) | H22: 4th April 2023 | I22: YES | J22: CAPA Submited | K22: =IF(I22="YES","CAPA VERIFICATION SHOULD BE SCHEDULED",IF(I22="NO","REMINDER LETTER SHOULD BE SENT","")) -> CAPA VERIFICATION SHOULD BE SCHEDULED | L22: 45536 | M22: https://nafdacng.sharepoint.com/sites/PMSLAGOS/Shared Documents/GDP (GOOD DISTRIBUTION PRATICE)/GSDP COMPANY FILES\JUVYWAY PHARMACY | N22: https://nafdacng.sharepoint.com/sites/PMSLAGOS/Shared Documents/GSDP (GOOD STORAGE AND DISTRIBUTION PRACTICE)/GSDP COMPANY FILES\JUVYWAY PHARMACY | O22: =IF(M22="","",HYPERLINK(M22,B22)) -> JUVYWAY PHARMCY CO.LTD
A23: 21 | B23: EVERSHINE PHARMACEUTICAL NIG LTD | C23: 41, Amoke Alasala Street, Iyana- Ipaja, Lagos | D23: 08061290502 | E23: GDP | F23: 22/02/2023 | G23: Medium-Risk (B) | H23: 4th April 2023 | I23: YES | J23: CAPA Submited | K23: =IF(I23="YES","CAPA VERIFICATION SHOULD BE SCHEDULED",IF(I23="NO","REMINDER LETTER SHOULD BE SENT","")) -> CAPA VERIFICATION SHOULD BE SCHEDULED | L23: 45323 | M23: https://nafdacng.sharepoint.com/sites/PMSLAGOS/Shared Documents/GDP (GOOD DISTRIBUTION PRATICE)/GSDP COMPANY FILES\EVERSHINE PHARMA NIG LTD | N23: https://nafdacng.sharepoint.com/sites/PMSLAGOS/Shared Documents/GSDP (GOOD STORAGE AND DISTRIBUTION PRACTICE)/GSDP COMPANY FILES\EVERSHINE PHARMA NIG LTD | O23: =IF(M23="","",HYPERLINK(M23,B23)) -> EVERSHINE PHARMACEUTICAL NIG LTD
A24: 22 | B24: FRANKEY NIG.LTD | C24: 9, Victor Fagbami street,Iyana- Ipaja, Lagos . | D24: 08033012635 | E24: GDP | F24: 22/02/2023 | G24: High-Risk (C) | H24: 4th April 2023 | I24: YES | J24: CAPA Submited | K24: =IF(I24="YES","CAPA VERIFICATION SHOULD BE SCHEDULED",IF(I24="NO","REMINDER LETTER SHOULD BE SENT","")) -> CAPA VERIFICATION SHOULD BE SCHEDULED | L24: 45413 | M24: https://nafdacng.sharepoint.com/sites/PMSLAGOS/Shared Documents/GDP (GOOD DISTRIBUTION PRATICE)/GSDP COMPANY FILES/FRANKCY NIG LTD | N24: https://nafdacng.sharepoint.com/sites/PMSLAGOS/Shared Documents/GSDP (GOOD STORAGE AND DISTRIBUTION PRACTICE)/GSDP COMPANY FILES/FRANKCY NIG LTD | O24: =IF(M24="","",HYPERLINK(M24,B24)) -> FRANKEY NIG.LTD
A25: 23 | B25: GOD IS GREAT PHARMACY | C25: 1,Kola Ogunwale, Off Iyana Ipaja Lagos | D25: 08058520035 | E25: GDP | F25: 23/02/2023 | G25: High-Risk (C) | H25: 4th April 2023 | I25: NO | J25: CAPA to be Submited | K25: =IF(I25="YES","CAPA VERIFICATION SHOULD BE SCHEDULED",IF(I25="NO","REMINDER LETTER SHOULD BE SENT","")) -> REMINDER LETTER SHOULD BE SENT | L25: 44774 | M25: https://nafdacng.sharepoint.com/sites/PMSLAGOS/Shared Documents/GDP (GOOD DISTRIBUTION PRATICE)/GSDP COMPANY FILES\GOD IS GREAT PHARMACY | N25: https://nafdacng.sharepoint.com/sites/PMSLAGOS/Shared Documents/GSDP (GOOD STORAGE AND DISTRIBUTION PRACTICE)/GSDP COMPANY FILES\GOD IS GREAT PHARMACY | O25: =IF(M25="","",HYPERLINK(M25,B25)) -> GOD IS GREAT PHARMACY
A26: 24 | B26: SOMEC UNITED PHARMACY | C26: 3,Adebayo Street Iyana Ipaja Lagos | D26: 07062791634 | E26: GDP | F26: 23/02/2023 | G26: Medium-Risk (B) | H26: 4th April 2023 | I26: NO | J26: CAPA to be Submited | K26: =IF(I26="YES","CAPA VERIFICATION SHOULD BE SCHEDULED",IF(I26="NO","REMINDER LETTER SHOULD BE SENT","")) -> REMINDER LETTER SHOULD BE SENT | L26: 45323 | M26: https://nafdacng.sharepoint.com/sites/PMSLAGOS/Shared Documents/GDP (GOOD DISTRIBUTION PRATICE)/GSDP COMPANY FILES/SKY PHARM | N26: https://nafdacng.sharepoint.com/sites/PMSLAGOS/Shared Documents/GSDP (GOOD STORAGE AND DISTRIBUTION PRACTICE)/GSDP COMPANY FILES/SKY PHARM | O26: =IF(M26="","",HYPERLINK(M26,B26)) -> SOMEC UNITED PHARMACY
A27: 25 | B27: UNITED ABC PHARMACEUTICAL | C27: 45/47,Ipaja Road, Iyana Ipaja, Lagos | D27: 08099887692 | E27: GDP | F27: 23/02/2023 | G27: Medium-Risk (B) | H27: 4th April 2023 | I27: NO | J27: CAPA to be Submited | K27: =IF(I27="YES","CAPA VERIFICATION SHOULD BE SCHEDULED",IF(I27="NO","REMINDER LETTER SHOULD BE SENT","")) -> REMINDER LETTER SHOULD BE SENT | L27: 45323 | M27: https://nafdacng.sharepoint.com/sites/PMSLAGOS/Shared Documents/GDP (GOOD DISTRIBUTION PRATICE)/GSDP COMPANY FILES\UNITED ABC PHARM | N27: https://nafdacng.sharepoint.com/sites/PMSLAGOS/Shared Documents/GSDP (GOOD STORAGE AND DISTRIBUTION PRACTICE)/GSDP COMPANY FILES\UNITED ABC PHARM | O27: =IF(M27="","",HYPERLINK(M27,B27)) -> UNITED ABC PHARMACEUTICAL
A28: 26 | B28: SA PHARMACY | C28: 1, Imope Compound, Ikotun, Lagos State | D28: 08033454283 | E28: GDP | F28: 24/02/2023 | G28: Medium-Risk (B) | H28: 4th April 2023 | I28: NO | J28: CAPA to be Submited | K28: =IF(I28="YES","CAPA VERIFICATION SHOULD BE SCHEDULED",IF(I28="NO","REMINDER LETTER SHOULD BE SENT","")) -> REMINDER LETTER SHOULD BE SENT | L28: 45323 | M28: https://nafdacng.sharepoint.com/sites/PMSLAGOS/Shared Documents/GDP (GOOD DISTRIBUTION PRATICE)/GSDP COMPANY FILES\SA PHARMACY | N28: https://nafdacng.sharepoint.com/sites/PMSLAGOS/Shared Documents/GSDP (GOOD STORAGE AND DISTRIBUTION PRACTICE)/GSDP COMPANY FILES\SA PHARMACY | O28: =IF(M28="","",HYPERLINK(M28,B28)) -> SA PHARMACY
A29: 27 | B29: RIGHTMATE PHARMACY | C29: 3,Fatimo Street, Ikotun Lagos State | D29: 08063358238 | E29: GDP | F29: 24/02/2023 | G29: Medium-Risk (B) | H29: 4th April 2023 | I29: NO | J29: CAPA to be Submited | K29: =IF(I29="YES","CAPA VERIFICATION SHOULD BE SCHEDULED",IF(I29="NO","REMINDER LETTER SHOULD BE SENT","")) -> REMINDER LETTER SHOULD BE SENT | L29: 45323 | M29: https://nafdacng.sharepoint.com/sites/PMSLAGOS/Shared Documents/GDP (GOOD DISTRIBUTION PRATICE)/GSDP COMPANY FILES\RIGHTMARES PHARM LTD | N29: https://nafdacng.sharepoint.com/sites/PMSLAGOS/Shared Documents/GSDP (GOOD STORAGE AND DISTRIBUTION PRACTICE)/GSDP COMPANY FILES\RIGHTMARES PHARM LTD | O29: =IF(M29="","",HYPERLINK(M29,B29)) -> RIGHTMATE PHARMACY
... A34: 32 | B34: UNITED AFRICA LABORATORY LIMITED | C34: 9, Tebun Bisiriyu street, shahsha, Lagos. | D34: 07063877874 | E34: GDP | F34: 30/03/2023 | G34: Medium-Risk (B) | H34: 11th august 2023 | I34: NO | J34: CAPA to be Submited | K34: =IF(I34="YES","CAPA VERIFICATION SHOULD BE SCHEDULED",IF(I34="NO","REMINDER LETTER SHOULD BE SENT","")) -> REMINDER LETTER SHOULD BE SENT | L34: 45352 | M34: https://nafdacng.sharepoint.com/sites/PMSLAGOS/Shared Documents/GDP (GOOD DISTRIBUTION PRATICE)/GSDP COMPANY FILES\UNITED AFRICA LABORATORY LTD | N34: https://nafdacng.sharepoint.com/sites/PMSLAGOS/Shared Documents/GSDP (GOOD STORAGE AND DISTRIBUTION PRACTICE)/GSDP COMPANY FILES\UNITED AFRICA LABORATORY LTD | O34: =IF(M34="","",HYPERLINK(M34,B34)) -> UNITED AFRICA LABORATORY LIMITED
A35: 33 | B35: SANTUS PHARMACY & STORES LTD. | C35: 11, Sasha road, Akowonjo, Lagos. | D35: 08051263650 | E35: GDP | F35: 30/03/2023 | G35: Medium-Risk (B) | H35: 29th january 2024 | I35: YES | J35: CAPA Submited | K35: =IF(I35="YES","CAPA VERIFICATION SHOULD BE SCHEDULED",IF(I35="NO","REMINDER LETTER SHOULD BE SENT","")) -> CAPA VERIFICATION SHOULD BE SCHEDULED | L35: DONE | M35: https://nafdacng.sharepoint.com/sites/PMSLAGOS/Shared Documents/GDP (GOOD DISTRIBUTION PRATICE)/GSDP COMPANY FILES\SANTUS PHARMACY LTD | N35: https://nafdacng.sharepoint.com/sites/PMSLAGOS/Shared Documents/GSDP (GOOD STORAGE AND DISTRIBUTION PRACTICE)/GSDP COMPANY FILES\SANTUS PHARMACY LTD | O35: =IF(M35="","",HYPERLINK(M35,B35)) -> SANTUS PHARMACY & STORES LTD.
A36: 34 | B36: THINK ETERNITY DRUGS LTD. | C36: 1, Oguntande street, Shasha, Lagos. | D36: 08120739721 | E36: GDP | F36: 30/03/2023 | G36: High-Risk (C) | H36: They were not issued cd | I36: NO | J36: CAPA to be Submited | K36: =IF(I36="YES","CAPA VERIFICATION SHOULD BE SCHEDULED",IF(I36="NO","REMINDER LETTER SHOULD BE SENT","")) -> REMINDER LETTER SHOULD BE SENT | L36: 45170 | M36: https://nafdacng.sharepoint.com/sites/PMSLAGOS/Shared Documents/GDP (GOOD DISTRIBUTION PRATICE)/GSDP COMPANY FILES\THINK ENTERNITY DRUGS LTD | N36: https://nafdacng.sharepoint.com/sites/PMSLAGOS/Shared Documents/GSDP (GOOD STORAGE AND DISTRIBUTION PRACTICE)/GSDP COMPANY FILES\THINK ENTERNITY DRUGS LTD | O36: =IF(M36="","",HYPERLINK(M36,B36)) -> THINK ETERNITY DRUGS LTD.
A37: 35 | B37: MIVERO PHARM. LTD. | C37: 244, Agege Motor road, Mushin, Lagos. | D37: 08161396721 | E37: GDP | F37: 29/03/2023 | G37: High-Risk (C) | H37: 30th january 2024 | I37: NO | J37: CAPA to be Submited | K37: =IF(I37="YES","CAPA VERIFICATION SHOULD BE SCHEDULED",IF(I37="NO","REMINDER LETTER SHOULD BE SENT","")) -> REMINDER LETTER SHOULD BE SENT | L37: 45170 | M37: https://nafdacng.sharepoint.com/sites/PMSLAGOS/Shared Documents/GDP (GOOD DISTRIBUTION PRATICE)/GSDP COMPANY FILES\MIVERO PHARM | N37: https://nafdacng.sharepoint.com/sites/PMSLAGOS/Shared Documents/GSDP (GOOD STORAGE AND DISTRIBUTION PRACTICE)/GSDP COMPANY FILES\MIVERO PHARM | O37: =IF(M37="","",HYPERLINK(M37,B37)) -> MIVERO PHARM. LTD.
A38: 36 | B38: R.L. UPRIGHT WAY NIG. LTD. | C38: 15, Market street, Somolu, Lagos. | D38: 08162250028 | E38: GDP | F38: 45050 | G38: High-Risk (C) | H38: They were not issued cd | I38: NO | J38: CAPA to be Submited | K38: =IF(I38="YES","CAPA VERIFICATION SHOULD BE SCHEDULED",IF(I38="NO","REMINDER LETTER SHOULD BE SENT","")) -> REMINDER LETTER SHOULD BE SENT | L38: 45200 | M38: https://nafdacng.sharepoint.com/sites/PMSLAGOS/Shared Documents/GDP (GOOD DISTRIBUTION PRATICE)/GSDP COMPANY FILES\R.L UPRIGHTWAY NIG LTD | N38: https://nafdacng.sharepoint.com/sites/PMSLAGOS/Shared Documents/GSDP (GOOD STORAGE AND DISTRIBUTION PRACTICE)/GSDP COMPANY FILES\R.L UPRIGHTWAY NIG LTD | O38: =IF(M38="","",HYPERLINK(M38,B38)) -> R.L. UPRIGHT WAY NIG. LTD.
A39: 37 | B39: TEACO PHARM. CO. NIG. LTD. | C39: 50, Akowonjo Road ,Egbeda, Lagos. | D39: 08033025740 | E39: GDP | F39: 45020 | G39: Medium-Risk (B) | H39: 8th june 2023 | I39: YES | J39: CAPA Submited | K39: =IF(I39="YES","CAPA VERIFICATION SHOULD BE SCHEDULED",IF(I39="NO","REMINDER LETTER SHOULD BE SENT","")) -> CAPA VERIFICATION SHOULD BE SCHEDULED | L39: 45078 | M39: https://nafdacng.sharepoint.com/sites/PMSLAGOS/Shared Documents/GDP (GOOD DISTRIBUTION PRATICE)/GSDP COMPANY FILES\TEACO PHARMACY | N39: https://nafdacng.sharepoint.com/sites/PMSLAGOS/Shared Documents/GSDP (GOOD STORAGE AND DISTRIBUTION PRACTICE)/GSDP COMPANY FILES\TEACO PHARMACY | O39: =IF(M39="","",HYPERLINK(M39,B39)) -> TEACO PHARM. CO. NIG. LTD.
A40: 38 | B40: FUNKET NIG. LTD. | C40: 83, Ikotun-Idumu road, Lagos. | D40: 08033156922 | E40: GDP | F40: 45020 | G40: Medium-Risk (B) | H40: 8th june 2023 | I40: NO | J40: CAPA to be Submited | K40: =IF(I40="YES","CAPA VERIFICATION SHOULD BE SCHEDULED",IF(I40="NO","REMINDER LETTER SHOULD BE SENT","")) -> REMINDER LETTER SHOULD BE SENT | L40: 45383 | M40: https://nafdacng.sharepoint.com/sites/PMSLAGOS/Shared Documents/GDP (GOOD DISTRIBUTION PRATICE)/GSDP COMPANY FILES\FUNKET NIG. LTD | N40: https://nafdacng.sharepoint.com/sites/PMSLAGOS/Shared Documents/GSDP (GOOD STORAGE AND DISTRIBUTION PRACTICE)/GSDP COMPANY FILES\FUNKET NIG. LTD | O40: =IF(M40="","",HYPERLINK(M40,B40)) -> FUNKET NIG. LTD.
A41: 39 | B41: KATCEE-MACKENZIE &ASSOCIATES | C41: 7, Market Street, Shomolu, Lagos | D41: 08023649732 | E41: GDP | F41: 45050 | G41: Medium-Risk (B) | H41: They were not issued cd | I41: NO | J41: CAPA to be Submited | K41: =IF(I41="YES","CAPA VERIFICATION SHOULD BE SCHEDULED",IF(I41="NO","REMINDER LETTER SHOULD BE SENT","")) -> REMINDER LETTER SHOULD BE SENT | L41: 45383 | M41: https://nafdacng.sharepoint.com/sites/PMSLAGOS/Shared Documents/GDP (GOOD DISTRIBUTION PRATICE)/GSDP COMPANY FILES\KATCEE-MACKENZIE LTD | N41: https://nafdacng.sharepoint.com/sites/PMSLAGOS/Shared Documents/GSDP (GOOD STORAGE AND DISTRIBUTION PRACTICE)/GSDP COMPANY FILES\KATCEE-MACKENZIE LTD | O41: =IF(M41="","",HYPERLINK(M41,B41)) -> KATCEE-MACKENZIE &ASSOCIATES
A42: 40 | B42: DRUG-IT SOLUTIONS LIMITED | C42: 1, Ileshomi Street, Mafoluku, Oshodi, Lagos | D42: 08093346489 | E42: GDP | F42: 18/04/2023 | G42: Low-Risk (A) | H42: 9th may 2023 | I42: NO | J42: CAPA to be Submited | K42: =IF(I42="YES","CAPA VERIFICATION SHOULD BE SCHEDULED",IF(I42="NO","REMINDER LETTER SHOULD BE SENT","")) -> REMINDER LETTER SHOULD BE SENT | L42: 45748 | M42: https://nafdacng.sharepoint.com/sites/PMSLAGOS/Shared Documents/GDP (GOOD DISTRIBUTION PRATICE)/GSDP COMPANY FILES\DRUG IT PHARMACY | N42: https://nafdacng.sharepoint.com/sites/PMSLAGOS/Shared Documents/GSDP (GOOD STORAGE AND DISTRIBUTION PRACTICE)/GSDP COMPANY FILES\DRUG IT PHARMACY | O42: =IF(M42="","",HYPERLINK(M42,B42)) -> DRUG-IT SOLUTIONS LIMITED
A43: 41 | B43: FAMOUS NIG. LTD. | C43: 1,Olurunshogo Str., Mushin, Lagos. | D43: 08035922751 | E43: GDP | F43: 19/04/2023 | G43: High-Risk (C) | H43: 30th january 2024 | I43: YES | J43: CAPA Submited | K43: =IF(I43="YES","CAPA VERIFICATION SHOULD BE SCHEDULED",IF(I43="NO","REMINDER LETTER SHOULD BE SENT","")) -> CAPA VERIFICATION SHOULD BE SCHEDULED | L43: 45200 | M43: https://nafdacng.sharepoint.com/sites/PMSLAGOS/Shared Documents/GDP (GOOD DISTRIBUTION PRATICE)/GSDP COMPANY FILES\FAMOUS CHEMIST LTD | N43: https://nafdacng.sharepoint.com/sites/PMSLAGOS/Shared Documents/GSDP (GOOD STORAGE AND DISTRIBUTION PRACTICE)/GSDP COMPANY FILES\FAMOUS CHEMIST LTD | O43: =IF(M43="","",HYPERLINK(M43,B43)) -> FAMOUS NIG. LTD.
A44: 42 | B44: ALIMOSHO CHEMIST LTD. | C44: 47, Alew Ipaja Road, Iyana-Ipaja, Lagos | D44: The facility is no longer engaged in the importation or distribution of drugs in the past 5 years. | E44: GDP | F44: 45035 | G44: N/A | H44: N/A | I44: N/A | J44: N/A | K44: A letter stating that they have stopped distribution was recieved by the directorate. | M44: https://nafdacng.sharepoint.com/sites/PMSLAGOS/Shared Documents/GDP (GOOD DISTRIBUTION PRATICE)/GSDP COMPANY FILES\ALIMOSHO CHEMISTS LTD | N44: https://nafdacng.sharepoint.com/sites/PMSLAGOS/Shared Documents/GSDP (GOOD STORAGE AND DISTRIBUTION PRACTICE)/GSDP COMPANY FILES\ALIMOSHO CHEMISTS LTD | O44: =IF(M44="","",HYPERLINK(M44,B44)) -> ALIMOSHO CHEMIST LTD.
...

Sheet VISUAL REPRESENTATIONS
B1: GSDP INSPECTIONS | C1: CEVI INSPECTIONS | D1: CAPA SUBMITTED | E1: LOW RISK | F1: MEDIUM RISK | G1: HIGH RISK
A2: JANUARY | B2: =COUNTIFS( 'INSPECTED FACILITIES 2023'!E:E,"GDP", 'INSPECTED FACILITIES 2023'!F:F,">="&DATE(2023,MONTH(DATEVALUE(A2&" 1")),1), 'INSPECTED FACILITIES 2023'!F:F,"<"&EOMONTH(DATE(2023,MONTH(DATEVALUE(A2&" 1")),1),0)+1 ) -> 6 | C2: =COUNTIFS( 'INSPECTED FACILITIES 2023'!E:E,"CAPA", 'INSPECTED FACILITIES 2023'!F:F,">="&DATE(2023,MONTH(DATEVALUE(A2&" 1")),1), 'INSPECTED FACILITIES 2023'!F:F,"<"&EOMONTH(DATE(2023,MONTH(DATEVALUE(A2&" 1")),1),0)+1 ) -> 0 | D2: =COUNTIFS( 'INSPECTED FACILITIES 2023'!I:I,"YES", 'INSPECTED FACILITIES 2023'!F:F,">="&DATE(2023,MONTH(DATEVALUE(A2&" 1")),1), 'INSPECTED FACILITIES 2023'!F:F,"<"&EOMONTH(DATE(2023,MONTH(DATEVALUE(A2&" 1")),1),0)+1 ) -> 2 | E2: =COUNTIFS( 'INSPECTED FACILITIES 2023'!G:G,"Low-Risk (A)", 'INSPECTED FACILITIES 2023'!F:F,">="&DATE(2023,MONTH(DATEVALUE(A2&" 1")),1), 'INSPECTED FACILITIES 2023'!F:F,"<"&EOMONTH(DATE(2023,MONTH(DATEVALUE(A2&" 1")),1),0)+1 ) -> 1 | F2: =COUNTIFS( 'INSPECTED FACILITIES 2023'!G:G,"Medium-Risk (B)", 'INSPECTED FACILITIES 2023'!F:F,">="&DATE(2023,MONTH(DATEVALUE(A2&" 1")),1), 'INSPECTED FACILITIES 2023'!F:F,"<"&EOMONTH(DATE(2023,MONTH(DATEVALUE(A2&" 1")),1),0)+1 ) -> 2 | G2: =COUNTIFS( 'INSPECTED FACILITIES 2023'!G:G,"High-Risk (C)", 'INSPECTED FACILITIES 2023'!F:F,">="&DATE(2023,MONTH(DATEVALUE(A2&" 1")),1), 'INSPECTED FACILITIES 2023'!F:F,"<"&EOMONTH(DATE(2023,MONTH(DATEVALUE(A2&" 1")),1),0)+1 ) -> 0
A3: FEBRUARY | B3: =COUNTIFS( 'INSPECTED FACILITIES 2023'!E:E,"GDP", 'INSPECTED FACILITIES 2023'!F:F,">="&DATE(2023,MONTH(DATEVALUE(A3&" 1")),1), 'INSPECTED FACILITIES 2023'!F:F,"<"&EOMONTH(DATE(2023,MONTH(DATEVALUE(A3&" 1")),1),0)+1 ) -> 8 | C3: =COUNTIFS( 'INSPECTED FACILITIES 2023'!E:E,"CAPA", 'INSPECTED FACILITIES 2023'!F:F,">="&DATE(2023,MONTH(DATEVALUE(A3&" 1")),1), 'INSPECTED FACILITIES 2023'!F:F,"<"&EOMONTH(DATE(2023,MONTH(DATEVALUE(A3&" 1")),1),0)+1 ) -> 0 | D3: =COUNTIFS( 'INSPECTED FACILITIES 2023'!I:I,"YES", 'INSPECTED FACILITIES 2023'!F:F,">="&DATE(2023,MONTH(DATEVALUE(A3&" 1")),1), 'INSPECTED FACILITIES 2023'!F:F,"<"&EOMONTH(DATE(2023,MONTH(DATEVALUE(A3&" 1")),1),0)+1 ) -> 3 | E3: =COUNTIFS( 'INSPECTED FACILITIES 2023'!G:G,"Low-Risk (A)", 'INSPECTED FACILITIES 2023'!F:F,">="&DATE(2023,MONTH(DATEVALUE(A3&" 1")),1), 'INSPECTED FACILITIES 2023'!F:F,"<"&EOMONTH(DATE(2023,MONTH(DATEVALUE(A3&" 1")),1),0)+1 ) -> 4 | F3: =COUNTIFS( 'INSPECTED FACILITIES 2023'!G:G,"Medium-Risk (B)", 'INSPECTED FACILITIES 2023'!F:F,">="&DATE(2023,MONTH(DATEVALUE(A3&" 1")),1), 'INSPECTED FACILITIES 2023'!F:F,"<"&EOMONTH(DATE(2023,MONTH(DATEVALUE(A3&" 1")),1),0)+1 ) -> 2 | G3: =COUNTIFS( 'INSPECTED FACILITIES 2023'!G:G,"High-Risk (C)", 'INSPECTED FACILITIES 2023'!F:F,">="&DATE(2023,MONTH(DATEVALUE(A3&" 1")),1), 'INSPECTED FACILITIES 2023'!F:F,"<"&EOMONTH(DATE(2023,MONTH(DATEVALUE(A3&" 1")),1),0)+1 ) -> 2
A4: MARCH | B4: =COUNTIFS( 'INSPECTED FACILITIES 2023'!E:E,"GDP", 'INSPECTED FACILITIES 2023'!F:F,">="&DATE(2023,MONTH(DATEVALUE(A4&" 1")),1), 'INSPECTED FACILITIES 2023'!F:F,"<"&EOMONTH(DATE(2023,MONTH(DATEVALUE(A4&" 1")),1),0)+1 ) -> 4 | C4: =COUNTIFS( 'INSPECTED FACILITIES 2023'!E:E,"CAPA", 'INSPECTED FACILITIES 2023'!F:F,">="&DATE(2023,MONTH(DATEVALUE(A4&" 1")),1), 'INSPECTED FACILITIES 2023'!F:F,"<"&EOMONTH(DATE(2023,MONTH(DATEVALUE(A4&" 1")),1),0)+1 ) -> 0 | D4: =COUNTIFS( 'INSPECTED FACILITIES 2023'!I:I,"YES", 'INSPECTED FACILITIES 2023'!F:F,">="&DATE(2023,MONTH(DATEVALUE(A4&" 1")),1), 'INSPECTED FACILITIES 2023'!F:F,"<"&EOMONTH(DATE(2023,MONTH(DATEVALUE(A4&" 1")),1),0)+1 ) -> 0 | E4: =COUNTIFS( 'INSPECTED FACILITIES 2023'!G:G,"Low-Risk (A)", 'INSPECTED FACILITIES 2023'!F:F,">="&DATE(2023,MONTH(DATEVALUE(A4&" 1")),1), 'INSPECTED FACILITIES 2023'!F:F,"<"&EOMONTH(DATE(2023,MONTH(DATEVALUE(A4&" 1")),1),0)+1 ) -> 1 | F4: =COUNTIFS( 'INSPECTED FACILITIES 2023'!G:G,"Medium-Risk (B)", 'INSPECTED FACILITIES 2023'!F:F,">="&DATE(2023,MONTH(DATEVALUE(A4&" 1")),1), 'INSPECTED FACILITIES 2023'!F:F,"<"&EOMONTH(DATE(2023,MONTH(DATEVALUE(A4&" 1")),1),0)+1 ) -> 1 | G4: =COUNTIFS( 'INSPECTED FACILITIES 2023'!G:G,"High-Risk (C)", 'INSPECTED FACILITIES 2023'!F:F,">="&DATE(2023,MONTH(DATEVALUE(A4&" 1")),1), 'INSPECTED FACILITIES 2023'!F:F,"<"&EOMONTH(DATE(2023,MONTH(DATEVALUE(A4&" 1")),1),0)+1 ) -> 2
A5: APRIL | B5: =COUNTIFS( 'INSPECTED FACILITIES 2023'!E:E,"GDP", 'INSPECTED FACILITIES 2023'!F:F,">="&DATE(2023,MONTH(DATEVALUE(A5&" 1")),1), 'INSPECTED FACILITIES 2023'!F:F,"<"&EOMONTH(DATE(2023,MONTH(DATEVALUE(A5&" 1")),1),0)+1 ) -> 3 | C5: =COUNTIFS( 'INSPECTED FACILITIES 2023'!E:E,"CAPA", 'INSPECTED FACILITIES 2023'!F:F,">="&DATE(2023,MONTH(DATEVALUE(A5&" 1")),1), 'INSPECTED FACILITIES 2023'!F:F,"<"&EOMONTH(DATE(2023,MONTH(DATEVALUE(A5&" 1")),1),0)+1 ) -> 0 | D5: =COUNTIFS( 'INSPECTED FACILITIES 2023'!I:I,"YES", 'INSPECTED FACILITIES 2023'!F:F,">="&DATE(2023,MONTH(DATEVALUE(A5&" 1")),1), 'INSPECTED FACILITIES 2023'!F:F,"<"&EOMONTH(DATE(2023,MONTH(DATEVALUE(A5&" 1")),1),0)+1 ) -> 1 | E5: =COUNTIFS( 'INSPECTED FACILITIES 2023'!G:G,"Low-Risk (A)", 'INSPECTED FACILITIES 2023'!F:F,">="&DATE(2023,MONTH(DATEVALUE(A5&" 1")),1), 'INSPECTED FACILITIES 2023'!F:F,"<"&EOMONTH(DATE(2023,MONTH(DATEVALUE(A5&" 1")),1),0)+1 ) -> 0 | F5: =COUNTIFS( 'INSPECTED FACILITIES 2023'!G:G,"Medium-Risk (B)", 'INSPECTED FACILITIES 2023'!F:F,">="&DATE(2023,MONTH(DATEVALUE(A5&" 1")),1), 'INSPECTED FACILITIES 2023'!F:F,"<"&EOMONTH(DATE(2023,MONTH(DATEVALUE(A5&" 1")),1),0)+1 ) -> 2 | G5: =COUNTIFS( 'INSPECTED FACILITIES 2023'!G:G,"High-Risk (C)", 'INSPECTED FACILITIES 2023'!F:F,">="&DATE(2023,MONTH(DATEVALUE(A5&" 1")),1), 'INSPECTED FACILITIES 2023'!F:F,"<"&EOMONTH(DATE(2023,MONTH(DATEVALUE(A5&" 1")),1),0)+1 ) -> 0
A6: MAY | B6: =COUNTIFS( 'INSPECTED FACILITIES 2023'!E:E,"GDP", 'INSPECTED FACILITIES 2023'!F:F,">="&DATE(2023,MONTH(DATEVALUE(A6&" 1")),1), 'INSPECTED FACILITIES 2023'!F:F,"<"&EOMONTH(DATE(2023,MONTH(DATEVALUE(A6&" 1")),1),0)+1 ) -> 11 | C6: =COUNTIFS( 'INSPECTED FACILITIES 2023'!E:E,"CAPA", 'INSPECTED FACILITIES 2023'!F:F,">="&DATE(2023,MONTH(DATEVALUE(A6&" 1")),1), 'INSPECTED FACILITIES 2023'!F:F,"<"&EOMONTH(DATE(2023,MONTH(DATEVALUE(A6&" 1")),1),0)+1 ) -> 0 | D6: =COUNTIFS( 'INSPECTED FACILITIES 2023'!I:I,"YES", 'INSPECTED FACILITIES 2023'!F:F,">="&DATE(2023,MONTH(DATEVALUE(A6&" 1")),1), 'INSPECTED FACILITIES 2023'!F:F,"<"&EOMONTH(DATE(2023,MONTH(DATEVALUE(A6&" 1")),1),0)+1 ) -> 1 | E6: =COUNTIFS( 'INSPECTED FACILITIES 2023'!G:G,"Low-Risk (A)", 'INSPECTED FACILITIES 2023'!F:F,">="&DATE(2023,MONTH(DATEVALUE(A6&" 1")),1), 'INSPECTED FACILITIES 2023'!F:F,"<"&EOMONTH(DATE(2023,MONTH(DATEVALUE(A6&" 1")),1),0)+1 ) -> 0 | F6: =COUNTIFS( 'INSPECTED FACILITIES 2023'!G:G,"Medium-Risk (B)", 'INSPECTED FACILITIES 2023'!F:F,">="&DATE(2023,MONTH(DATEVALUE(A6&" 1")),1), 'INSPECTED FACILITIES 2023'!F:F,"<"&EOMONTH(DATE(2023,MONTH(DATEVALUE(A6&" 1")),1),0)+1 ) -> 5 | G6: =COUNTIFS( 'INSPECTED FACILITIES 2023'!G:G,"High-Risk (C)", 'INSPECTED FACILITIES 2023'!F:F,">="&DATE(2023,MONTH(DATEVALUE(A6&" 1")),1), 'INSPECTED FACILITIES 2023'!F:F,"<"&EOMONTH(DATE(2023,MONTH(DATEVALUE(A6&" 1")),1),0)+1 ) -> 5
A7: JUNE | B7: =COUNTIFS( 'INSPECTED FACILITIES 2023'!E:E,"GDP", 'INSPECTED FACILITIES 2023'!F:F,">="&DATE(2023,MONTH(DATEVALUE(A7&" 1")),1), 'INSPECTED FACILITIES 2023'!F:F,"<"&EOMONTH(DATE(2023,MONTH(DATEVALUE(A7&" 1")),1),0)+1 ) -> 1 | C7: =COUNTIFS( 'INSPECTED FACILITIES 2023'!E:E,"CAPA", 'INSPECTED FACILITIES 2023'!F:F,">="&DATE(2023,MONTH(DATEVALUE(A7&" 1")),1), 'INSPECTED FACILITIES 2023'!F:F,"<"&EOMONTH(DATE(2023,MONTH(DATEVALUE(A7&" 1")),1),0)+1 ) -> 0 | D7: =COUNTIFS( 'INSPECTED FACILITIES 2023'!I:I,"YES", 'INSPECTED FACILITIES 2023'!F:F,">="&DATE(2023,MONTH(DATEVALUE(A7&" 1")),1), 'INSPECTED FACILITIES 2023'!F:F,"<"&EOMONTH(DATE(2023,MONTH(DATEVALUE(A7&" 1")),1),0)+1 ) -> 0 | E7: =COUNTIFS( 'INSPECTED FACILITIES 2023'!G:G,"Low-Risk (A)", 'INSPECTED FACILITIES 2023'!F:F,">="&DATE(2023,MONTH(DATEVALUE(A7&" 1")),1), 'INSPECTED FACILITIES 2023'!F:F,"<"&EOMONTH(DATE(2023,MONTH(DATEVALUE(A7&" 1")),1),0)+1 ) -> 1 | F7: =COUNTIFS( 'INSPECTED FACILITIES 2023'!G:G,"Medium-Risk (B)", 'INSPECTED FACILITIES 2023'!F:F,">="&DATE(2023,MONTH(DATEVALUE(A7&" 1")),1), 'INSPECTED FACILITIES 2023'!F:F,"<"&EOMONTH(DATE(2023,MONTH(DATEVALUE(A7&" 1")),1),0)+1 ) -> 0 | G7: =COUNTIFS( 'INSPECTED FACILITIES 2023'!G:G,"High-Risk (C)", 'INSPECTED FACILITIES 2023'!F:F,">="&DATE(2023,MONTH(DATEVALUE(A7&" 1")),1), 'INSPECTED FACILITIES 2023'!F:F,"<"&EOMONTH(DATE(2023,MONTH(DATEVALUE(A7&" 1")),1),0)+1 ) -> 0
A8: JULY | B8: =COUNTIFS( 'INSPECTED FACILITIES 2023'!E:E,"GDP", 'INSPECTED FACILITIES 2023'!F:F,">="&DATE(2023,MONTH(DATEVALUE(A8&" 1")),1), 'INSPECTED FACILITIES 2023'!F:F,"<"&EOMONTH(DATE(2023,MONTH(DATEVALUE(A8&" 1")),1),0)+1 ) -> 3 | C8: =COUNTIFS( 'INSPECTED FACILITIES 2023'!E:E,"CAPA", 'INSPECTED FACILITIES 2023'!F:F,">="&DATE(2023,MONTH(DATEVALUE(A8&" 1")),1), 'INSPECTED FACILITIES 2023'!F:F,"<"&EOMONTH(DATE(2023,MONTH(DATEVALUE(A8&" 1")),1),0)+1 ) -> 0 | D8: =COUNTIFS( 'INSPECTED FACILITIES 2023'!I:I,"YES", 'INSPECTED FACILITIES 2023'!F:F,">="&DATE(2023,MONTH(DATEVALUE(A8&" 1")),1), 'INSPECTED FACILITIES 2023'!F:F,"<"&EOMONTH(DATE(2023,MONTH(DATEVALUE(A8&" 1")),1),0)+1 ) -> 0 | E8: =COUNTIFS( 'INSPECTED FACILITIES 2023'!G:G,"Low-Risk (A)", 'INSPECTED FACILITIES 2023'!F:F,">="&DATE(2023,MONTH(DATEVALUE(A8&" 1")),1), 'INSPECTED FACILITIES 2023'!F:F,"<"&EOMONTH(DATE(2023,MONTH(DATEVALUE(A8&" 1")),1),0)+1 ) -> 0 | F8: =COUNTIFS( 'INSPECTED FACILITIES 2023'!G:G,"Medium-Risk (B)", 'INSPECTED FACILITIES 2023'!F:F,">="&DATE(2023,MONTH(DATEVALUE(A8&" 1")),1), 'INSPECTED FACILITIES 2023'!F:F,"<"&EOMONTH(DATE(2023,MONTH(DATEVALUE(A8&" 1")),1),0)+1 ) -> 1 | G8: =COUNTIFS( 'INSPECTED FACILITIES 2023'!G:G,"High-Risk (C)", 'INSPECTED FACILITIES 2023'!F:F,">="&DATE(2023,MONTH(DATEVALUE(A8&" 1")),1), 'INSPECTED FACILITIES 2023'!F:F,"<"&EOMONTH(DATE(2023,MONTH(DATEVALUE(A8&" 1")),1),0)+1 ) -> 2
A9: AUGUST | B9: =COUNTIFS( 'INSPECTED FACILITIES 2023'!E:E,"GDP", 'INSPECTED FACILITIES 2023'!F:F,">="&DATE(2023,MONTH(DATEVALUE(A9&" 1")),1), 'INSPECTED FACILITIES 2023'!F:F,"<"&EOMONTH(DATE(2023,MONTH(DATEVALUE(A9&" 1")),1),0)+1 ) -> 3 | C9: =COUNTIFS( 'INSPECTED FACILITIES 2023'!E:E,"CAPA", 'INSPECTED FACILITIES 2023'!F:F,">="&DATE(2023,MONTH(DATEVALUE(A9&" 1")),1), 'INSPECTED FACILITIES 2023'!F:F,"<"&EOMONTH(DATE(2023,MONTH(DATEVALUE(A9&" 1")),1),0)+1 ) -> 0 | D9: =COUNTIFS( 'INSPECTED FACILITIES 2023'!I:I,"YES", 'INSPECTED FACILITIES 2023'!F:F,">="&DATE(2023,MONTH(DATEVALUE(A9&" 1")),1), 'INSPECTED FACILITIES 2023'!F:F,"<"&EOMONTH(DATE(2023,MONTH(DATEVALUE(A9&" 1")),1),0)+1 ) -> 1 | E9: =COUNTIFS( 'INSPECTED FACILITIES 2023'!G:G,"Low-Risk (A)", 'INSPECTED FACILITIES 2023'!F:F,">="&DATE(2023,MONTH(DATEVALUE(A9&" 1")),1), 'INSPECTED FACILITIES 2023'!F:F,"<"&EOMONTH(DATE(2023,MONTH(DATEVALUE(A9&" 1")),1),0)+1 ) -> 0 | F9: =COUNTIFS( 'INSPECTED FACILITIES 2023'!G:G,"Medium-Risk (B)", 'INSPECTED FACILITIES 2023'!F:F,">="&DATE(2023,MONTH(DATEVALUE(A9&" 1")),1), 'INSPECTED FACILITIES 2023'!F:F,"<"&EOMONTH(DATE(2023,MONTH(DATEVALUE(A9&" 1")),1),0)+1 ) -> 1 | G9: =COUNTIFS( 'INSPECTED FACILITIES 2023'!G:G,"High-Risk (C)", 'INSPECTED FACILITIES 2023'!F:F,">="&DATE(2023,MONTH(DATEVALUE(A9&" 1")),1), 'INSPECTED FACILITIES 2023'!F:F,"<"&EOMONTH(DATE(2023,MONTH(DATEVALUE(A9&" 1")),1),0)+1 ) -> 0
A10: SEPTEMBER | B10: =COUNTIFS( 'INSPECTED FACILITIES 2023'!E:E,"GDP", 'INSPECTED FACILITIES 2023'!F:F,">="&DATE(2023,MONTH(DATEVALUE(A10&" 1")),1), 'INSPECTED FACILITIES 2023'!F:F,"<"&EOMONTH(DATE(2023,MONTH(DATEVALUE(A10&" 1")),1),0)+1 ) -> 4 | C10: =COUNTIFS( 'INSPECTED FACILITIES 2023'!E:E,"CAPA", 'INSPECTED FACILITIES 2023'!F:F,">="&DATE(2023,MONTH(DATEVALUE(A10&" 1")),1), 'INSPECTED FACILITIES 2023'!F:F,"<"&EOMONTH(DATE(2023,MONTH(DATEVALUE(A10&" 1")),1),0)+1 ) -> 0 | D10: =COUNTIFS( 'INSPECTED FACILITIES 2023'!I:I,"YES", 'INSPECTED FACILITIES 2023'!F:F,">="&DATE(2023,MONTH(DATEVALUE(A10&" 1")),1), 'INSPECTED FACILITIES 2023'!F:F,"<"&EOMONTH(DATE(2023,MONTH(DATEVALUE(A10&" 1")),1),0)+1 ) -> 2 | E10: =COUNTIFS( 'INSPECTED FACILITIES 2023'!G:G,"Low-Risk (A)", 'INSPECTED FACILITIES 2023'!F:F,">="&DATE(2023,MONTH(DATEVALUE(A10&" 1")),1), 'INSPECTED FACILITIES 2023'!F:F,"<"&EOMONTH(DATE(2023,MONTH(DATEVALUE(A10&" 1")),1),0)+1 ) -> 2 | F10: =COUNTIFS( 'INSPECTED FACILITIES 2023'!G:G,"Medium-Risk (B)", 'INSPECTED FACILITIES 2023'!F:F,">="&DATE(2023,MONTH(DATEVALUE(A10&" 1")),1), 'INSPECTED FACILITIES 2023'!F:F,"<"&EOMONTH(DATE(2023,MONTH(DATEVALUE(A10&" 1")),1),0)+1 ) -> 0 | G10: =COUNTIFS( 'INSPECTED FACILITIES 2023'!G:G,"High-Risk (C)", 'INSPECTED FACILITIES 2023'!F:F,">="&DATE(2023,MONTH(DATEVALUE(A10&" 1")),1), 'INSPECTED FACILITIES 2023'!F:F,"<"&EOMONTH(DATE(2023,MONTH(DATEVALUE(A10&" 1")),1),0)+1 ) -> 1
A11: OCTOBER | B11: =COUNTIFS( 'INSPECTED FACILITIES 2023'!E:E,"GDP", 'INSPECTED FACILITIES 2023'!F:F,">="&DATE(2023,MONTH(DATEVALUE(A11&" 1")),1), 'INSPECTED FACILITIES 2023'!F:F,"<"&EOMONTH(DATE(2023,MONTH(DATEVALUE(A11&" 1")),1),0)+1 ) -> 3 | C11: =COUNTIFS( 'INSPECTED FACILITIES 2023'!E:E,"CAPA", 'INSPECTED FACILITIES 2023'!F:F,">="&DATE(2023,MONTH(DATEVALUE(A11&" 1")),1), 'INSPECTED FACILITIES 2023'!F:F,"<"&EOMONTH(DATE(2023,MONTH(DATEVALUE(A11&" 1")),1),0)+1 ) -> 0 | D11: =COUNTIFS( 'INSPECTED FACILITIES 2023'!I:I,"YES", 'INSPECTED FACILITIES 2023'!F:F,">="&DATE(2023,MONTH(DATEVALUE(A11&" 1")),1), 'INSPECTED FACILITIES 2023'!F:F,"<"&EOMONTH(DATE(2023,MONTH(DATEVALUE(A11&" 1")),1),0)+1 ) -> 0 | E11: =COUNTIFS( 'INSPECTED FACILITIES 2023'!G:G,"Low-Risk (A)", 'INSPECTED FACILITIES 2023'!F:F,">="&DATE(2023,MONTH(DATEVALUE(A11&" 1")),1), 'INSPECTED FACILITIES 2023'!F:F,"<"&EOMONTH(DATE(2023,MONTH(DATEVALUE(A11&" 1")),1),0)+1 ) -> 0 | F11: =COUNTIFS( 'INSPECTED FACILITIES 2023'!G:G,"Medium-Risk (B)", 'INSPECTED FACILITIES 2023'!F:F,">="&DATE(2023,MONTH(DATEVALUE(A11&" 1")),1), 'INSPECTED FACILITIES 2023'!F:F,"<"&EOMONTH(DATE(2023,MONTH(DATEVALUE(A11&" 1")),1),0)+1 ) -> 2 | G11: =COUNTIFS( 'INSPECTED FACILITIES 2023'!G:G,"High-Risk (C)", 'INSPECTED FACILITIES 2023'!F:F,">="&DATE(2023,MONTH(DATEVALUE(A11&" 1")),1), 'INSPECTED FACILITIES 2023'!F:F,"<"&EOMONTH(DATE(2023,MONTH(DATEVALUE(A11&" 1")),1),0)+1 ) -> 0
A12: NOVEMBER | B12: =COUNTIFS( 'INSPECTED FACILITIES 2023'!E:E,"GDP", 'INSPECTED FACILITIES 2023'!F:F,">="&DATE(2023,MONTH(DATEVALUE(A12&" 1")),1), 'INSPECTED FACILITIES 2023'!F:F,"<"&EOMONTH(DATE(2023,MONTH(DATEVALUE(A12&" 1")),1),0)+1 ) -> 0 | C12: =COUNTIFS( 'INSPECTED FACILITIES 2023'!E:E,"CAPA", 'INSPECTED FACILITIES 2023'!F:F,">="&DATE(2023,MONTH(DATEVALUE(A12&" 1")),1), 'INSPECTED FACILITIES 2023'!F:F,"<"&EOMONTH(DATE(2023,MONTH(DATEVALUE(A12&" 1")),1),0)+1 ) -> 0 | D12: =COUNTIFS( 'INSPECTED FACILITIES 2023'!I:I,"YES", 'INSPECTED FACILITIES 2023'!F:F,">="&DATE(2023,MONTH(DATEVALUE(A12&" 1")),1), 'INSPECTED FACILITIES 2023'!F:F,"<"&EOMONTH(DATE(2023,MONTH(DATEVALUE(A12&" 1")),1),0)+1 ) -> 0 | E12: =COUNTIFS( 'INSPECTED FACILITIES 2023'!G:G,"Low-Risk (A)", 'INSPECTED FACILITIES 2023'!F:F,">="&DATE(2023,MONTH(DATEVALUE(A12&" 1")),1), 'INSPECTED FACILITIES 2023'!F:F,"<"&EOMONTH(DATE(2023,MONTH(DATEVALUE(A12&" 1")),1),0)+1 ) -> 0 | F12: =COUNTIFS( 'INSPECTED FACILITIES 2023'!G:G,"Medium-Risk (B)", 'INSPECTED FACILITIES 2023'!F:F,">="&DATE(2023,MONTH(DATEVALUE(A12&" 1")),1), 'INSPECTED FACILITIES 2023'!F:F,"<"&EOMONTH(DATE(2023,MONTH(DATEVALUE(A12&" 1")),1),0)+1 ) -> 0 | G12: =COUNTIFS( 'INSPECTED FACILITIES 2023'!G:G,"High-Risk (C)", 'INSPECTED FACILITIES 2023'!F:F,">="&DATE(2023,MONTH(DATEVALUE(A12&" 1")),1), 'INSPECTED FACILITIES 2023'!F:F,"<"&EOMONTH(DATE(2023,MONTH(DATEVALUE(A12&" 1")),1),0)+1 ) -> 0
A13: DECEMBER | B13: =COUNTIFS( 'INSPECTED FACILITIES 2023'!E:E,"GDP", 'INSPECTED FACILITIES 2023'!F:F,">="&DATE(2023,MONTH(DATEVALUE(A13&" 1")),1), 'INSPECTED FACILITIES 2023'!F:F,"<"&EOMONTH(DATE(2023,MONTH(DATEVALUE(A13&" 1")),1),0)+1 ) -> 3 | C13: =COUNTIFS( 'INSPECTED FACILITIES 2023'!E:E,"CAPA", 'INSPECTED FACILITIES 2023'!F:F,">="&DATE(2023,MONTH(DATEVALUE(A13&" 1")),1), 'INSPECTED FACILITIES 2023'!F:F,"<"&EOMONTH(DATE(2023,MONTH(DATEVALUE(A13&" 1")),1),0)+1 ) -> 0 | D13: =COUNTIFS( 'INSPECTED FACILITIES 2023'!I:I,"YES", 'INSPECTED FACILITIES 2023'!F:F,">="&DATE(2023,MONTH(DATEVALUE(A13&" 1")),1), 'INSPECTED FACILITIES 2023'!F:F,"<"&EOMONTH(DATE(2023,MONTH(DATEVALUE(A13&" 1")),1),0)+1 ) -> 1 | E13: =COUNTIFS( 'INSPECTED FACILITIES 2023'!G:G,"Low-Risk (A)", 'INSPECTED FACILITIES 2023'!F:F,">="&DATE(2023,MONTH(DATEVALUE(A13&" 1")),1), 'INSPECTED FACILITIES 2023'!F:F,"<"&EOMONTH(DATE(2023,MONTH(DATEVALUE(A13&" 1")),1),0)+1 ) -> 1 | F13: =COUNTIFS( 'INSPECTED FACILITIES 2023'!G:G,"Medium-Risk (B)", 'INSPECTED FACILITIES 2023'!F:F,">="&DATE(2023,MONTH(DATEVALUE(A13&" 1")),1), 'INSPECTED FACILITIES 2023'!F:F,"<"&EOMONTH(DATE(2023,MONTH(DATEVALUE(A13&" 1")),1),0)+1 ) -> 1 | G13: =COUNTIFS( 'INSPECTED FACILITIES 2023'!G:G,"High-Risk (C)", 'INSPECTED FACILITIES 2023'!F:F,">="&DATE(2023,MONTH(DATEVALUE(A13&" 1")),1), 'INSPECTED FACILITIES 2023'!F:F,"<"&EOMONTH(DATE(2023,MONTH(DATEVALUE(A13&" 1")),1),0)+1 ) -> 0

Sheet FEB
A1: GDP INSPECTION CLASSIFICATION DATA BASE AS AT 2023
A2: S/N | B2: NAME OF MANUFACTURER | C2: LOCATION ADDRESS | D2: CONTACT | E2: TYPE OF LAST INSPECTION | F2: DATE OF LAST INSPECTION | G2: FINDINGS | H2: CAPA ISSUED DATE | I2: CAPA SUBMITTED | J2: CONCLUSION | K2: REMARKS | L2: EXPECTED DATE OF INSPECTION | M2: OMPANY FILE | N2: Column2
A3: 1 | B3: MECURE INDUSTRIES LTD | C3: Plot 6, Block H, Apapa Oshodi Expressway, Oshodi, Lagos | D3: 0700632873 | E3: GDP | F3: 44970 | G3: Low-Risk (A) | H3: 31st march 2023 | I3: YES | J3: CAPA Submited | K3: CAPA VERIFICATION SHOULD BE SCHEDULED | L3: 45689 | M3: https://nafdacng.sharepoint.com/sites/PMSLAGOS/Shared Documents/GDP (GOOD DISTRIBUTION PRATICE)/GSDP COMPANY FILES\MECURE IND. LTD | N3: MECURE INDUSTRIES LTD
A4: 2 | B4: GENEITH PHARMACEUTICALS | C4: 12, Adewale Crescent, Oshodi, Lagos | D4: 08122912281 | E4: GDP | F4: 44970 | G4: Low-Risk (A) | H4: 31st march 2023 | I4: YES | J4: CAPA Submited | K4: =IF(I4="YES","CAPA VERIFICATION SHOULD BE SCHEDULED",IF(I4="NO","REMINDER LETTER SHOULD BE SENT","")) -> CAPA VERIFICATION SHOULD BE SCHEDULED | L4: 45689 | M4: https://nafdacng.sharepoint.com/sites/PMSLAGOS/Shared Documents/GDP (GOOD DISTRIBUTION PRATICE)/GSDP COMPANY FILES\GENEITH PHARM. LTD | N4: =IF(M4="","",HYPERLINK(M4,B4)) -> GENEITH PHARMACEUTICALS
A5: 3 | B5: ONWUADI & SONS LTD | C5: 11, Achakpo Street, Ajegunle, Lagos | D5: 08028642459 | E5: GDP | F5: 44970 | G5: Medium-Risk (B) | H5: 4th April 2023 | I5: YES | J5: CAPA Submited | K5: =IF(I5="YES","CAPA VERIFICATION SHOULD BE SCHEDULED",IF(I5="NO","REMINDER LETTER SHOULD BE SENT","")) -> CAPA VERIFICATION SHOULD BE SCHEDULED | L5: 45323 | M5: https://nafdacng.sharepoint.com/sites/PMSLAGOS/Shared Documents/GDP (GOOD DISTRIBUTION PRATICE)/GSDP COMPANY FILES\ONWUADI AND SONS LTD | N5: =IF(M5="","",HYPERLINK(M5,B5)) -> ONWUADI & SONS LTD
A6: 4 | B6: MODDY DRUG CO. LTD | C6: 93, Baale Street, Ajegunle, Lagos | D6: 0802306320 | E6: GDP | F6: 44970 | G6: Medium-Risk (B) | H6: 4th April 2023 | I6: NO | J6: CAPA to be Submited | K6: =IF(I6="YES","CAPA VERIFICATION SHOULD BE SCHEDULED",IF(I6="NO","REMINDER LETTER SHOULD BE SENT","")) -> REMINDER LETTER SHOULD BE SENT | L6: 45323 | M6: https://nafdacng.sharepoint.com/sites/PMSLAGOS/Shared Documents/GDP (GOOD DISTRIBUTION PRATICE)/GSDP COMPANY FILES\MOODY DRUGS CO. LTD | N6: =IF(M6="","",HYPERLINK(M6,B6)) -> MODDY DRUG CO. LTD
A7: 5 | B7: JUMENCO PHARMACEUTICAL | C7: 52, Ladega Street, Ikorodu,Lagos | D7: 08065232177 | E7: GDP | F7: 14/02/2023 | G7: Medium-Risk (B) | H7: 31st march 2023 | I7: NO | J7: CAPA to be Submited | K7: =IF(I7="YES","CAPA VERIFICATION SHOULD BE SCHEDULED",IF(I7="NO","REMINDER LETTER SHOULD BE SENT","")) -> REMINDER LETTER SHOULD BE SENT | L7: 45323 | M7: https://nafdacng.sharepoint.com/sites/PMSLAGOS/Shared Documents/GDP (GOOD DISTRIBUTION PRATICE)/GSDP COMPANY FILES\JUMENCO PHARMACEUTICALS LTD | N7: =IF(M7="","",HYPERLINK(M7,B7)) -> JUMENCO PHARMACEUTICAL
A8: 6 | B8: ANOKEM PHARMACEUTICALS | C8: 58,Eluku Street,Ikorodu, Lagos | D8: 07017691325 | E8: GDP | F8: 14/02/2023 | G8: Medium-Risk (B) | H8: 4th April 2023 | I8: NO | J8: CAPA to be Submited | K8: =IF(I8="YES","CAPA VERIFICATION SHOULD BE SCHEDULED",IF(I8="NO","REMINDER LETTER SHOULD BE SENT","")) -> REMINDER LETTER SHOULD BE SENT | L8: 45323 | M8: https://nafdacng.sharepoint.com/sites/PMSLAGOS/Shared Documents/GDP (GOOD DISTRIBUTION PRATICE)/GSDP COMPANY FILES\ANOKEM PHARM. LTD | N8: =IF(M8="","",HYPERLINK(M8,B8)) -> ANOKEM PHARMACEUTICALS
A9: 7 | B9: RALPHONES PHARMACEUTICAL | C9: 1 Ralphone Lane,Irawo ajegunle,ikorodu,Lagos | D9: 08037588238 | E9: GDP | F9: 14/02/2023 | G9: Low-Risk (A) | H9: 31st march 2023 | I9: YES | J9: CAPA Submited | K9: =IF(I9="YES","CAPA VERIFICATION SHOULD BE SCHEDULED",IF(I9="NO","REMINDER LETTER SHOULD BE SENT","")) -> CAPA VERIFICATION SHOULD BE SCHEDULED | L9: 45689 | M9: https://nafdacng.sharepoint.com/sites/PMSLAGOS/Shared Documents/GDP (GOOD DISTRIBUTION PRATICE)/GSDP COMPANY FILES\RALPHONES PHARMACEUTICAL LTD | N9: =IF(M9="","",HYPERLINK(M9,B9)) -> RALPHONES PHARMACEUTICAL
A10: 8 | B10: LUGZ PHARMACEUTICAL | C10: 58,Lagos Rd,Opp UBA,Ikorodu, Lagos | D10: 08093955361 08148337773 | E10: GDP | F10: 14/02/2023 | G10: Medium-Risk (B) | H10: 4th April 2023 | I10: NO | J10: CAPA to be Submited | K10: =IF(I10="YES","CAPA VERIFICATION SHOULD BE SCHEDULED",IF(I10="NO","REMINDER LETTER SHOULD BE SENT","")) -> REMINDER LETTER SHOULD BE SENT | L10: 45323 | M10: https://nafdacng.sharepoint.com/sites/PMSLAGOS/Shared Documents/GDP (GOOD DISTRIBUTION PRATICE)/GSDP COMPANY FILES\LUGZ PHARMACY | N10: =IF(M10="","",HYPERLINK(M10,B10)) -> LUGZ PHARMACEUTICAL
A11: 9 | B11: LADAMOS PHARMACY | C11: 2, Adenaike Alagbe Street , Ikorodu, Lagos | D11: 08033885195 | E11: GDP | F11: 14/02/2023 | G11: High-Risk (C) | H11: They were not issued cd | I11: N/A | J11: CAPA to be Submited | K11: =IF(I11="YES","CAPA VERIFICATION SHOULD BE SCHEDULED",IF(I11="NO","REMINDER LETTER SHOULD BE SENT","")) | L11: 44774 | N11: =IF(M11="","",HYPERLINK(M11,B11))
A12: 10 | B12: GOODCARE PHARMACEUTICAL | C12: 11, sawo Road,Agric,Ikorodu,Lagos | D12: 08064266572 | E12: GDP | F12: 15/02/2023 | G12: Medium-Risk (B) | H12: 4th April 2023 | I12: YES | J12: CAPA Submited | K12: =IF(I12="YES","CAPA VERIFICATION SHOULD BE SCHEDULED",IF(I12="NO","REMINDER LETTER SHOULD BE SENT","")) -> CAPA VERIFICATION SHOULD BE SCHEDULED | L12: 45323 | M12: https://nafdacng.sharepoint.com/sites/PMSLAGOS/Shared Documents/GDP (GOOD DISTRIBUTION PRATICE)/GSDP COMPANY FILES\GOODCARE | N12: =IF(M12="","",HYPERLINK(M12,B12)) -> GOODCARE PHARMACEUTICAL
A13: 11 | B13: PATVICS PHARMACEUTICAL | C13: 603, Ikorodu Road, Mile 12, Lagos | D13: 08033927269 | E13: GDP | F13: 15/02/2023 | G13: High-Risk (C) | H13: 4th April 2023 | I13: NO | J13: CAPA to be Submited | K13: =IF(I13="YES","CAPA VERIFICATION SHOULD BE SCHEDULED",IF(I13="NO","REMINDER LETTER SHOULD BE SENT","")) -> REMINDER LETTER SHOULD BE SENT | L13: 44774 | M13: https://nafdacng.sharepoint.com/sites/PMSLAGOS/Shared Documents/GDP (GOOD DISTRIBUTION PRATICE)/GSDP COMPANY FILES\PATVICS LTD | N13: =IF(M13="","",HYPERLINK(M13,B13)) -> PATVICS PHARMACEUTICAL
A14: 12 | B14: KOJOS PHARMACY | C14: 5, Oju Emuren Street, Odogunyan, Ikorodu | D14: 08073823496 | E14: GDP | F14: 15/02/2023 | G14: Low-Risk (A) | H14: 31st march 2023 | I14: NO | J14: CAPA to be Submited | K14: =IF(I14="YES","CAPA VERIFICATION SHOULD BE SCHEDULED",IF(I14="NO","REMINDER LETTER SHOULD BE SENT","")) -> REMINDER LETTER SHOULD BE SENT | L14: 45689 | M14: https://nafdacng.sharepoint.com/sites/PMSLAGOS/Shared Documents/GDP (GOOD DISTRIBUTION PRATICE)/GSDP COMPANY FILES\KOJOS PHARMACY LTD | N14: =IF(M14="","",HYPERLINK(M14,B14)) -> KOJOS PHARMACY
A15: 13 | B15: VIXA PHARMACEUTICALS | C15: 13B, Sunday Jigida street, off celestical way,ogudu, lagos | D15: 07082004139 | E15: GDP | F15: 15/02/2023 | G15: Medium-Risk (B) | H15: 4th April 2023 | I15: YES | J15: CAPA Submited | K15: =IF(I15="YES","CAPA VERIFICATION SHOULD BE SCHEDULED",IF(I15="NO","REMINDER LETTER SHOULD BE SENT","")) -> CAPA VERIFICATION SHOULD BE SCHEDULED | L15: 45323 | N15: =IF(M15="","",HYPERLINK(M15,B15))
A16: 14 | B16: SWIPHA NIGERIA | C16: 5, Dopemu road, depemu Lagos | D16: 08146679976 | E16: GDP | F16: 16/02/2023 | G16: Low-Risk (A) | H16: 4th April 2023 | I16: YES | J16: CAPA Submited | K16: =IF(I16="YES","CAPA VERIFICATION SHOULD BE SCHEDULED",IF(I16="NO","REMINDER LETTER SHOULD BE SENT","")) -> CAPA VERIFICATION SHOULD BE SCHEDULED | L16: 45689 | M16: https://nafdacng.sharepoint.com/sites/PMSLAGOS/Shared Documents/GDP (GOOD DISTRIBUTION PRATICE)/GSDP COMPANY FILES\SWIPHA NIG. LTD | N16: =IF(M16="","",HYPERLINK(M16,B16)) -> SWIPHA NIGERIA
A17: 15 | B17: BJ CHOICE PHARM | C17: 1, Okenube Last Bus Stop, Ikotun Lagos | D17: 08033204754 | E17: GDP | F17: 16/02/2023 | G17: Medium-Risk (B) | H17: 45631 | I17: NO | J17: CAPA to be Submited | K17: =IF(I17="YES","CAPA VERIFICATION SHOULD BE SCHEDULED",IF(I17="NO","REMINDER LETTER SHOULD BE SENT","")) -> REMINDER LETTER SHOULD BE SENT | L17: 45323 | M17: https://nafdacng.sharepoint.com/sites/PMSLAGOS/Shared Documents/GDP (GOOD DISTRIBUTION PRATICE)/GSDP COMPANY FILES\BJ CHOICE PHARM. LTD | N17: =IF(M17="","",HYPERLINK(M17,B17)) -> BJ CHOICE PHARM
A18: 16 | B18: PAKEN VENTURES | C18: 294, Idimu Road, Ikotun-Egbeda | D18: 08103961314 | E18: GDP | F18: 16/02/2023 | G18: High-Risk (C) | H18: 4th April 2023 | I18: NO | J18: CAPA to be Submited | K18: =IF(I18="YES","CAPA VERIFICATION SHOULD BE SCHEDULED",IF(I18="NO","REMINDER LETTER SHOULD BE SENT","")) -> REMINDER LETTER SHOULD BE SENT | L18: 44774 | M18: https://nafdacng.sharepoint.com/sites/PMSLAGOS/Shared Documents/GDP (GOOD DISTRIBUTION PRATICE)/GSDP COMPANY FILES\PAKEN VENTURES LTD | N18: =IF(M18="","",HYPERLINK(M18,B18)) -> PAKEN VENTURES
A19: 17 | B19: HENBOSCO PHARMACY | C19: 195, Abeokuta Exp. Way, Iyana Ipaja | D19: 08099916512 | E19: GDP | F19: 17/02/2023 | G19: High-Risk (C) | H19: They were not issued cd | I19: NO | J19: CAPA to be Submited | K19: =IF(I19="YES","CAPA VERIFICATION SHOULD BE SCHEDULED",IF(I19="NO","REMINDER LETTER SHOULD BE SENT","")) -> REMINDER LETTER SHOULD BE SENT | L19: 44774 | M19: https://nafdacng.sharepoint.com/sites/PMSLAGOS/Shared Documents/GDP (GOOD DISTRIBUTION PRATICE)/GSDP COMPANY FILES\HENBOSCO PHARMACY LTD | N19: =IF(M19="","",HYPERLINK(M19,B19)) -> HENBOSCO PHARMACY
A20: 18 | B20: LYNDUS PHARMACY LTD | C20: 9 Akesan Rd, Egan, by Nepa, Igando, Alimosho, Lagos | D20: 08137719998 08037138148 | E20: GDP | F20: 21/02/2023 | G20: High-Risk (C) | H20: 4th April 2023 | I20: NO | J20: CAPA to be Submited | K20: =IF(I20="YES","CAPA VERIFICATION SHOULD BE SCHEDULED",IF(I20="NO","REMINDER LETTER SHOULD BE SENT","")) -> REMINDER LETTER SHOULD BE SENT | L20: 44774 | M20: https://nafdacng.sharepoint.com/sites/PMSLAGOS/Shared Documents/GDP (GOOD DISTRIBUTION PRATICE)/GSDP COMPANY FILES\LYNDUS PHARMACY LTD | N20: =IF(M20="","",HYPERLINK(M20,B20)) -> LYNDUS PHARMACY LTD
A21: 19 | B21: ROM CHIDECK PHARM. LTD | C21: 4, Disusts, Isheri, Oshun, Alem, Lagos . | D21: 07018687107 | E21: GDP | F21: 21/02/2023 | G21: High-Risk (C) | H21: 4th April 2023 | I21: NO | J21: CAPA to be Submited | K21: =IF(I21="YES","CAPA VERIFICATION SHOULD BE SCHEDULED",IF(I21="NO","REMINDER LETTER SHOULD BE SENT","")) -> REMINDER LETTER SHOULD BE SENT | L21: 44774 | M21: https://nafdacng.sharepoint.com/sites/PMSLAGOS/Shared%20Documents/GDP%20(GOOD%20DISTRIBUTION%20PRATICE)/GSDP%20COMPANY%20FILES\ROM-CHIDEK | N21: =IF(M21="","",HYPERLINK(M21,B21)) -> ROM CHIDECK PHARM. LTD
A22: 20 | B22: JUVYWAY PHARMCY CO.LTD | C22: 57,Alimosho Road,Iyana- Ipaja, Lagos | D22: 08133295836 | E22: GDP | F22: 22/02/2023 | G22: High-Risk (C) | H22: 4th April 2023 | I22: YES | J22: CAPA Submited | K22: =IF(I22="YES","CAPA VERIFICATION SHOULD BE SCHEDULED",IF(I22="NO","REMINDER LETTER SHOULD BE SENT","")) -> CAPA VERIFICATION SHOULD BE SCHEDULED | L22: 45536 | M22: https://nafdacng.sharepoint.com/sites/PMSLAGOS/Shared Documents/GDP (GOOD DISTRIBUTION PRATICE)/GSDP COMPANY FILES\JUVYWAY PHARMACY | N22: =IF(M22="","",HYPERLINK(M22,B22)) -> JUVYWAY PHARMCY CO.LTD
A23: 21 | B23: EVERSHINE PHARMACEUTICAL NIG LTD | C23: 41, Amoke Alasala Street, Iyana- Ipaja, Lagos | D23: 08061290502 | E23: GDP | F23: 22/02/2023 | G23: Medium-Risk (B) | H23: 4th April 2023 | I23: YES | J23: CAPA Submited | K23: =IF(I23="YES","CAPA VERIFICATION SHOULD BE SCHEDULED",IF(I23="NO","REMINDER LETTER SHOULD BE SENT","")) -> CAPA VERIFICATION SHOULD BE SCHEDULED | L23: 45323 | M23: https://nafdacng.sharepoint.com/sites/PMSLAGOS/Shared Documents/GDP (GOOD DISTRIBUTION PRATICE)/GSDP COMPANY FILES\EVERSHINE PHARMA NIG LTD | N23: =IF(M23="","",HYPERLINK(M23,B23)) -> EVERSHINE PHARMACEUTICAL NIG LTD
A24: 22 | B24: FRANKEY NIG.LTD | C24: 9, Victor Fagbami street,Iyana- Ipaja, Lagos . | D24: 08033012635 | E24: GDP | F24: 22/02/2023 | G24: High-Risk (C) | H24: 4th April 2023 | I24: YES | J24: CAPA Submited | K24: =IF(I24="YES","CAPA VERIFICATION SHOULD BE SCHEDULED",IF(I24="NO","REMINDER LETTER SHOULD BE SENT","")) -> CAPA VERIFICATION SHOULD BE SCHEDULED | L24: 45413 | M24: https://nafdacng.sharepoint.com/sites/PMSLAGOS/Shared Documents/GDP (GOOD DISTRIBUTION PRATICE)/GSDP COMPANY FILES/FRANKCY NIG LTD | N24: =IF(M24="","",HYPERLINK(M24,B24)) -> FRANKEY NIG.LTD
A25: 23 | B25: GOD IS GREAT PHARMACY | C25: 1,Kola Ogunwale, Off Iyana Ipaja Lagos | D25: 08058520035 | E25: GDP | F25: 23/02/2023 | G25: High-Risk (C) | H25: 4th April 2023 | I25: NO | J25: CAPA to be Submited | K25: =IF(I25="YES","CAPA VERIFICATION SHOULD BE SCHEDULED",IF(I25="NO","REMINDER LETTER SHOULD BE SENT","")) -> REMINDER LETTER SHOULD BE SENT | L25: 44774 | M25: https://nafdacng.sharepoint.com/sites/PMSLAGOS/Shared Documents/GDP (GOOD DISTRIBUTION PRATICE)/GSDP COMPANY FILES\GOD IS GREAT PHARMACY | N25: =IF(M25="","",HYPERLINK(M25,B25)) -> GOD IS GREAT PHARMACY
A26: 24 | B26: SOMEC UNITED PHARMACY | C26: 3,Adebayo Street Iyana Ipaja Lagos | D26: 07062791634 | E26: GDP | F26: 23/02/2023 | G26: Medium-Risk (B) | H26: 4th April 2023 | I26: NO | J26: CAPA to be Submited | K26: =IF(I26="YES","CAPA VERIFICATION SHOULD BE SCHEDULED",IF(I26="NO","REMINDER LETTER SHOULD BE SENT","")) -> REMINDER LETTER SHOULD BE SENT | L26: 45323 | M26: https://nafdacng.sharepoint.com/sites/PMSLAGOS/Shared Documents/GDP (GOOD DISTRIBUTION PRATICE)/GSDP COMPANY FILES/SKY PHARM | N26: =IF(M26="","",HYPERLINK(M26,B26)) -> SOMEC UNITED PHARMACY
A27: 25 | B27: UNITED ABC PHARMACEUTICAL | C27: 45/47,Ipaja Road, Iyana Ipaja, Lagos | D27: 08099887692 | E27: GDP | F27: 23/02/2023 | G27: Medium-Risk (B) | H27: 4th April 2023 | I27: NO | J27: CAPA to be Submited | K27: =IF(I27="YES","CAPA VERIFICATION SHOULD BE SCHEDULED",IF(I27="NO","REMINDER LETTER SHOULD BE SENT","")) -> REMINDER LETTER SHOULD BE SENT | L27: 45323 | M27: https://nafdacng.sharepoint.com/sites/PMSLAGOS/Shared Documents/GDP (GOOD DISTRIBUTION PRATICE)/GSDP COMPANY FILES\UNITED ABC PHARM | N27: =IF(M27="","",HYPERLINK(M27,B27)) -> UNITED ABC PHARMACEUTICAL
A28: 26 | B28: SA PHARMACY | C28: 1, Imope Compound, Ikotun, Lagos State | D28: 08033454283 | E28: GDP | F28: 24/02/2023 | G28: Medium-Risk (B) | H28: 4th April 2023 | I28: NO | J28: CAPA to be Submited | K28: =IF(I28="YES","CAPA VERIFICATION SHOULD BE SCHEDULED",IF(I28="NO","REMINDER LETTER SHOULD BE SENT","")) -> REMINDER LETTER SHOULD BE SENT | L28: 45323 | M28: https://nafdacng.sharepoint.com/sites/PMSLAGOS/Shared Documents/GDP (GOOD DISTRIBUTION PRATICE)/GSDP COMPANY FILES\SA PHARMACY | N28: =IF(M28="","",HYPERLINK(M28,B28)) -> SA PHARMACY
A29: 27 | B29: RIGHTMATE PHARMACY | C29: 3,Fatimo Street, Ikotun Lagos State | D29: 08063358238 | E29: GDP | F29: 24/02/2023 | G29: Medium-Risk (B) | H29: 4th April 2023 | I29: NO | J29: CAPA to be Submited | K29: =IF(I29="YES","CAPA VERIFICATION SHOULD BE SCHEDULED",IF(I29="NO","REMINDER LETTER SHOULD BE SENT","")) -> REMINDER LETTER SHOULD BE SENT | L29: 45323 | M29: https://nafdacng.sharepoint.com/sites/PMSLAGOS/Shared Documents/GDP (GOOD DISTRIBUTION PRATICE)/GSDP COMPANY FILES\RIGHTMARES PHARM LTD | N29: =IF(M29="","",HYPERLINK(M29,B29)) -> RIGHTMATE PHARMACY

Sheet MAR
A1: GDP INSPECTION CLASSIFICATION DATA BASE AS AT 2023
A2: S/N | B2: NAME OF MANUFACTURER | C2: LOCATION ADDRESS | D2: CONTACT | E2: TYPE OF LAST INSPECTION | F2: DATE OF LAST INSPECTION | G2: FINDINGS | H2: CAPA ISSUED DATE | I2: CAPA SUBMITTED | J2: CONCLUSION | K2: REMARKS | L2: EXPECTED DATE OF INSPECTION | M2: OMPANY FILE | N2: Column1 | O2: Column2
