Workbook

Sheet INSPECTED FACILITIES 2024
A1: GDP INSPECTION CLASSIFICATION DATABASE AS AT 2024
A2: S/N | B2: NAME OF MANUFACTURER | C2: LOCATION ADDRESS | D2: CONTACT | E2: TYPE OF LAST INSPECTION | F2: DATE OF LAST INSPECTION | G2: FINDINGS | H2: CAPA ISSUED DATE | I2: CAPA SUBMITTED | J2: CONCLUSION | K2: REMARKS | L2: EXPECTED DATE OF INSPECTION | M2: Column1 | N2: Column12 | O2: Column2
A3: 1 | B3: DI MAGGO PHARMACEUTICALS | C3: 1 Egbe Road Ikotun Lagos. | D3: Mr. Magnus Ekenyem,08037277196 | E3: GDP | F3: 45362 | G3: Medium Risk | H3: 28/05/24 | I3: NO | J3: CAPA to be submitted | K3: =IF(I3="YES","CAPA VERIFICATION SHOULD BE SCHEDULED",IF(I3="NO","REMINDER LETTER SHOULD BE SENT","")) -> REMINDER LETTER SHOULD BE SENT | L3: 45717 | M3: https://nafdacng.sharepoint.com/sites/PMSLAGOS/Shared Documents/GDP (GOOD DISTRIBUTION PRATICE)/GSDP COMPANY FILES\DI-MAGGIO | N3: https://nafdacng.sharepoint.com/sites/PMSLAGOS/Shared Documents/GSDP (GOOD STORAGE AND DISTRIBUTION PRACTICE)/GSDP COMPANY FILES\DI-MAGGIO | O3: =IF(M3="","",HYPERLINK(M3,B3)) -> DI MAGGO PHARMACEUTICALS
A4: 2 | B4: SONYDON AND SONS PHARM NIG. LTD | C4: 126, Egbe Road Beside Nepa B/Stop Ejigbo Lagos State. | D4: Mr. Sunday Igwe | E4: GDP | F4: 45362 | G4: Medium Risk | H4: 28/05/25 | I4: NO | J4: CAPA to be submitted | K4: =IF(I4="YES","CAPA VERIFICATION SHOULD BE SCHEDULED",IF(I4="NO","REMINDER LETTER SHOULD BE SENT","")) -> REMINDER LETTER SHOULD BE SENT | L4: 45717 | M4: https://nafdacng.sharepoint.com/sites/PMSLAGOS/Shared Documents/GDP (GOOD DISTRIBUTION PRATICE)/GSDP COMPANY FILES\SONYDON & SON | N4: https://nafdacng.sharepoint.com/sites/PMSLAGOS/Shared Documents/GSDP (GOOD STORAGE AND DISTRIBUTION PRACTICE)/GSDP COMPANY FILES\SONYDON & SON | O4: =IF(M4="","",HYPERLINK(M4,B4)) -> SONYDON AND SONS PHARM NIG. LTD
A5: 3 | B5: SOLOCHUCKS PHARMACEUTICALS | C5: 8 Alli Dogo Street, Badia, Ijora Lagos State. | D5: Pharm. Okolie Adolphus,07063390356 | E5: GDP | F5: 45363 | G5: Medium Risk | H5: 28/05/26 | I5: NO | J5: CAPA to be submitted | K5: =IF(I6="YES","CAPA VERIFICATION SHOULD BE SCHEDULED",IF(I6="NO","REMINDER LETTER SHOULD BE SENT","")) -> REMINDER LETTER SHOULD BE SENT | L5: 45717 | M5: https://nafdacng.sharepoint.com/sites/PMSLAGOS/Shared Documents/GDP (GOOD DISTRIBUTION PRATICE)/GSDP COMPANY FILES\SOLOCHUKS PHARM | N5: https://nafdacng.sharepoint.com/sites/PMSLAGOS/Shared Documents/GSDP (GOOD STORAGE AND DISTRIBUTION PRACTICE)/GSDP COMPANY FILES\SOLOCHUKS PHARM | O5: =IF(M5="","",HYPERLINK(M5,B5)) -> SOLOCHUCKS PHARMACEUTICALS
A6: 4 | B6: SLOCHARS PHARMACEUTICALS | C6: 49 Coker Road Orile Coker Lagos State. | D6: Mr. Damilare Dawodu,08033359934 | E6: GDP | F6: 45363 | G6: Medium Risk | H6: 20/3/24 | I6: NO | J6: CAPA to be submitted | K6: =IF(#REF!="YES","CAPA VERIFICATION SHOULD BE SCHEDULED",IF(#REF!="NO","REMINDER LETTER SHOULD BE SENT","")) -> #REF! | L6: 45717 | M6: https://nafdacng.sharepoint.com/sites/PMSLAGOS/Shared Documents/GDP (GOOD DISTRIBUTION PRATICE)/GSDP COMPANY FILES\SLOCHARS PHARM | N6: https://nafdacng.sharepoint.com/sites/PMSLAGOS/Shared Documents/GSDP (GOOD STORAGE AND DISTRIBUTION PRACTICE)/GSDP COMPANY FILES\SLOCHARS PHARM | O6: =IF(M6="","",HYPERLINK(M6,B6)) -> SLOCHARS PHARMACEUTICALS
A7: 5 | B7: GRACEJOHNSON LIMITED | C7: 448, OLD OJO ROAD, SATELLITE TOWN LAGOS | D7: Offia Justina O.,08094579401 | E7: GDP | F7: 45364 | G7: Medium Risk | H7: 28/05/24 | I7: NO | J7: CAPA to be submitted | K7: =IF(I7="YES","CAPA VERIFICATION SHOULD BE SCHEDULED",IF(I7="NO","REMINDER LETTER SHOULD BE SENT","")) -> REMINDER LETTER SHOULD BE SENT | L7: 45717 | M7: https://nafdacng.sharepoint.com/sites/PMSLAGOS/Shared Documents/GDP (GOOD DISTRIBUTION PRATICE)/GSDP COMPANY FILES\GRACE JOHNSON LTD | N7: https://nafdacng.sharepoint.com/sites/PMSLAGOS/Shared Documents/GSDP (GOOD STORAGE AND DISTRIBUTION PRACTICE)/GSDP COMPANY FILES\GRACE JOHNSON LTD | O7: =IF(M7="","",HYPERLINK(M7,B7)) -> GRACEJOHNSON LIMITED
A8: 6 | B8: EL-NOSCO PHARMACY | C8: 62, EKORO ROAD, ABULE-EGBA LAGOS | D8: Pharm Ifeoma Nkemdilim,07031553339 | E8: GDP | F8: 45365 | G8: Medium Risk | H8: 28/05/24 | I8: NO | J8: CAPA to be submitted | K8: =IF(I8="YES","CAPA VERIFICATION SHOULD BE SCHEDULED",IF(I8="NO","REMINDER LETTER SHOULD BE SENT","")) -> REMINDER LETTER SHOULD BE SENT | L8: 45717 | M8: https://nafdacng.sharepoint.com/sites/PMSLAGOS/Shared Documents/GDP (GOOD DISTRIBUTION PRATICE)/GSDP COMPANY FILES\EL-NOSCO PHARM | N8: https://nafdacng.sharepoint.com/sites/PMSLAGOS/Shared Documents/GSDP (GOOD STORAGE AND DISTRIBUTION PRACTICE)/GSDP COMPANY FILES\EL-NOSCO PHARM | O8: =IF(M8="","",HYPERLINK(M8,B8)) -> EL-NOSCO PHARMACY
A9: 7 | B9: S. UMUNNA PHARMACEUTICALS | C9: 26, MEIRAN RD., MEIRAN LAGOS | D9: Pharm Agubor Stantely,08062585880 | E9: GDP | F9: 45365 | G9: Medium Risk | H9: 28/05/24 | I9: NO | J9: CAPA to be submitted | K9: =IF(I9="YES","CAPA VERIFICATION SHOULD BE SCHEDULED",IF(I9="NO","REMINDER LETTER SHOULD BE SENT","")) -> REMINDER LETTER SHOULD BE SENT | L9: 45717 | M9: https://nafdacng.sharepoint.com/sites/PMSLAGOS/Shared Documents/GDP (GOOD DISTRIBUTION PRATICE)/GSDP COMPANY FILES\S. UMUNNA PHARM | N9: https://nafdacng.sharepoint.com/sites/PMSLAGOS/Shared Documents/GSDP (GOOD STORAGE AND DISTRIBUTION PRACTICE)/GSDP COMPANY FILES\S. UMUNNA PHARM | O9: =IF(M9="","",HYPERLINK(M9,B9)) -> S. UMUNNA PHARMACEUTICALS
A10: 8 | B10: TONIVIC PHARMACY | C10: 18, DEMURIN STREET, KETU LAGOS | D10: Anita Chiwendu,09083549449 | E10: GDP | F10: 45362 | G10: Medium Risk | H10: 28/3/24 | I10: NO | J10: CAPA to be submitted | K10: =IF(I10="YES","CAPA VERIFICATION SHOULD BE SCHEDULED",IF(I10="NO","REMINDER LETTER SHOULD BE SENT","")) -> REMINDER LETTER SHOULD BE SENT | L10: 45717 | M10: https://nafdacng.sharepoint.com/sites/PMSLAGOS/Shared Documents/GDP (GOOD DISTRIBUTION PRATICE)/GSDP COMPANY FILES\TONIVIC | N10: https://nafdacng.sharepoint.com/sites/PMSLAGOS/Shared Documents/GSDP (GOOD STORAGE AND DISTRIBUTION PRACTICE)/GSDP COMPANY FILES\TONIVIC | O10: =IF(M10="","",HYPERLINK(M10,B10)) -> TONIVIC PHARMACY
A11: 9 | B11: JOEBIZ PHARMACY | C11: 26, Odugate Street, Ikorudu road, Lagos. | D11: Pharm. Edeh Gift,'07034630536 | E11: GDP | F11: 45369 | G11: Medium Risk | H11: 28/05/24 | I11: NO | J11: CAPA to be submitted | K11: =IF(I11="YES","CAPA VERIFICATION SHOULD BE SCHEDULED",IF(I11="NO","REMINDER LETTER SHOULD BE SENT","")) -> REMINDER LETTER SHOULD BE SENT | L11: 45717 | M11: https://nafdacng.sharepoint.com/sites/PMSLAGOS/Shared Documents/GDP (GOOD DISTRIBUTION PRATICE)/GSDP COMPANY FILES\JOEBIZ PHARMACY | N11: https://nafdacng.sharepoint.com/sites/PMSLAGOS/Shared Documents/GSDP (GOOD STORAGE AND DISTRIBUTION PRACTICE)/GSDP COMPANY FILES\JOEBIZ PHARMACY | O11: =IF(M11="","",HYPERLINK(M11,B11)) -> JOEBIZ PHARMACY
A12: 10 | B12: GOODCARE PHARMACEUTICALS LTD (CAPA) | C12: 111 ISAWO ROAD, AGRIC IKORODU LAGOS | D12: 8064266572 | E12: CAPA | F12: 45369 | G12: Medium Risk | H12: 28/05/24 | I12: YES | J12: CAPA Submitted | K12: =IF(I12="YES","CAPA VERIFICATION SHOULD BE SCHEDULED",IF(I12="NO","REMINDER LETTER SHOULD BE SENT","")) -> CAPA VERIFICATION SHOULD BE SCHEDULED | L12: 45717 | M12: https://nafdacng.sharepoint.com/sites/PMSLAGOS/Shared Documents/GDP (GOOD DISTRIBUTION PRATICE)/GSDP COMPANY FILES\GOODCARE | N12: https://nafdacng.sharepoint.com/sites/PMSLAGOS/Shared Documents/GSDP (GOOD STORAGE AND DISTRIBUTION PRACTICE)/GSDP COMPANY FILES\GOODCARE | O12: =IF(M12="","",HYPERLINK(M12,B12)) -> GOODCARE PHARMACEUTICALS LTD (CAPA)
A13: 11 | B13: RALPHONES PHARMACEUTICAL (CAPA) | C13: 1 Ralphone Lane,Irawo ajegunle,ikorodu,Lagos | D13: 8037588238 | E13: CAPA | F13: 45369 | G13: Medium Risk | H13: 28/5/2024 | I13: NO | J13: CAPA Submitted | K13: =IF(I13="YES","CAPA VERIFICATION SHOULD BE SCHEDULED",IF(I13="NO","REMINDER LETTER SHOULD BE SENT","")) -> REMINDER LETTER SHOULD BE SENT | L13: 45717 | M13: https://nafdacng.sharepoint.com/sites/PMSLAGOS/Shared Documents/GDP (GOOD DISTRIBUTION PRATICE)/GSDP COMPANY FILES\RALPHONES PHARMACEUTICAL LTD | N13: https://nafdacng.sharepoint.com/sites/PMSLAGOS/Shared Documents/GSDP (GOOD STORAGE AND DISTRIBUTION PRACTICE)/GSDP COMPANY FILES\RALPHONES PHARMACEUTICAL LTD | O13: =IF(M13="","",HYPERLINK(M13,B13)) -> RALPHONES PHARMACEUTICAL (CAPA)
A14: 12 | B14: ROYAL PRIESTHOOD LAB LTD. | C14: 3, ERULE OLABO STR., ODONLA ODONGUNYAN, IKORODU LAGOS | D14: Olufunsho Okunewo,08033512909 | E14: GDP | F14: 45369 | G14: Medium Risk | H14: 28/05/24 | I14: NO | J14: CAPA to be submitted | K14: =IF(I14="YES","CAPA VERIFICATION SHOULD BE SCHEDULED",IF(I14="NO","REMINDER LETTER SHOULD BE SENT","")) -> REMINDER LETTER SHOULD BE SENT | L14: 45717 | M14: https://nafdacng.sharepoint.com/:f:/s/PMSLAGOS/IgA0Jl4IY1vDR7iQOT0MDq3TAUynKViboBPDh_ABRHjR7sQ?e=A8QmxD | N14: https://nafdacng.sharepoint.com/:f:/s/PMSLAGOS/IgA0Jl4IY1vDR7iQOT0MDq3TAUynKViboBPDh_ABRHjR7sQ?e=A8QmxD | O14: =IF(M14="","",HYPERLINK(M14,B14)) -> ROYAL PRIESTHOOD LAB LTD.
A15: 13 | B15: MIVERO PHARM LTD (CAPA) | C15: 244,AGEGE MOTOR ROAD, MUSHIN LAGOS | D15: 8161396721 | E15: CAPA | F15: 45370 | G15: Low Risk | H15: 28/05/24 | I15: YES | J15: CAPA Submitted | K15: =IF(I15="YES","CAPA VERIFICATION SHOULD BE SCHEDULED",IF(I15="NO","REMINDER LETTER SHOULD BE SENT","")) -> CAPA VERIFICATION SHOULD BE SCHEDULED | L15: 46082 | M15: https://nafdacng.sharepoint.com/sites/PMSLAGOS/Shared Documents/GDP (GOOD DISTRIBUTION PRATICE)/GSDP COMPANY FILES\MIVERO PHARM | N15: https://nafdacng.sharepoint.com/sites/PMSLAGOS/Shared Documents/GSDP (GOOD STORAGE AND DISTRIBUTION PRACTICE)/GSDP COMPANY FILES\MIVERO PHARM | O15: =IF(M15="","",HYPERLINK(M15,B15)) -> MIVERO PHARM LTD (CAPA)
A16: 14 | B16: SEC PHARMACY | C16: 135, ITIRE-IJESHA ROAD, SURULERE LAGOS | D16: Pharm Kehinde,'08034760477 | E16: GDP | F16: 45370 | G16: Medium Risk | H16: 28/05/24 | I16: NO | J16: CAPA to be submitted | K16: =IF(I16="YES","CAPA VERIFICATION SHOULD BE SCHEDULED",IF(I16="NO","REMINDER LETTER SHOULD BE SENT","")) -> REMINDER LETTER SHOULD BE SENT | L16: 45717 | M16: https://nafdacng.sharepoint.com/sites/PMSLAGOS/Shared Documents/GDP (GOOD DISTRIBUTION PRATICE)/GSDP COMPANY FILES\SEC PHARMACEUTICAL | N16: https://nafdacng.sharepoint.com/sites/PMSLAGOS/Shared Documents/GSDP (GOOD STORAGE AND DISTRIBUTION PRACTICE)/GSDP COMPANY FILES\SEC PHARMACEUTICAL | O16: =IF(M16="","",HYPERLINK(M16,B16)) -> SEC PHARMACY
A17: 15 | B17: FEDESON PHARMACY | C17: 147, IJESHA RD., IJESHA LAGOS | D17: Pharm Ifeyinwa Morah,09053039212 | E17: GDP | F17: 45370 | G17: Low Risk | H17: 28/05/24 | I17: YES | J17: CAPA Submitted | K17: =IF(I17="YES","CAPA VERIFICATION SHOULD BE SCHEDULED",IF(I17="NO","REMINDER LETTER SHOULD BE SENT","")) -> CAPA VERIFICATION SHOULD BE SCHEDULED | L17: 46082 | M17: https://nafdacng.sharepoint.com/sites/PMSLAGOS/Shared Documents/GDP (GOOD DISTRIBUTION PRATICE)/GSDP COMPANY FILES\FEDESON PHARM | N17: https://nafdacng.sharepoint.com/sites/PMSLAGOS/Shared Documents/GSDP (GOOD STORAGE AND DISTRIBUTION PRACTICE)/GSDP COMPANY FILES\FEDESON PHARM | O17: =IF(M17="","",HYPERLINK(M17,B17)) -> FEDESON PHARMACY
A18: 16 | B18: ALATRA PHARMACEUTICALS (CAPA) | C18: 7,0RIYOMI STREET,OFF KODESOH STREET,IKEJA | D18: Nriagu Pius,08023545633 | E18: CAPA | F18: 45427 | G18: Low Risk | H18: 29/05/24 | I18: YES | J18: CAPA Submitted | K18: =IF(I18="YES","CAPA VERIFICATION SHOULD BE SCHEDULED",IF(I18="NO","REMINDER LETTER SHOULD BE SENT","")) -> CAPA VERIFICATION SHOULD BE SCHEDULED | L18: 46143 | M18: https://nafdacng.sharepoint.com/:f:/s/PMSLAGOS/IgDEREDujMUYRZhkrewJEPixAbYbfZ1LbL8qianGZ-plcdU?e=WqHder | N18: https://nafdacng.sharepoint.com/:f:/s/PMSLAGOS/IgDEREDujMUYRZhkrewJEPixAbYbfZ1LbL8qianGZ-plcdU?e=WqHder | O18: =IF(M18="","",HYPERLINK(M18,B18)) -> ALATRA PHARMACEUTICALS (CAPA)
A19: 17 | B19: EZE-SUNICH PHARMACY | C19: 207, SHIBIRI ROAD, SHIBIRI, EKUNPA | D19: Amara Okoye'08063788228 | E19: GDP | F19: 45371 | G19: Medium Risk | H19: 28/05/24 | I19: NO | J19: CAPA to be submitted | K19: =IF(I19="YES","CAPA VERIFICATION SHOULD BE SCHEDULED",IF(I19="NO","REMINDER LETTER SHOULD BE SENT","")) -> REMINDER LETTER SHOULD BE SENT | L19: 45717 | M19: https://nafdacng.sharepoint.com/sites/PMSLAGOS/Shared Documents/GDP (GOOD DISTRIBUTION PRATICE)/GSDP COMPANY FILES\EZE-SUNICH PHARM | N19: https://nafdacng.sharepoint.com/sites/PMSLAGOS/Shared Documents/GSDP (GOOD STORAGE AND DISTRIBUTION PRACTICE)/GSDP COMPANY FILES\EZE-SUNICH PHARM | O19: =IF(M19="","",HYPERLINK(M19,B19)) -> EZE-SUNICH PHARMACY
A20: 18 | B20: JOMEC PHARM CO.LTD | C20: 865 SURULERE STREET DOPEMU LAGOS | D20: Mr. Ifeanyi Okafor,8033453140 | E20: GDP | F20: 45418 | G20: Medium Risk | H20: 21/5/24 | I20: NO | J20: CAPA to be submitted | K20: =IF(I20="YES","CAPA VERIFICATION SHOULD BE SCHEDULED",IF(I20="NO","REMINDER LETTER SHOULD BE SENT","")) -> REMINDER LETTER SHOULD BE SENT | L20: 45778 | O20: =IF(M20="","",HYPERLINK(M20,B20))
A21: 19 | B21: CHUPET PHARMACEUTICAL | C21: 18/20 OGUNGBESAN STREET COKER SURULERE LAGOS | D21: Pharm. Ngozi Ata,08034028483 | E21: GDP | F21: 45419 | G21: Low Risk | H21: 45570 | I21: YES | J21: CAPA submitted | K21: =IF(I21="YES","CAPA VERIFICATION SHOULD BE SCHEDULED",IF(I21="NO","REMINDER LETTER SHOULD BE SENT","")) -> CAPA VERIFICATION SHOULD BE SCHEDULED | L21: 46143 | M21: https://nafdacng.sharepoint.com/sites/PMSLAGOS/Shared Documents/GDP (GOOD DISTRIBUTION PRATICE)/GSDP COMPANY FILES\CHUPET PHARMACEUTICALS | N21: https://nafdacng.sharepoint.com/sites/PMSLAGOS/Shared Documents/GSDP (GOOD STORAGE AND DISTRIBUTION PRACTICE)/GSDP COMPANY FILES\CHUPET PHARMACEUTICALS | O21: =IF(M21="","",HYPERLINK(M21,B21)) -> CHUPET PHARMACEUTICAL
A22: 20 | B22: SPINE PRODUCT LTD | C22: 24 AYODELE OKEOWO STREET SOLUYI GBAGADA LAGOS | D22: Pharm. Dominica Chiamaka Emezirinwanne,08030998612 | E22: GDP | F22: 45420 | G22: Medium Risk | H22: 29/5/24 | I22: NO | J22: CAPA to be submitted | K22: =IF(I22="YES","CAPA VERIFICATION SHOULD BE SCHEDULED",IF(I22="NO","REMINDER LETTER SHOULD BE SENT","")) -> REMINDER LETTER SHOULD BE SENT | L22: 45778 | M22: https://nafdacng.sharepoint.com/sites/PMSLAGOS/Shared Documents/GDP (GOOD DISTRIBUTION PRATICE)/GSDP COMPANY FILES\SPINE PRODUCT LTD | N22: https://nafdacng.sharepoint.com/sites/PMSLAGOS/Shared Documents/GSDP (GOOD STORAGE AND DISTRIBUTION PRACTICE)/GSDP COMPANY FILES\SPINE PRODUCT LTD | O22: =IF(M22="","",HYPERLINK(M22,B22)) -> SPINE PRODUCT LTD
A23: 21 | B23: HOLY TRINTY PHARMACY | C23: 12/19 ABULE ADALOKO ROAD ABULE-ERA OJO LAGOS | D23: Pharm Tina Agbada | E23: GDP | F23: 45421 | G23: Medium Risk | H23: 29/11/24 | I23: NO | J23: CAPA to be submitted | K23: =IF(I23="YES","CAPA VERIFICATION SHOULD BE SCHEDULED",IF(I23="NO","REMINDER LETTER SHOULD BE SENT","")) -> REMINDER LETTER SHOULD BE SENT | L23: 45778 | M23: https://nafdacng.sharepoint.com/sites/PMSLAGOS/Shared Documents/GDP (GOOD DISTRIBUTION PRATICE)/GSDP COMPANY FILES\HOLY TRINTY PHARM | N23: https://nafdacng.sharepoint.com/sites/PMSLAGOS/Shared Documents/GSDP (GOOD STORAGE AND DISTRIBUTION PRACTICE)/GSDP COMPANY FILES\HOLY TRINTY PHARM | O23: =IF(M23="","",HYPERLINK(M23,B23)) -> HOLY TRINTY PHARMACY
A24: 22 | B24: J.O SARCHMORE PHARMACY | C24: 118 OLD LAGOS ROAD DEPPER LIFE BIBLE CHURCH AJARA BADAGRY LAGOS | D24: Orejekwe Joseph,08146180819 | E24: GDP | F24: 45421 | G24: Medium Risk | H24: 21/5/24 | I24: NO | J24: CAPA to be submitted | K24: =IF(I24="YES","CAPA VERIFICATION SHOULD BE SCHEDULED",IF(I24="NO","REMINDER LETTER SHOULD BE SENT","")) -> REMINDER LETTER SHOULD BE SENT | L24: 45778 | M24: https://nafdacng.sharepoint.com/sites/PMSLAGOS/Shared Documents/GDP (GOOD DISTRIBUTION PRATICE)/GSDP COMPANY FILES\J.O SARCHMORE PHARM | N24: https://nafdacng.sharepoint.com/sites/PMSLAGOS/Shared Documents/GSDP (GOOD STORAGE AND DISTRIBUTION PRACTICE)/GSDP COMPANY FILES\J.O SARCHMORE PHARM | O24: =IF(M24="","",HYPERLINK(M24,B24)) -> J.O SARCHMORE PHARMACY
A25: 23 | B25: SUNLIGHT LINKS PHARMACY LTD | C25: 135 BORNO WAY EBUTA-METTA LAGOS | D25: Pharm. Olajide Omilana,07036693454 | E25: GDP | F25: 45425 | G25: Medium Risk | H25: 29/5/24 | I25: NO | J25: CAPA to be submitted | K25: =IF(I25="YES","CAPA VERIFICATION SHOULD BE SCHEDULED",IF(I25="NO","REMINDER LETTER SHOULD BE SENT","")) -> REMINDER LETTER SHOULD BE SENT | L25: 45778 | M25: https://nafdacng.sharepoint.com/sites/PMSLAGOS/Shared Documents/GDP (GOOD DISTRIBUTION PRATICE)/GSDP COMPANY FILES\SUNLIGHT LINK PHARMACY | N25: https://nafdacng.sharepoint.com/sites/PMSLAGOS/Shared Documents/GSDP (GOOD STORAGE AND DISTRIBUTION PRACTICE)/GSDP COMPANY FILES\SUNLIGHT LINK PHARMACY | O25: =IF(M25="","",HYPERLINK(M25,B25)) -> SUNLIGHT LINKS PHARMACY LTD
A26: 24 | B26: AL-TINEZ PHARMACEUTICALS | C26: 18 JONES STREET EBUTE-METTA LAGOS | D26: Pharm. Eze Gift Laz,09033777367 | E26: GDP | F26: 45425 | G26: Medium Risk | H26: 29/05/24 | I26: NO | J26: CAPA to be submitted | K26: =IF(I26="YES","CAPA VERIFICATION SHOULD BE SCHEDULED",IF(I26="NO","REMINDER LETTER SHOULD BE SENT","")) -> REMINDER LETTER SHOULD BE SENT | L26: 45778 | M26: https://nafdacng.sharepoint.com/sites/PMSLAGOS/Shared Documents/GDP (GOOD DISTRIBUTION PRATICE)/GSDP COMPANY FILES\AL-TINEZ PHARMA. LTD | N26: https://nafdacng.sharepoint.com/sites/PMSLAGOS/Shared Documents/GSDP (GOOD STORAGE AND DISTRIBUTION PRACTICE)/GSDP COMPANY FILES\AL-TINEZ PHARMA. LTD | O26: =IF(M26="","",HYPERLINK(M26,B26)) -> AL-TINEZ PHARMACEUTICALS
A27: 25 | B27: ROCA PHARMACEUTICAL | C27: 324 IJU-ISHAGA ROAD IJU LAGOS | D27: Pharm. Onyekachi Udeogu,08038569395 | E27: GDP | F27: 45426 | G27: Medium Risk | I27: NO | J27: CAPA to be submitted | K27: =IF(I27="YES","CAPA VERIFICATION SHOULD BE SCHEDULED",IF(I27="NO","REMINDER LETTER SHOULD BE SENT","")) -> REMINDER LETTER SHOULD BE SENT | L27: 45778 | O27: =IF(M27="","",HYPERLINK(M27,B27))
A28: 26 | B28: EMBASSY PHARMACEUTICALS (CAPA) | C28: 41,Ademola Street,Off Obafemi Awolowo Road,Ikoyi,Lagos state | D28: 8029702822 | E28: CAPA | F28: 45428 | G28: Low Risk | I28: YES | J28: N/A | K28: CONTINOUS MONITORING TO ENSURE COMPLIANCE | L28: 46143 | M28: https://nafdacng.sharepoint.com/sites/PMSLAGOS/Shared Documents/GDP (GOOD DISTRIBUTION PRATICE)/GSDP COMPANY FILES\EMBASSY PHARM | N28: https://nafdacng.sharepoint.com/sites/PMSLAGOS/Shared Documents/GSDP (GOOD STORAGE AND DISTRIBUTION PRACTICE)/GSDP COMPANY FILES\EMBASSY PHARM | O28: =IF(M28="","",HYPERLINK(M28,B28)) -> EMBASSY PHARMACEUTICALS (CAPA)
A29: 27 | B29: HILLY PHARMACY | C29: 2 0DO OBALENDE LAGSO STATE | D29: Ogwe Chukwuemeka,08065263178 | E29: GDP | F29: 45428 | G29: Medium Risk | I29: YES | J29: CAPA to be submitted | K29: =IF(I29="YES","CAPA VERIFICATION SHOULD BE SCHEDULED",IF(I29="NO","REMINDER LETTER SHOULD BE SENT","")) -> CAPA VERIFICATION SHOULD BE SCHEDULED | L29: 45778 | M29: https://nafdacng.sharepoint.com/sites/PMSLAGOS/Shared Documents/GDP (GOOD DISTRIBUTION PRATICE)/GSDP COMPANY FILES\HILLY PHARMACY | N29: https://nafdacng.sharepoint.com/sites/PMSLAGOS/Shared Documents/GSDP (GOOD STORAGE AND DISTRIBUTION PRACTICE)/GSDP COMPANY FILES\HILLY PHARMACY | O29: =IF(M29="","",HYPERLINK(M29,B29)) -> HILLY PHARMACY
A30: 28 | B30: ZADIP PHARMA NIG. LTD | C30: 68B, COKER ROAD, ILUPEJU | D30: Odugbesan Esther; 08023279017 | E30: GDP | F30: 45509 | G30: Medium Risk | H30: 45481 | I30: NO | J30: CAPA to be submitted | K30: =IF(I30="YES","CAPA VERIFICATION SHOULD BE SCHEDULED",IF(I30="NO","REMINDER LETTER SHOULD BE SENT","")) -> REMINDER LETTER SHOULD BE SENT | L30: 45870 | M30: https://nafdacng.sharepoint.com/sites/PMSLAGOS/Shared Documents/GDP (GOOD DISTRIBUTION PRATICE)/GSDP COMPANY FILES\ZADIP PHARMA | N30: https://nafdacng.sharepoint.com/sites/PMSLAGOS/Shared Documents/GSDP (GOOD STORAGE AND DISTRIBUTION PRACTICE)/GSDP COMPANY FILES\ZADIP PHARMA | O30: =IF(M30="","",HYPERLINK(M30,B30)) -> ZADIP PHARMA NIG. LTD
A31: 29 | B31: UNIQUE PHARM LTD | C31: 3, BLIND CENTRE ROAD, OSHODI-MUSHIN | D31: Pharm. Titus Udoh 08034022402 | E31: GDP | F31: 45511 | G31: Medium Risk | H31: 15/08/24 | I31: YES | J31: CAPA submitted | K31: =IF(I31="YES","CAPA VERIFICATION SHOULD BE SCHEDULED",IF(I31="NO","REMINDER LETTER SHOULD BE SENT","")) -> CAPA VERIFICATION SHOULD BE SCHEDULED | L31: 45597 | M31: https://nafdacng.sharepoint.com/sites/PMSLAGOS/Shared Documents/GDP (GOOD DISTRIBUTION PRATICE)/GSDP COMPANY FILES\UNIQUE PHARMACEUTICALS | N31: https://nafdacng.sharepoint.com/sites/PMSLAGOS/Shared Documents/GSDP (GOOD STORAGE AND DISTRIBUTION PRACTICE)/GSDP COMPANY FILES\UNIQUE PHARMACEUTICALS | O31: =IF(M31="","",HYPERLINK(M31,B31)) -> UNIQUE PHARM LTD
A32: 30 | B32: GENERICS & SPECIALITIES LTD | C32: 9, Dave Anazodo street, Behind Eleganza Company, Ajao Estate, Isolo. | D32: Pharm. Cyril Odidika 08033344839 | E32: GDP | F32: 45512 | G32: Medium Risk | H32: 27/08/24 | I32: YES | J32: CAPA Submitted | K32: =IF(I32="YES","CAPA VERIFICATION SHOULD BE SCHEDULED",IF(I32="NO","REMINDER LETTER SHOULD BE SENT","")) -> CAPA VERIFICATION SHOULD BE SCHEDULED | L32: DONE | M32: https://nafdacng.sharepoint.com/sites/PMSLAGOS/Shared Documents/GDP (GOOD DISTRIBUTION PRATICE)/GSDP COMPANY FILES\GENERICS & SPECIALITIES | N32: https://nafdacng.sharepoint.com/sites/PMSLAGOS/Shared Documents/GSDP (GOOD STORAGE AND DISTRIBUTION PRACTICE)/GSDP COMPANY FILES\UNIQUE PHARMACEUTICALS | O32: =IF(M32="","",HYPERLINK(M32,B32)) -> GENERICS & SPECIALITIES LTD
A33: 31 | B33: INTERPHARM GMBH | C33: 11A, John Olugbo Street, Ikeja, Lagos | D33: 8033329209 | E33: GDP | F33: 45513 | G33: Medium Risk | H33: NO CAPA | I33: NO | J33: CAPA to be submitted | K33: =IF(I33="YES","CAPA VERIFICATION SHOULD BE SCHEDULED",IF(I33="NO","REMINDER LETTER SHOULD BE SENT","")) -> REMINDER LETTER SHOULD BE SENT | L33: 45870 | M33: https://nafdacng.sharepoint.com/sites/PMSLAGOS/Shared Documents/GDP (GOOD DISTRIBUTION PRATICE)/GSDP COMPANY FILES\INTERPHARM GMBH | N33: https://nafdacng.sharepoint.com/sites/PMSLAGOS/Shared Documents/GSDP (GOOD STORAGE AND DISTRIBUTION PRACTICE)/GSDP COMPANY FILES\INTERPHARM GMBH | O33: =IF(M33="","",HYPERLINK(M33,B33)) -> INTERPHARM GMBH
A34: 32 | B34: AWARD GLOBAL COMPANY LTD (CAPA) | C34: 13, Olawole Dawodu street, Gbagada | D34: Pharm Abel Okechukwu 08065139057 | E34: CAPA | F34: 45516 | G34: Medium Risk | H34: 15/0824 | I34: YES | J34: CAPA submitted | K34: =IF(I34="YES","CAPA VERIFICATION SHOULD BE SCHEDULED",IF(I34="NO","REMINDER LETTER SHOULD BE SENT","")) -> CAPA VERIFICATION SHOULD BE SCHEDULED | L34: DONE | M34: https://nafdacng.sharepoint.com/sites/PMSLAGOS/Shared Documents/GDP (GOOD DISTRIBUTION PRATICE)/GSDP COMPANY FILES\AWARD GLOBAL | N34: https://nafdacng.sharepoint.com/sites/PMSLAGOS/Shared Documents/GSDP (GOOD STORAGE AND DISTRIBUTION PRACTICE)/GSDP COMPANY FILES\AWARD GLOBAL | O34: =IF(M34="","",HYPERLINK(M34,B34)) -> AWARD GLOBAL COMPANY LTD (CAPA)
A35: 33 | B35: MARCSON HEALTHCARE | C35: 29, Agric Road, Cele Bus-stop, isawo, Ikorodu. | D35: Pharm. Femi Abolarin 08037149817 | E35: GDP | F35: 45517 | G35: Medium Risk | H35: 20/08/24 | I35: YES | J35: CAPA submitted | K35: =IF(I35="YES","CAPA VERIFICATION SHOULD BE SCHEDULED",IF(I35="NO","REMINDER LETTER SHOULD BE SENT","")) -> CAPA VERIFICATION SHOULD BE SCHEDULED | L35: 45954 | M35: https://nafdacng.sharepoint.com/sites/PMSLAGOS/Shared Documents/GDP (GOOD DISTRIBUTION PRATICE)/GSDP COMPANY FILES\MARCSON HEALTHCARE | N35: https://nafdacng.sharepoint.com/sites/PMSLAGOS/Shared Documents/GSDP (GOOD STORAGE AND DISTRIBUTION PRACTICE)/GSDP COMPANY FILES\MARCSON HEALTHCARE | O35: =IF(M35="","",HYPERLINK(M35,B35)) -> MARCSON HEALTHCARE
A36: 34 | B36: PHARMAMAX NIGERIA LTD | C36: 7/9 Sawyer Crescent, Phase 1, Gbagada | D36: Pharm Okoye Martha 07036263207 | E36: GDP | F36: 45518 | G36: Medium Risk | H36: 15/08/24 | I36: NO | J36: CAPA to be submitted | K36: =IF(I36="YES","CAPA VERIFICATION SHOULD BE SCHEDULED",IF(I36="NO","REMINDER LETTER SHOULD BE SENT","")) -> REMINDER LETTER SHOULD BE SENT | L36: 45894 | M36: https://nafdacng.sharepoint.com/sites/PMSLAGOS/Shared Documents/GDP (GOOD DISTRIBUTION PRATICE)/GSDP COMPANY FILES/PHARMAMAX NIG. LTD | N36: https://nafdacng.sharepoint.com/sites/PMSLAGOS/Shared Documents/GSDP (GOOD STORAGE AND DISTRIBUTION PRACTICE)/GSDP COMPANY FILES/PHARMAMAX NIG. LTD | O36: =IF(M36="","",HYPERLINK(M36,B36)) -> PHARMAMAX NIGERIA LTD
A37: 35 | B37: INTERPHARMA INDUSTRIES LTD | C37: 28/30 Salvation Road, Opebi, Ikeja | D37: Pharm Adeyinka Benson | E37: GDP | F37: 45520 | G37: Medium Risk | H37: 16/08/24 | I37: NO | J37: CAPA to be submitted | K37: =IF(I37="YES","CAPA VERIFICATION SHOULD BE SCHEDULED",IF(I37="NO","REMINDER LETTER SHOULD BE SENT","")) -> REMINDER LETTER SHOULD BE SENT | L37: 45894 | M37: https://nafdacng.sharepoint.com/sites/PMSLAGOS/Shared Documents/GDP (GOOD DISTRIBUTION PRATICE)/GSDP COMPANY FILES/INTERPHARM GMBH | N37: https://nafdacng.sharepoint.com/sites/PMSLAGOS/Shared Documents/GSDP (GOOD STORAGE AND DISTRIBUTION PRACTICE)/GSDP COMPANY FILES/INTERPHARM GMBH | O37: =IF(M37="","",HYPERLINK(M37,B37)) -> INTERPHARMA INDUSTRIES LTD
A38: 36 | B38: KCH CONSUMER HEALTHCARE LTD | C38: 23B, Kwame Nkrumah Crown Estate, Lekki-Epe Expressway, Lagos State. | D38: Pharm Chris Ukah 08032317625 | E38: GDP | F38: 45523 | G38: Medium Risk | H38: 21/08/24 | I38: YES | J38: CAPA Submitted | K38: =IF(I38="YES","CAPA VERIFICATION SHOULD BE SCHEDULED",IF(I38="NO","REMINDER LETTER SHOULD BE SENT","")) -> CAPA VERIFICATION SHOULD BE SCHEDULED | L38: DONE | M38: https://nafdacng.sharepoint.com/sites/PMSLAGOS/Shared Documents/GDP (GOOD DISTRIBUTION PRATICE)/GSDP COMPANY FILES\KCH CONSUMER | N38: https://nafdacng.sharepoint.com/sites/PMSLAGOS/Shared Documents/GSDP (GOOD STORAGE AND DISTRIBUTION PRACTICE)/GSDP COMPANY FILES\KCH CONSUMER | O38: =IF(M38="","",HYPERLINK(M38,B38)) -> KCH CONSUMER HEALTHCARE LTD
A39: 37 | B39: XCEL PHARMA LTD | C39: 9, Olowogbomu street, Ilupeju, Lagos | D39: Pharm Steve Okonkwo 08023077320 | E39: GDP | F39: 45532 | G39: Medium Risk | H39: 45786 | I39: NO | J39: CAPA to be submitted | K39: REMINDER LETTER | L39: 45870 | M39: https://nafdacng.sharepoint.com/sites/PMSLAGOS/Shared Documents/GDP (GOOD DISTRIBUTION PRATICE)/GSDP COMPANY FILES\XCEL PHARMA | N39: https://nafdacng.sharepoint.com/sites/PMSLAGOS/Shared Documents/GSDP (GOOD STORAGE AND DISTRIBUTION PRACTICE)/GSDP COMPANY FILES\XCEL PHARMA | O39: =IF(M39="","",HYPERLINK(M39,B39)) -> XCEL PHARMA LTD
A40: 38 | B40: MEDVACC PHARMACY LTD | C40: 16, Karimu Kotun Street, Victoria Island | D40: Gbone Ihukwe 08022245920 | E40: GDP | F40: 45551 | G40: Medium Risk | H40: 19/09/24 | I40: YES | J40: CAPA submitted | K40: =IF(I40="YES","CAPA VERIFICATION SHOULD BE SCHEDULED",IF(I40="NO","REMINDER LETTER SHOULD BE SENT","")) -> CAPA VERIFICATION SHOULD BE SCHEDULED | L40: DONE | M40: https://nafdacng.sharepoint.com/sites/PMSLAGOS/Shared Documents/GDP (GOOD DISTRIBUTION PRATICE)/GSDP COMPANY FILES\MEDVACC PHARMACY | N40: https://nafdacng.sharepoint.com/sites/PMSLAGOS/Shared Documents/GSDP (GOOD STORAGE AND DISTRIBUTION PRACTICE)/GSDP COMPANY FILES\MEDVACC PHARMACY | O40: =IF(M40="","",HYPERLINK(M40,B40)) -> MEDVACC PHARMACY LTD
...

Sheet MARCH
A1: GDP INSPECTION CLASSIFICATION DATABASE AS AT 2024
A2: S/N | B2: NAME OF MANUFACTURER | C2: LOCATION ADDRESS | D2: CONTACT | E2: TYPE OF LAST INSPECTION | F2: DATE OF LAST INSPECTION | G2: FINDINGS | H2: CAPA ISSUED DATE | I2: CAPA SUBMITTED | J2: CONCLUSION | K2: REMARKS | L2: EXPECTED DATE OF INSPECTION | M2: Column1 | N2: Column12 | O2: Column2
A3: 1 | B3: DI MAGGO PHARMACEUTICALS | C3: 1 Egbe Road Ikotun Lagos. | D3: Mr. Magnus Ekenyem,08037277196 | E3: GDP | F3: 45362 | G3: Medium Risk | H3: 28/05/24 | I3: NO | J3: CAPA to be submitted | K3: =IF(I3="YES","CAPA VERIFICATION SHOULD BE SCHEDULED",IF(I3="NO","REMINDER LETTER SHOULD BE SENT","")) -> REMINDER LETTER SHOULD BE SENT | L3: 45717 | M3: https://nafdacng.sharepoint.com/sites/PMSLAGOS/Shared Documents/GSDP (GOOD STORAGE AND DISTRIBUTION PRACTICE)/GSDP COMPANY FILES\DI-MAGGIO | N3: =IF(L3="","",HYPERLINK(L3,B3)) -> DI MAGGO PHARMACEUTICALS
A4: 2 | B4: SONYDON AND SONS PHARM NIG. LTD | C4: 126, Egbe Road Beside Nepa B/Stop Ejigbo Lagos State. | D4: Mr. Sunday Igwe | E4: GDP | F4: 45362 | G4: Medium Risk | H4: 28/05/25 | I4: NO | J4: CAPA to be submitted | K4: =IF(I4="YES","CAPA VERIFICATION SHOULD BE SCHEDULED",IF(I4="NO","REMINDER LETTER SHOULD BE SENT","")) -> REMINDER LETTER SHOULD BE SENT | L4: 45717 | M4: https://nafdacng.sharepoint.com/sites/PMSLAGOS/Shared Documents/GSDP (GOOD STORAGE AND DISTRIBUTION PRACTICE)/GSDP COMPANY FILES\SONYDON & SON | N4: =IF(L4="","",HYPERLINK(L4,B4)) -> SONYDON AND SONS PHARM NIG. LTD
A5: 3 | B5: SOLOCHUCKS PHARMACEUTICALS | C5: 8 Alli Dogo Street, Badia, Ijora Lagos State. | D5: Pharm. Okolie Adolphus,07063390356 | E5: GDP | F5: 45363 | G5: Medium Risk | H5: 28/05/26 | I5: NO | J5: CAPA to be submitted | K5: =IF(I6="YES","CAPA VERIFICATION SHOULD BE SCHEDULED",IF(I6="NO","REMINDER LETTER SHOULD BE SENT","")) -> REMINDER LETTER SHOULD BE SENT | L5: 45717 | M5: https://nafdacng.sharepoint.com/sites/PMSLAGOS/Shared Documents/GSDP (GOOD STORAGE AND DISTRIBUTION PRACTICE)/GSDP COMPANY FILES\SOLOCHUKS PHARM | N5: =IF(L5="","",HYPERLINK(L5,B5)) -> SOLOCHUCKS PHARMACEUTICALS
A6: 4 | B6: SLOCHARS PHARMACEUTICALS | C6: 49 Coker Road Orile Coker Lagos State. | D6: Mr. Damilare Dawodu,08033359934 | E6: GDP | F6: 45363 | G6: Medium Risk | H6: 20/3/24 | I6: NO | J6: CAPA to be submitted | K6: =IF(#REF!="YES","CAPA VERIFICATION SHOULD BE SCHEDULED",IF(#REF!="NO","REMINDER LETTER SHOULD BE SENT","")) -> #REF! | L6: 45717 | M6: https://nafdacng.sharepoint.com/sites/PMSLAGOS/Shared Documents/GSDP (GOOD STORAGE AND DISTRIBUTION PRACTICE)/GSDP COMPANY FILES\SLOCHARS PHARM | N6: =IF(L6="","",HYPERLINK(L6,B6)) -> SLOCHARS PHARMACEUTICALS
A7: 5 | B7: GRACEJOHNSON LIMITED | C7: 448, OLD OJO ROAD, SATELLITE TOWN LAGOS | D7: Offia Justina O.,08094579401 | E7: GDP | F7: 45364 | G7: Medium Risk | H7: 28/05/24 | I7: NO | J7: CAPA to be submitted | K7: =IF(I7="YES","CAPA VERIFICATION SHOULD BE SCHEDULED",IF(I7="NO","REMINDER LETTER SHOULD BE SENT","")) -> REMINDER LETTER SHOULD BE SENT | L7: 45717 | M7: https://nafdacng.sharepoint.com/sites/PMSLAGOS/Shared Documents/GSDP (GOOD STORAGE AND DISTRIBUTION PRACTICE)/GSDP COMPANY FILES\GRACE JOHNSON LTD | N7: =IF(L7="","",HYPERLINK(L7,B7)) -> GRACEJOHNSON LIMITED
A8: 6 | B8: EL-NOSCO PHARMACY | C8: 62, EKORO ROAD, ABULE-EGBA LAGOS | D8: Pharm Ifeoma Nkemdilim,07031553339 | E8: GDP | F8: 45365 | G8: Medium Risk | H8: 28/05/24 | I8: NO | J8: CAPA to be submitted | K8: =IF(I8="YES","CAPA VERIFICATION SHOULD BE SCHEDULED",IF(I8="NO","REMINDER LETTER SHOULD BE SENT","")) -> REMINDER LETTER SHOULD BE SENT | L8: 45717 | M8: https://nafdacng.sharepoint.com/sites/PMSLAGOS/Shared Documents/GSDP (GOOD STORAGE AND DISTRIBUTION PRACTICE)/GSDP COMPANY FILES\EL-NOSCO PHARM | N8: =IF(L8="","",HYPERLINK(L8,B8)) -> EL-NOSCO PHARMACY
A9: 7 | B9: S. UMUNNA PHARMACEUTICALS | C9: 26, MEIRAN RD., MEIRAN LAGOS | D9: Pharm Agubor Stantely,08062585880 | E9: GDP | F9: 45365 | G9: Medium Risk | H9: 28/05/24 | I9: NO | J9: CAPA to be submitted | K9: =IF(I9="YES","CAPA VERIFICATION SHOULD BE SCHEDULED",IF(I9="NO","REMINDER LETTER SHOULD BE SENT","")) -> REMINDER LETTER SHOULD BE SENT | L9: 45717 | M9: https://nafdacng.sharepoint.com/sites/PMSLAGOS/Shared Documents/GSDP (GOOD STORAGE AND DISTRIBUTION PRACTICE)/GSDP COMPANY FILES\S. UMUNNA PHARM | N9: =IF(L9="","",HYPERLINK(L9,B9)) -> S. UMUNNA PHARMACEUTICALS
A10: 8 | B10: TONIVIC PHARMACY | C10: 18, DEMURIN STREET, KETU LAGOS | D10: Anita Chiwendu,09083549449 | E10: GDP | F10: 45362 | G10: Medium Risk | H10: 28/3/24 | I10: NO | J10: CAPA to be submitted | K10: =IF(I10="YES","CAPA VERIFICATION SHOULD BE SCHEDULED",IF(I10="NO","REMINDER LETTER SHOULD BE SENT","")) -> REMINDER LETTER SHOULD BE SENT | L10: 45717 | M10: https://nafdacng.sharepoint.com/sites/PMSLAGOS/Shared Documents/GSDP (GOOD STORAGE AND DISTRIBUTION PRACTICE)/GSDP COMPANY FILES\TONIVIC | N10: =IF(L10="","",HYPERLINK(L10,B10)) -> TONIVIC PHARMACY
A11: 9 | B11: JOEBIZ PHARMACY | C11: 26, Odugate Street, Ikorudu road, Lagos. | D11: Pharm. Edeh Gift,'07034630536 | E11: GDP | F11: 45369 | G11: Medium Risk | H11: 28/05/24 | I11: NO | J11: CAPA to be submitted | K11: =IF(I11="YES","CAPA VERIFICATION SHOULD BE SCHEDULED",IF(I11="NO","REMINDER LETTER SHOULD BE SENT","")) -> REMINDER LETTER SHOULD BE SENT | L11: 45717 | M11: https://nafdacng.sharepoint.com/sites/PMSLAGOS/Shared Documents/GSDP (GOOD STORAGE AND DISTRIBUTION PRACTICE)/GSDP COMPANY FILES\JOEBIZ PHARMACY | N11: =IF(L11="","",HYPERLINK(L11,B11)) -> JOEBIZ PHARMACY
A12: 10 | B12: GOODCARE PHARMACEUTICALS LTD (CAPA) | C12: 111 ISAWO ROAD, AGRIC IKORODU LAGOS | D12: 8064266572 | E12: CAPA | F12: 45369 | G12: Medium Risk | H12: 28/05/24 | I12: YES | J12: CAPA Submitted | K12: =IF(I12="YES","CAPA VERIFICATION SHOULD BE SCHEDULED",IF(I12="NO","REMINDER LETTER SHOULD BE SENT","")) -> CAPA VERIFICATION SHOULD BE SCHEDULED | L12: 45717 | M12: https://nafdacng.sharepoint.com/sites/PMSLAGOS/Shared Documents/GSDP (GOOD STORAGE AND DISTRIBUTION PRACTICE)/GSDP COMPANY FILES\GOODCARE | N12: =IF(L12="","",HYPERLINK(L12,B12)) -> GOODCARE PHARMACEUTICALS LTD (CAPA)
A13: 11 | B13: RALPHONES PHARMACEUTICAL (CAPA) | C13: 1 Ralphone Lane,Irawo ajegunle,ikorodu,Lagos | D13: 8037588238 | E13: CAPA | F13: 45369 | G13: Medium Risk | H13: 28/5/2024 | I13: NO | J13: CAPA Submitted | K13: =IF(I13="YES","CAPA VERIFICATION SHOULD BE SCHEDULED",IF(I13="NO","REMINDER LETTER SHOULD BE SENT","")) -> REMINDER LETTER SHOULD BE SENT | L13: 45717 | M13: https://nafdacng.sharepoint.com/sites/PMSLAGOS/Shared Documents/GSDP (GOOD STORAGE AND DISTRIBUTION PRACTICE)/GSDP COMPANY FILES\RALPHONES PHARMACEUTICAL LTD | N13: =IF(L13="","",HYPERLINK(L13,B13)) -> RALPHONES PHARMACEUTICAL (CAPA)
A14: 12 | B14: ROYAL PRIESTHOOD LAB LTD. | C14: 3, ERULE OLABO STR., ODONLA ODONGUNYAN, IKORODU LAGOS | D14: Olufunsho Okunewo,08033512909 | E14: GDP | F14: 45369 | G14: Medium Risk | H14: 28/05/24 | I14: NO | J14: CAPA to be submitted | K14: =IF(I14="YES","CAPA VERIFICATION SHOULD BE SCHEDULED",IF(I14="NO","REMINDER LETTER SHOULD BE SENT","")) -> REMINDER LETTER SHOULD BE SENT | L14: 45717 | M14: https://nafdacng.sharepoint.com/:f:/s/PMSLAGOS/IgA0Jl4IY1vDR7iQOT0MDq3TAUynKViboBPDh_ABRHjR7sQ?e=A8QmxD | N14: =IF(L14="","",HYPERLINK(L14,B14)) -> ROYAL PRIESTHOOD LAB LTD.
A15: 13 | B15: MIVERO PHARM LTD (CAPA) | C15: 244,AGEGE MOTOR ROAD, MUSHIN LAGOS | D15: 8161396721 | E15: CAPA | F15: 45370 | G15: Low Risk | H15: 28/05/24 | I15: YES | J15: CAPA Submitted | K15: =IF(I15="YES","CAPA VERIFICATION SHOULD BE SCHEDULED",IF(I15="NO","REMINDER LETTER SHOULD BE SENT","")) -> CAPA VERIFICATION SHOULD BE SCHEDULED | L15: 46082 | M15: https://nafdacng.sharepoint.com/sites/PMSLAGOS/Shared Documents/GSDP (GOOD STORAGE AND DISTRIBUTION PRACTICE)/GSDP COMPANY FILES\MIVERO PHARM | N15: =IF(L15="","",HYPERLINK(L15,B15)) -> MIVERO PHARM LTD (CAPA)
A16: 14 | B16: SEC PHARMACY | C16: 135, ITIRE-IJESHA ROAD, SURULERE LAGOS | D16: Pharm Kehinde,'08034760477 | E16: GDP | F16: 45370 | G16: Medium Risk | H16: 28/05/24 | I16: NO | J16: CAPA to be submitted | K16: =IF(I16="YES","CAPA VERIFICATION SHOULD BE SCHEDULED",IF(I16="NO","REMINDER LETTER SHOULD BE SENT","")) -> REMINDER LETTER SHOULD BE SENT | L16: 45717 | M16: https://nafdacng.sharepoint.com/sites/PMSLAGOS/Shared Documents/GSDP (GOOD STORAGE AND DISTRIBUTION PRACTICE)/GSDP COMPANY FILES\SEC PHARMACEUTICAL | N16: =IF(L16="","",HYPERLINK(L16,B16)) -> SEC PHARMACY
A17: 15 | B17: FEDESON PHARMACY | C17: 147, IJESHA RD., IJESHA LAGOS | D17: Pharm Ifeyinwa Morah,09053039212 | E17: GDP | F17: 45370 | G17: Low Risk | H17: 28/05/24 | I17: YES | J17: CAPA Submitted | K17: =IF(I17="YES","CAPA VERIFICATION SHOULD BE SCHEDULED",IF(I17="NO","REMINDER LETTER SHOULD BE SENT","")) -> CAPA VERIFICATION SHOULD BE SCHEDULED | L17: 46082 | M17: https://nafdacng.sharepoint.com/sites/PMSLAGOS/Shared Documents/GSDP (GOOD STORAGE AND DISTRIBUTION PRACTICE)/GSDP COMPANY FILES\FEDESON PHARM | N17: =IF(L17="","",HYPERLINK(L17,B17)) -> FEDESON PHARMACY
A18: 17 | B18: EZE-SUNICH PHARMACY | C18: 207, SHIBIRI ROAD, SHIBIRI, EKUNPA | D18: Amara Okoye'08063788228 | E18: GDP | F18: 45371 | G18: Medium Risk | H18: 28/05/24 | I18: NO | J18: CAPA to be submitted | K18: =IF(I18="YES","CAPA VERIFICATION SHOULD BE SCHEDULED",IF(I18="NO","REMINDER LETTER SHOULD BE SENT","")) -> REMINDER LETTER SHOULD BE SENT | L18: 45717 | M18: https://nafdacng.sharepoint.com/sites/PMSLAGOS/Shared Documents/GSDP (GOOD STORAGE AND DISTRIBUTION PRACTICE)/GSDP COMPANY FILES\EZE-SUNICH PHARM | N18: =IF(L18="","",HYPERLINK(L18,B18)) -> EZE-SUNICH PHARMACY

Sheet MAY
A1: GDP INSPECTION CLASSIFICATION DATABASE AS AT 2024
A2: S/N | B2: NAME OF MANUFACTURER | C2: LOCATION ADDRESS | D2: CONTACT | E2: TYPE OF LAST INSPECTION | F2: DATE OF LAST INSPECTION | G2: FINDINGS | H2: CAPA ISSUED DATE | I2: CAPA SUBMITTED | J2: CONCLUSION | K2: REMARKS | L2: EXPECTED DATE OF INSPECTION | M2: Column1 | N2: Column12 | O2: Column2
A3: 16 | B3: ALATRA PHARMACEUTICALS (CAPA) | C3: 7,0RIYOMI STREET,OFF KODESOH STREET,IKEJA | D3: Nriagu Pius,08023545633 | E3: CAPA | F3: 45427 | G3: Low Risk | H3: 29/05/24 | I3: YES | J3: CAPA Submitted | K3: =IF(I3="YES","CAPA VERIFICATION SHOULD BE SCHEDULED",IF(I3="NO","REMINDER LETTER SHOULD BE SENT","")) -> CAPA VERIFICATION SHOULD BE SCHEDULED | L3: 46143 | M3: https://nafdacng.sharepoint.com/:f:/s/PMSLAGOS/IgDEREDujMUYRZhkrewJEPixAbYbfZ1LbL8qianGZ-plcdU?e=WqHder | N3: =IF(L3="","",HYPERLINK(L3,B3)) -> ALATRA PHARMACEUTICALS (CAPA)
A4: 18 | B4: JOMEC PHARM CO.LTD | C4: 865 SURULERE STREET DOPEMU LAGOS | D4: Mr. Ifeanyi Okafor,8033453140 | E4: GDP | F4: 45418 | G4: Medium Risk | H4: 21/5/24 | I4: NO | J4: CAPA to be submitted | K4: =IF(I4="YES","CAPA VERIFICATION SHOULD BE SCHEDULED",IF(I4="NO","REMINDER LETTER SHOULD BE SENT","")) -> REMINDER LETTER SHOULD BE SENT | L4: 45778 | N4: =IF(L4="","",HYPERLINK(L4,B4)) -> JOMEC PHARM CO.LTD
A5: 19 | B5: CHUPET PHARMACEUTICAL | C5: 18/20 OGUNGBESAN STREET COKER SURULERE LAGOS | D5: Pharm. Ngozi Ata,08034028483 | E5: GDP | F5: 45419 | G5: Low Risk | H5: 45570 | I5: YES | J5: CAPA submitted | K5: =IF(I5="YES","CAPA VERIFICATION SHOULD BE SCHEDULED",IF(I5="NO","REMINDER LETTER SHOULD BE SENT","")) -> CAPA VERIFICATION SHOULD BE SCHEDULED | L5: 46143 | M5: https://nafdacng.sharepoint.com/sites/PMSLAGOS/Shared Documents/GSDP (GOOD STORAGE AND DISTRIBUTION PRACTICE)/GSDP COMPANY FILES\CHUPET PHARMACEUTICALS | N5: =IF(L5="","",HYPERLINK(L5,B5)) -> CHUPET PHARMACEUTICAL
A6: 20 | B6: SPINE PRODUCT LTD | C6: 24 AYODELE OKEOWO STREET SOLUYI GBAGADA LAGOS | D6: Pharm. Dominica Chiamaka Emezirinwanne,08030998612 | E6: GDP | F6: 45420 | G6: Medium Risk | H6: 29/5/24 | I6: NO | J6: CAPA to be submitted | K6: =IF(I6="YES","CAPA VERIFICATION SHOULD BE SCHEDULED",IF(I6="NO","REMINDER LETTER SHOULD BE SENT","")) -> REMINDER LETTER SHOULD BE SENT | L6: 45778 | M6: https://nafdacng.sharepoint.com/sites/PMSLAGOS/Shared Documents/GSDP (GOOD STORAGE AND DISTRIBUTION PRACTICE)/GSDP COMPANY FILES\SPINE PRODUCT LTD | N6: =IF(L6="","",HYPERLINK(L6,B6)) -> SPINE PRODUCT LTD
A7: 21 | B7: HOLY TRINTY PHARMACY | C7: 12/19 ABULE ADALOKO ROAD ABULE-ERA OJO LAGOS | D7: Pharm Tina Agbada | E7: GDP | F7: 45421 | G7: Medium Risk | H7: 29/11/24 | I7: NO | J7: CAPA to be submitted | K7: =IF(I7="YES","CAPA VERIFICATION SHOULD BE SCHEDULED",IF(I7="NO","REMINDER LETTER SHOULD BE SENT","")) -> REMINDER LETTER SHOULD BE SENT | L7: 45778 | M7: https://nafdacng.sharepoint.com/sites/PMSLAGOS/Shared Documents/GSDP (GOOD STORAGE AND DISTRIBUTION PRACTICE)/GSDP COMPANY FILES\HOLY TRINTY PHARM | N7: =IF(L7="","",HYPERLINK(L7,B7)) -> HOLY TRINTY PHARMACY
A8: 22 | B8: J.O SARCHMORE PHARMACY | C8: 118 OLD LAGOS ROAD DEPPER LIFE BIBLE CHURCH AJARA BADAGRY LAGOS | D8: Orejekwe Joseph,08146180819 | E8: GDP | F8: 45421 | G8: Medium Risk | H8: 21/5/24 | I8: NO | J8: CAPA to be submitted | K8: =IF(I8="YES","CAPA VERIFICATION SHOULD BE SCHEDULED",IF(I8="NO","REMINDER LETTER SHOULD BE SENT","")) -> REMINDER LETTER SHOULD BE SENT | L8: 45778 | M8: https://nafdacng.sharepoint.com/sites/PMSLAGOS/Shared Documents/GSDP (GOOD STORAGE AND DISTRIBUTION PRACTICE)/GSDP COMPANY FILES\J.O SARCHMORE PHARM | N8: =IF(L8="","",HYPERLINK(L8,B8)) -> J.O SARCHMORE PHARMACY
A9: 23 | B9: SUNLIGHT LINKS PHARMACY LTD | C9: 135 BORNO WAY EBUTA-METTA LAGOS | D9: Pharm. Olajide Omilana,07036693454 | E9: GDP | F9: 45425 | G9: Medium Risk | H9: 29/5/24 | I9: NO | J9: CAPA to be submitted | K9: =IF(I9="YES","CAPA VERIFICATION SHOULD BE SCHEDULED",IF(I9="NO","REMINDER LETTER SHOULD BE SENT","")) -> REMINDER LETTER SHOULD BE SENT | L9: 45778 | M9: https://nafdacng.sharepoint.com/sites/PMSLAGOS/Shared Documents/GSDP (GOOD STORAGE AND DISTRIBUTION PRACTICE)/GSDP COMPANY FILES\SUNLIGHT LINK PHARMACY | N9: =IF(L9="","",HYPERLINK(L9,B9)) -> SUNLIGHT LINKS PHARMACY LTD
A10: 24 | B10: AL-TINEZ PHARMACEUTICALS | C10: 18 JONES STREET EBUTE-METTA LAGOS | D10: Pharm. Eze Gift Laz,09033777367 | E10: GDP | F10: 45425 | G10: Medium Risk | H10: 29/05/24 | I10: NO | J10: CAPA to be submitted | K10: =IF(I10="YES","CAPA VERIFICATION SHOULD BE SCHEDULED",IF(I10="NO","REMINDER LETTER SHOULD BE SENT","")) -> REMINDER LETTER SHOULD BE SENT | L10: 45778 | M10: https://nafdacng.sharepoint.com/sites/PMSLAGOS/Shared Documents/GSDP (GOOD STORAGE AND DISTRIBUTION PRACTICE)/GSDP COMPANY FILES\AL-TINEZ PHARMA. LTD | N10: =IF(L10="","",HYPERLINK(L10,B10)) -> AL-TINEZ PHARMACEUTICALS
A11: 25 | B11: ROCA PHARMACEUTICAL | C11: 324 IJU-ISHAGA ROAD IJU LAGOS | D11: Pharm. Onyekachi Udeogu,08038569395 | E11: GDP | F11: 45426 | G11: Medium Risk | I11: NO | J11: CAPA to be submitted | K11: =IF(I11="YES","CAPA VERIFICATION SHOULD BE SCHEDULED",IF(I11="NO","REMINDER LETTER SHOULD BE SENT","")) -> REMINDER LETTER SHOULD BE SENT | L11: 45778 | N11: =IF(L11="","",HYPERLINK(L11,B11)) -> ROCA PHARMACEUTICAL
A12: 26 | B12: EMBASSY PHARMACEUTICALS (CAPA) | C12: 41,Ademola Street,Off Obafemi Awolowo Road,Ikoyi,Lagos state | D12: 8029702822 | E12: CAPA | F12: 45428 | G12: Low Risk | I12: YES | J12: N/A | K12: CONTINOUS MONITORING TO ENSURE COMPLIANCE | L12: 46143 | M12: https://nafdacng.sharepoint.com/sites/PMSLAGOS/Shared Documents/GSDP (GOOD STORAGE AND DISTRIBUTION PRACTICE)/GSDP COMPANY FILES\EMBASSY PHARM | N12: =IF(L12="","",HYPERLINK(L12,B12)) -> EMBASSY PHARMACEUTICALS (CAPA)
A13: 27 | B13: HILLY PHARMACY | C13: 2 0DO OBALENDE LAGSO STATE | D13: Ogwe Chukwuemeka,08065263178 | E13: GDP | F13: 45428 | G13: Medium Risk | I13: YES | J13: CAPA to be submitted | K13: =IF(I13="YES","CAPA VERIFICATION SHOULD BE SCHEDULED",IF(I13="NO","REMINDER LETTER SHOULD BE SENT","")) -> CAPA VERIFICATION SHOULD BE SCHEDULED | L13: 45778 | M13: https://nafdacng.sharepoint.com/sites/PMSLAGOS/Shared Documents/GSDP (GOOD STORAGE AND DISTRIBUTION PRACTICE)/GSDP COMPANY FILES\HILLY PHARMACY | N13: =IF(L13="","",HYPERLINK(L13,B13)) -> HILLY PHARMACY

Sheet AUGUST
A1: GDP INSPECTION CLASSIFICATION DATABASE AS AT 2024
A2: S/N | B2: NAME OF MANUFACTURER | C2: LOCATION ADDRESS | D2: CONTACT | E2: TYPE OF LAST INSPECTION | F2: DATE OF LAST INSPECTION | G2: FINDINGS | H2: CAPA ISSUED DATE | I2: CAPA SUBMITTED | J2: CONCLUSION | K2: REMARKS | L2: EXPECTED DATE OF INSPECTION | M2: Column1 | N2: Column12 | O2: Column2
A3: 28 | B3: ZADIP PHARMA NIG. LTD | C3: 68B, COKER ROAD, ILUPEJU | D3: Odugbesan Esther; 08023279017 | E3: GDP | F3: 45509 | G3: Medium Risk | H3: 45481 | I3: NO | J3: CAPA to be submitted | K3: =IF(I3="YES","CAPA VERIFICATION SHOULD BE SCHEDULED",IF(I3="NO","REMINDER LETTER SHOULD BE SENT","")) -> REMINDER LETTER SHOULD BE SENT | L3: 45870 | M3: https://nafdacng.sharepoint.com/sites/PMSLAGOS/Shared Documents/GSDP (GOOD STORAGE AND DISTRIBUTION PRACTICE)/GSDP COMPANY FILES\ZADIP PHARMA | N3: =IF(L3="","",HYPERLINK(L3,B3)) -> ZADIP PHARMA NIG. LTD
A4: 29 | B4: UNIQUE PHARM LTD | C4: 3, BLIND CENTRE ROAD, OSHODI-MUSHIN | D4: Pharm. Titus Udoh 08034022402 | E4: GDP | F4: 45511 | G4: Medium Risk | H4: 15/08/24 | I4: YES | J4: CAPA submitted | K4: =IF(I4="YES","CAPA VERIFICATION SHOULD BE SCHEDULED",IF(I4="NO","REMINDER LETTER SHOULD BE SENT","")) -> CAPA VERIFICATION SHOULD BE SCHEDULED | L4: 45597 | M4: https://nafdacng.sharepoint.com/sites/PMSLAGOS/Shared Documents/GSDP (GOOD STORAGE AND DISTRIBUTION PRACTICE)/GSDP COMPANY FILES\UNIQUE PHARMACEUTICALS | N4: =IF(L4="","",HYPERLINK(L4,B4)) -> UNIQUE PHARM LTD
A5: 30 | B5: GENERICS & SPECIALITIES LTD | C5: 9, Dave Anazodo street, Behind Eleganza Company, Ajao Estate, Isolo. | D5: Pharm. Cyril Odidika 08033344839 | E5: GDP | F5: 45512 | G5: Medium Risk | H5: 27/08/24 | I5: YES | J5: CAPA Submitted | K5: =IF(I5="YES","CAPA VERIFICATION SHOULD BE SCHEDULED",IF(I5="NO","REMINDER LETTER SHOULD BE SENT","")) -> CAPA VERIFICATION SHOULD BE SCHEDULED | L5: DONE | M5: https://nafdacng.sharepoint.com/sites/PMSLAGOS/Shared Documents/GSDP (GOOD STORAGE AND DISTRIBUTION PRACTICE)/GSDP COMPANY FILES\UNIQUE PHARMACEUTICALS | N5: =IF(L5="","",HYPERLINK(L5,B5)) -> GENERICS & SPECIALITIES LTD
A6: 31 | B6: INTERPHARM GMBH | C6: 11A, John Olugbo Street, Ikeja, Lagos | D6: 8033329209 | E6: GDP | F6: 45513 | G6: Medium Risk | H6: NO CAPA | I6: NO | J6: CAPA to be submitted | K6: =IF(I6="YES","CAPA VERIFICATION SHOULD BE SCHEDULED",IF(I6="NO","REMINDER LETTER SHOULD BE SENT","")) -> REMINDER LETTER SHOULD BE SENT | L6: 45870 | M6: https://nafdacng.sharepoint.com/sites/PMSLAGOS/Shared Documents/GSDP (GOOD STORAGE AND DISTRIBUTION PRACTICE)/GSDP COMPANY FILES\INTERPHARM GMBH | N6: =IF(L6="","",HYPERLINK(L6,B6)) -> INTERPHARM GMBH
A7: 32 | B7: AWARD GLOBAL COMPANY LTD (CAPA) | C7: 13, Olawole Dawodu street, Gbagada | D7: Pharm Abel Okechukwu 08065139057 | E7: CAPA | F7: 45516 | G7: Medium Risk | H7: 15/0824 | I7: YES | J7: CAPA submitted | K7: =IF(I7="YES","CAPA VERIFICATION SHOULD BE SCHEDULED",IF(I7="NO","REMINDER LETTER SHOULD BE SENT","")) -> CAPA VERIFICATION SHOULD BE SCHEDULED | L7: DONE | M7: https://nafdacng.sharepoint.com/sites/PMSLAGOS/Shared Documents/GSDP (GOOD STORAGE AND DISTRIBUTION PRACTICE)/GSDP COMPANY FILES\AWARD GLOBAL | N7: =IF(L7="","",HYPERLINK(L7,B7)) -> AWARD GLOBAL COMPANY LTD (CAPA)
A8: 33 | B8: MARCSON HEALTHCARE | C8: 29, Agric Road, Cele Bus-stop, isawo, Ikorodu. | D8: Pharm. Femi Abolarin 08037149817 | E8: GDP | F8: 45517 | G8: Medium Risk | H8: 20/08/24 | I8: YES | J8: CAPA submitted | K8: =IF(I8="YES","CAPA VERIFICATION SHOULD BE SCHEDULED",IF(I8="NO","REMINDER LETTER SHOULD BE SENT","")) -> CAPA VERIFICATION SHOULD BE SCHEDULED | L8: 45954 | M8: https://nafdacng.sharepoint.com/sites/PMSLAGOS/Shared Documents/GSDP (GOOD STORAGE AND DISTRIBUTION PRACTICE)/GSDP COMPANY FILES\MARCSON HEALTHCARE | N8: =IF(L8="","",HYPERLINK(L8,B8)) -> MARCSON HEALTHCARE
A9: 34 | B9: PHARMAMAX NIGERIA LTD | C9: 7/9 Sawyer Crescent, Phase 1, Gbagada | D9: Pharm Okoye Martha 07036263207 | E9: GDP | F9: 45518 | G9: Medium Risk | H9: 15/08/24 | I9: NO | J9: CAPA to be submitted | K9: =IF(I9="YES","CAPA VERIFICATION SHOULD BE SCHEDULED",IF(I9="NO","REMINDER LETTER SHOULD BE SENT","")) -> REMINDER LETTER SHOULD BE SENT | L9: 45894 | M9: https://nafdacng.sharepoint.com/sites/PMSLAGOS/Shared Documents/GSDP (GOOD STORAGE AND DISTRIBUTION PRACTICE)/GSDP COMPANY FILES/PHARMAMAX NIG. LTD | N9: =IF(L9="","",HYPERLINK(L9,B9)) -> PHARMAMAX NIGERIA LTD
A10: 35 | B10: INTERPHARMA INDUSTRIES LTD | C10: 28/30 Salvation Road, Opebi, Ikeja | D10: Pharm Adeyinka Benson | E10: GDP | F10: 45520 | G10: Medium Risk | H10: 16/08/24 | I10: NO | J10: CAPA to be submitted | K10: =IF(I10="YES","CAPA VERIFICATION SHOULD BE SCHEDULED",IF(I10="NO","REMINDER LETTER SHOULD BE SENT","")) -> REMINDER LETTER SHOULD BE SENT | L10: 45894 | M10: https://nafdacng.sharepoint.com/sites/PMSLAGOS/Shared Documents/GSDP (GOOD STORAGE AND DISTRIBUTION PRACTICE)/GSDP COMPANY FILES/INTERPHARM GMBH | N10: =IF(L10="","",HYPERLINK(L10,B10)) -> INTERPHARMA INDUSTRIES LTD
A11: 36 | B11: KCH CONSUMER HEALTHCARE LTD | C11: 23B, Kwame Nkrumah Crown Estate, Lekki-Epe Expressway, Lagos State. | D11: Pharm Chris Ukah 08032317625 | E11: GDP | F11: 45523 | G11: Medium Risk | H11: 21/08/24 | I11: YES | J11: CAPA Submitted | K11: =IF(I11="YES","CAPA VERIFICATION SHOULD BE SCHEDULED",IF(I11="NO","REMINDER LETTER SHOULD BE SENT","")) -> CAPA VERIFICATION SHOULD BE SCHEDULED | L11: DONE | M11: https://nafdacng.sharepoint.com/sites/PMSLAGOS/Shared Documents/GSDP (GOOD STORAGE AND DISTRIBUTION PRACTICE)/GSDP COMPANY FILES\KCH CONSUMER | N11: =IF(L11="","",HYPERLINK(L11,B11)) -> KCH CONSUMER HEALTHCARE LTD
A12: 37 | B12: XCEL PHARMA LTD | C12: 9, Olowogbomu street, Ilupeju, Lagos | D12: Pharm Steve Okonkwo 08023077320 | E12: GDP | F12: 45532 | G12: Medium Risk | H12: 45786 | I12: NO | J12: CAPA to be submitted | K12: REMINDER LETTER | L12: 45870 | M12: https://nafdacng.sharepoint.com/sites/PMSLAGOS/Shared Documents/GSDP (GOOD STORAGE AND DISTRIBUTION PRACTICE)/GSDP COMPANY FILES\XCEL PHARMA | N12: =IF(L12="","",HYPERLINK(L12,B12)) -> XCEL PHARMA LTD

Sheet SEPTEMBER
A1: GDP INSPECTION CLASSIFICATION DATABASE AS AT 2024
A2: S/N | B2: NAME OF MANUFACTURER | C2: LOCATION ADDRESS | D2: CONTACT | E2: TYPE OF LAST INSPECTION | F2: DATE OF LAST INSPECTION | G2: FINDINGS | H2: CAPA ISSUED DATE | I2: CAPA SUBMITTED | J2: CONCLUSION | K2: REMARKS | L2: EXPECTED DATE OF INSPECTION | M2: Column1 | N2: Column12 | O2: Column2
A3: 38 | B3: MEDVACC PHARMACY LTD | C3: 16, Karimu Kotun Street, Victoria Island | D3: Gbone Ihukwe 08022245920 | E3: GDP | F3: 45551 | G3: Medium Risk | H3: 19/09/24 | I3: YES | J3: CAPA submitted | K3: =IF(I3="YES","CAPA VERIFICATION SHOULD BE SCHEDULED",IF(I3="NO","REMINDER LETTER SHOULD BE SENT","")) -> CAPA VERIFICATION SHOULD BE SCHEDULED | L3: DONE | M3: https://nafdacng.sharepoint.com/sites/PMSLAGOS/Shared Documents/GSDP (GOOD STORAGE AND DISTRIBUTION PRACTICE)/GSDP COMPANY FILES\MEDVACC PHARMACY | N3: =IF(L3="","",HYPERLINK(L3,A3)) -> 38
A4: 39 | B4: VACCIPHARM LTD (CAPA) | C4: 30, Raymond Njoku, Ikoyi, Lagos | D4: Pharm. Fdekemi Adeyemi 0809455315 | E4: CAPA | F4: 45551 | G4: Medium Risk | I4: YES | J4: CAPA Submitted | K4: =IF(I4="YES","CAPA VERIFICATION SHOULD BE SCHEDULED",IF(I4="NO","REMINDER LETTER SHOULD BE SENT","")) -> CAPA VERIFICATION SHOULD BE SCHEDULED | L4: 45901 | M4: https://nafdacng.sharepoint.com/sites/PMSLAGOS/Shared Documents/GSDP (GOOD STORAGE AND DISTRIBUTION PRACTICE)/GSDP COMPANY FILES\VACCI PHARM | N4: =IF(L4="","",HYPERLINK(L4,A4)) -> 39
A5: 40 | B5: PLACEWARE NIG. LTD | C5: 64, Aina street, Ojodu beside trinity school, Lagos. | D5: Pharm. Idowu Akinola 08023246113 | E5: GDP | F5: 45552 | G5: Medium Risk | H5: 18/09/24 | I5: YES | J5: CAPA to be submitted | K5: =IF(I5="YES","CAPA VERIFICATION SHOULD BE SCHEDULED",IF(I5="NO","REMINDER LETTER SHOULD BE SENT","")) -> CAPA VERIFICATION SHOULD BE SCHEDULED | L5: DONE | M5: https://nafdacng.sharepoint.com/sites/PMSLAGOS/Shared Documents/GSDP (GOOD STORAGE AND DISTRIBUTION PRACTICE)/GSDP COMPANY FILES\PLACEWARE NIG LTD | N5: =IF(L5="","",HYPERLINK(L5,A5)) -> 40
A6: 41 | B6: SUMMIT HEALTHCARE PHARMACEUTICAL | C6: 27, Isaac John street, GRA, Ikeja, Lagos | D6: Ogugua Benaiah 08037119762 | E6: GDP | F6: 45553 | G6: Medium Risk | H6: 19/09/24 | I6: NO | J6: CAPA to be submitted | K6: =IF(I6="YES","CAPA VERIFICATION SHOULD BE SCHEDULED",IF(I6="NO","REMINDER LETTER SHOULD BE SENT","")) -> REMINDER LETTER SHOULD BE SENT | L6: 45925 | M6: https://nafdacng.sharepoint.com/sites/PMSLAGOS/Shared Documents/GSDP (GOOD STORAGE AND DISTRIBUTION PRACTICE)/GSDP COMPANY FILES\SUMMIT HEALTHCARE | N6: =IF(L6="","",HYPERLINK(L6,A6)) -> 41
A7: 42 | B7: MERIT HEALTHCARE LTD | C7: 10, Dele Ashiru street, Ire Akari estate, Isolo | D7: Adedamola Adeyanju 08171273639 | E7: GDP | F7: 45558 | G7: Low Risk | H7: 24/0924 | I7: NO | J7: CAPA to be submitted | K7: =IF(I7="YES","CAPA VERIFICATION SHOULD BE SCHEDULED",IF(I7="NO","REMINDER LETTER SHOULD BE SENT","")) -> REMINDER LETTER SHOULD BE SENT | L7: 45925 | M7: https://nafdacng.sharepoint.com/sites/PMSLAGOS/Shared Documents/GSDP (GOOD STORAGE AND DISTRIBUTION PRACTICE)/GSDP COMPANY FILES\MERIT HEALTHCARE | N7: =IF(L7="","",HYPERLINK(L7,A7)) -> 42
A8: 43 | B8: EXXON PHARM. LTD | C8: Arcee Textile Mill Comp., Plot A, blk 2B , Aswani street, Isolo | D8: Pharm Mercy Ndubuisi 07031888548 | E8: GDP | F8: 45558 | G8: High Risk | I8: YES | J8: CAPA Submitted | K8: =IF(I8="YES","CAPA VERIFICATION SHOULD BE SCHEDULED",IF(I8="NO","REMINDER LETTER SHOULD BE SENT","")) -> CAPA VERIFICATION SHOULD BE SCHEDULED | L8: 45717 | M8: https://nafdacng.sharepoint.com/sites/PMSLAGOS/Shared Documents/GSDP (GOOD STORAGE AND DISTRIBUTION PRACTICE)/GSDP COMPANY FILES\exxon | N8: =IF(L8="","",HYPERLINK(L8,A8)) -> 43
A9: 44 | B9: NEOLIFE INTERNATIONAL LTD. | C9: 12, Chief Olu Oshunkeye Crescent, Gbagada, Lagos | D9: Beatrice Onuoha 08146512653 | E9: GDP | F9: 45559 | G9: Medium Risk | H9: 30/09/24 | I9: NO | J9: CAPA to be submitted | K9: =IF(I9="YES","CAPA VERIFICATION SHOULD BE SCHEDULED",IF(I9="NO","REMINDER LETTER SHOULD BE SENT","")) -> REMINDER LETTER SHOULD BE SENT | L9: 45925 | M9: https://nafdacng.sharepoint.com/sites/PMSLAGOS/Shared Documents/GSDP (GOOD STORAGE AND DISTRIBUTION PRACTICE)/GSDP COMPANY FILES\NEOLIFE | N9: =IF(L9="","",HYPERLINK(L9,A9)) -> 44
A10: 45 | B10: AWARD GLOBAL COMPANY LTD (CAPA) | C10: 13, Olawole Dawodu street, Gbagada | D10: Pharm Abel Okechukwu 08065139057 | E10: CAPA | F10: 45559 | G10: Medium Risk | H10: 30/09/24 | I10: YES | J10: CAPA Submitted | K10: =IF(I10="YES","CAPA VERIFICATION SHOULD BE SCHEDULED",IF(I10="NO","REMINDER LETTER SHOULD BE SENT","")) -> CAPA VERIFICATION SHOULD BE SCHEDULED | L10: DONE | M10: https://nafdacng.sharepoint.com/sites/PMSLAGOS/Shared Documents/GSDP (GOOD STORAGE AND DISTRIBUTION PRACTICE)/GSDP COMPANY FILES/AWARD GLOBAL | N10: =IF(L10="","",HYPERLINK(L10,A10)) -> 45

Sheet OCTOBER
A1: GDP INSPECTION CLASSIFICATION DATABASE AS AT 2024
A2: S/N | B2: NAME OF MANUFACTURER | C2: LOCATION ADDRESS | D2: CONTACT | E2: TYPE OF LAST INSPECTION | F2: DATE OF LAST INSPECTION | G2: FINDINGS | H2: CAPA ISSUED DATE | I2: CAPA SUBMITTED | J2: CONCLUSION | K2: REMARKS | L2: EXPECTED DATE OF INSPECTION | M2: Column1 | N2: Column12 | O2: Column2
A3: 46 | B3: CHANRAI HEALTHCARE LTD. (CAPA) | C3: 122-132, Oshodi-apapa express, Isolo, Lagos | D3: 8024153514 | E3: CAPA | F3: 45568 | G3: Low Risk | H3: NO CAPA | I3: N/A | J3: CAPA CLOSED | K3: CONTINOUS MONITORING TO ENSURE COMPLIANCE | L3: 46296 | M3: https://nafdacng.sharepoint.com/sites/PMSLAGOS/Shared Documents/GSDP (GOOD STORAGE AND DISTRIBUTION PRACTICE)/GSDP COMPANY FILES\CHANRAI | N3: =IF(L3="","",HYPERLINK(L3,A3)) -> 46

Sheet NOVEMBER
A1: GDP INSPECTION CLASSIFICATION DATABASE AS AT 2024
A2: S/N | B2: NAME OF MANUFACTURER | C2: LOCATION ADDRESS | D2: CONTACT | E2: TYPE OF LAST INSPECTION | F2: DATE OF LAST INSPECTION | G2: FINDINGS | H2: CAPA ISSUED DATE | I2: CAPA SUBMITTED | J2: CONCLUSION | K2: REMARKS | L2: EXPECTED DATE OF INSPECTION | M2: Column1 | N2: Column12 | O2: Column2
A3: 47 | B3: TRICARE PHARM. | C3: 28, Osolo way, Airport Road, Lagos | D3: 8033082688 | E3: GDP | F3: 45601 | G3: Medium Risk | H3: 45454 | I3: NO | J3: CAPA to be submitted | K3: =IF(I3="YES","CAPA VERIFICATION SHOULD BE SCHEDULED",IF(I3="NO","REMINDER LETTER SHOULD BE SENT","")) -> REMINDER LETTER SHOULD BE SENT | L3: 45962 | M3: https://nafdacng.sharepoint.com/sites/PMSLAGOS/Shared Documents/GSDP (GOOD STORAGE AND DISTRIBUTION PRACTICE)/GSDP COMPANY FILES\TRICARE | N3: =IF(L3="","",HYPERLINK(L3,A3)) -> 47
A4: 48 | B4: STERLING BIOPHARM | C4: 6, Femi Asiwaju Close, Ojodu estate, Ojodu, Lagos | D4: 8034676220 | E4: GDP | F4: 45601 | G4: Medium Risk | H4: 45605 | I4: N/A | J4: CAPA Submitted | K4: CONTINOUS MONITORING TO ENSURE COMPLIANCE | L4: 45962 | M4: https://nafdacng.sharepoint.com/sites/PMSLAGOS/Shared Documents/GSDP (GOOD STORAGE AND DISTRIBUTION PRACTICE)/GSDP COMPANY FILES\STERLING BIOPHARMA | N4: =IF(L4="","",HYPERLINK(L4,A4)) -> 48
A5: 49 | B5: SEAGREEN PHARMACEUTICALS | C5: 3, Okunfolami Str., Anthony Village | D5: Rosita Ijeoma 9017749944 | E5: GDP | F5: 45608 | G5: High Risk | H5: 45605 | I5: YES | J5: CAPA submitted | K5: =IF(I5="YES","CAPA VERIFICATION SHOULD BE SCHEDULED",IF(I5="NO","REMINDER LETTER SHOULD BE SENT","")) -> CAPA VERIFICATION SHOULD BE SCHEDULED | L5: 45778 | M5: https://nafdacng.sharepoint.com/sites/PMSLAGOS/Shared Documents/GSDP (GOOD STORAGE AND DISTRIBUTION PRACTICE)/GSDP COMPANY FILES\Seagreen Pharmaceuticals | N5: =IF(L5="","",HYPERLINK(L5,A5)) -> 49
A6: 50 | B6: BRENT CROSS PHARM LTD. | C6: 9, JOHNSON STR., OFF BODE THOMAS SURULERE | D6: Benedict IK 08033936345 | E6: GDP | F6: 45615 | G6: High Risk | H6: 45618 | I6: NO | J6: CAPA to be Submitted | K6: =IF(I6="YES","CAPA VERIFICATION SHOULD BE SCHEDULED",IF(I6="NO","REMINDER LETTER SHOULD BE SENT","")) -> REMINDER LETTER SHOULD BE SENT | L6: 45778 | M6: https://nafdacng.sharepoint.com/sites/PMSLAGOS/Shared Documents/GSDP (GOOD STORAGE AND DISTRIBUTION PRACTICE)/GSDP COMPANY FILES\Brent Cross | N6: =IF(L6="","",HYPERLINK(L6,A6)) -> 50
A7: 51 | B7: PHARMGATE HEALTHCARE LTD. | C7: 28, Salawu Onikoyi Str., Ifako, Gbagada | D7: Mbonu Charles 0802337610 | E7: GDP | F7: 45616 | G7: Medium Risk | H7: 45333 | I7: NO | J7: CAPA to be submitted | K7: =IF(I7="YES","CAPA VERIFICATION SHOULD BE SCHEDULED",IF(I7="NO","REMINDER LETTER SHOULD BE SENT","")) -> REMINDER LETTER SHOULD BE SENT | L7: 45962 | M7: https://nafdacng.sharepoint.com/sites/PMSLAGOS/Shared Documents/GSDP (GOOD STORAGE AND DISTRIBUTION PRACTICE)/GSDP COMPANY FILES\Pharmgate Healthcare LTD | N7: =IF(L7="","",HYPERLINK(L7,A7)) -> 51
A8: 52 | B8: NECTAR HEALTHCARE LTD. | C8: 16B, Residence Road, Gbagada Phase 2 | D8: Ifeoma Alptus 08039302111 | E8: GDP | F8: 45616 | G8: Medium Risk | H8: 22/11/24 | I8: NO | J8: CAPA to be submitted | K8: =IF(I8="YES","CAPA VERIFICATION SHOULD BE SCHEDULED",IF(I8="NO","REMINDER LETTER SHOULD BE SENT","")) -> REMINDER LETTER SHOULD BE SENT | L8: 45962 | M8: https://nafdacng.sharepoint.com/sites/PMSLAGOS/Shared Documents/GSDP (GOOD STORAGE AND DISTRIBUTION PRACTICE)/GSDP COMPANY FILES\NECTAR | N8: =IF(L8="","",HYPERLINK(L8,A8)) -> 52
A9: 53 | B9: ZOGGER PHARMA LTD. | C9: 5B, Akin George Road, Obanikoro | D9: Kuti Olusegun 08053274036 | E9: GDP | F9: 45616 | G9: Medium Risk | I9: NO | J9: CAPA to be submitted | K9: =IF(I9="YES","CAPA VERIFICATION SHOULD BE SCHEDULED",IF(I9="NO","REMINDER LETTER SHOULD BE SENT","")) -> REMINDER LETTER SHOULD BE SENT | L9: 45962 | M9: https://nafdacng.sharepoint.com/sites/PMSLAGOS/Shared Documents/GSDP (GOOD STORAGE AND DISTRIBUTION PRACTICE)/GSDP COMPANY FILES\ZOGGAR PHARMA LTD | N9: =IF(L9="","",HYPERLINK(L9,A9)) -> 53
A10: 54 | B10: FAES FARMA NIG. LTD. | C10: 25D, Ladoke Akintola Str., Ikeja GRA | D10: Pharm. Johnbull 08034523215 | E10: GDP | F10: 45617 | G10: Medium Risk | I10: NO | J10: CAPA to be submitted | K10: =IF(I10="YES","CAPA VERIFICATION SHOULD BE SCHEDULED",IF(I10="NO","REMINDER LETTER SHOULD BE SENT","")) -> REMINDER LETTER SHOULD BE SENT | L10: 45962 | M10: https://nafdacng.sharepoint.com/sites/PMSLAGOS/Shared Documents/GSDP (GOOD STORAGE AND DISTRIBUTION PRACTICE)/GSDP COMPANY FILES\Faes Farma ltd | N10: =IF(L10="","",HYPERLINK(L10,A10)) -> 54
A11: 55 | B11: LYN-EDGE PHARMACEUTICALS | C11: Block viii, Plot 23, Orchad Close, Chevron alternative route, Lekki | D11: Njoku Uche 07031710888 | E11: GDP | F11: 45617 | G11: Medium Risk | H11: 29/11/24 | I11: NO | J11: CAPA to be submitted | K11: =IF(I11="YES","CAPA VERIFICATION SHOULD BE SCHEDULED",IF(I11="NO","REMINDER LETTER SHOULD BE SENT","")) -> REMINDER LETTER SHOULD BE SENT | L11: 45962 | M11: https://nafdacng.sharepoint.com/sites/PMSLAGOS/Shared Documents/GSDP (GOOD STORAGE AND DISTRIBUTION PRACTICE)/GSDP COMPANY FILES\LYN EDGE | N11: =IF(L11="","",HYPERLINK(L11,A11)) -> 55

Sheet DECEMBER
A1: GDP INSPECTION CLASSIFICATION DATABASE AS AT 2024
